Workbook

Sheet Inicio TOPSIS
B2: Datos cuantificados de los criterios y alternativas | D2: Criterios
D3: Técnico | E3: Económico | F3: Social | G3: Ambiental | H3: Comercial
D4: Capacidad técnica de la red eléctrica | E4: Costos de instalación, operación y mantenimiento | F4: Cantidad de Personas beneficiadas | G4: Calles con ato flujo y emisiones de CO2 | H4: Cercanica y fomento al turismo y comercio
B5: Pesos: | D5: 0.2615 | E5: 0.204 | F5: 0.2884 | G5: 0.125 | H5: 0.1211 | I5: =SUM(D5:H5) -> 1
B6: Alternativas | C6: Baron | D6: ='C.Tec.'!D96 -> 0 | E6: ='C.Eco.'!D96 -> 0.9808857 | F6: ='C.Soc.'!D93 -> 0.36281503 | G6: ='C.Amb.'!D96 -> 0.8 | H6: ='C.Com.'!D96 -> 0.0071238538
C7: Cordillera | D7: ='C.Tec.'!D97 -> 1 | E7: ='C.Eco.'!D97 -> 0.98173925 | F7: ='C.Soc.'!D94 -> 0.14266978 | G7: ='C.Amb.'!D97 -> 0.8 | H7: ='C.Com.'!D97 -> 0.0001374636
C8: Esperanza | D8: ='C.Tec.'!D98 -> 0 | E8: ='C.Eco.'!D98 -> 0.99999887 | F8: ='C.Soc.'!D95 -> 0.11451585 | G8: ='C.Amb.'!D98 -> 0.2 | H8: ='C.Com.'!D98 -> 0.00054911813
C9: Jean y Marie Thierry | D9: ='C.Tec.'!D99 -> 1 | E9: ='C.Eco.'!D99 -> 0.98161873 | F9: ='C.Soc.'!D96 -> 0.29761478 | G9: ='C.Amb.'!D99 -> 0.2 | H9: ='C.Com.'!D99 -> 0.087043511
C10: Laguna Verde | D10: ='C.Tec.'!D100 -> 1 | E10: ='C.Eco.'!D100 -> 1 | F10: ='C.Soc.'!D97 -> 0.041930595 | G10: ='C.Amb.'!D100 -> 0 | H10: ='C.Com.'!D100 -> 0.000158064
C11: Las Cañas | D11: ='C.Tec.'!D101 -> 1 | E11: ='C.Eco.'!D101 -> 0.99999936 | F11: ='C.Soc.'!D98 -> 0.045411279 | G11: ='C.Amb.'!D101 -> 0.2 | H11: ='C.Com.'!D101 -> 3.0490389e-07
C12: Marcelo Mena | D12: ='C.Tec.'!D102 -> 1 | E12: ='C.Eco.'!D102 -> 0.24707253 | F12: ='C.Soc.'!D99 -> 0.60684915 | G12: ='C.Amb.'!D102 -> 1 | H12: ='C.Com.'!D102 -> 0.012388061
C13: Padre Demian Molokai | D13: ='C.Tec.'!D103 -> 0 | E13: ='C.Eco.'!D103 -> 0.2465036 | F13: ='C.Soc.'!D100 -> 0.20146727 | G13: ='C.Amb.'!D103 -> 0.2 | H13: ='C.Com.'!D103 -> 7.4434903e-05
C14: Placeres | D14: ='C.Tec.'!D104 -> 0 | E14: ='C.Eco.'!D104 -> 0.98110127 | F14: ='C.Soc.'!D101 -> 0.44840509 | G14: ='C.Amb.'!D104 -> 0.8 | H14: ='C.Com.'!D104 -> 0.0054602435
C15: Placilla | D15: ='C.Tec.'!D105 -> 0.87618801 | E15: ='C.Eco.'!D105 -> 0.98202359 | F15: ='C.Soc.'!D102 -> 0.83096674 | G15: ='C.Amb.'!D105 -> 1 | H15: ='C.Com.'!D105 -> 0.065785158
C16: Plaza Justicia | D16: ='C.Tec.'!D106 -> 1 | E16: ='C.Eco.'!D106 -> 0 | F16: ='C.Soc.'!D103 -> 0.68866453 | G16: ='C.Amb.'!D106 -> 1 | H16: ='C.Com.'!D106 -> 1
C17: Puertas Negras | D17: ='C.Tec.'!D107 -> 1 | E17: ='C.Eco.'!D107 -> 0.99999956 | F17: ='C.Soc.'!D104 -> 0.079997174 | G17: ='C.Amb.'!D107 -> 0 | H17: ='C.Com.'!D107 -> 0
C18: Quebrada Verde | D18: ='C.Tec.'!D108 -> 1 | E18: ='C.Eco.'!D108 -> 8.5595701e-05 | F18: ='C.Soc.'!D105 -> 0.54049409 | G18: ='C.Amb.'!D108 -> 0.8 | H18: ='C.Com.'!D108 -> 0.0030182647
... C20: Rodelillo | D20: ='C.Tec.'!D110 -> 0 | E20: ='C.Eco.'!D110 -> 0.24693024 | F20: ='C.Soc.'!D107 -> 0.40566218 | G20: ='C.Amb.'!D110 -> 0.8 | H20: ='C.Com.'!D110 -> 0.00067801563
D21: {=SQRT(SUMPRODUCT(D6:D20^2))} -> 2.9610311 | E21: {=SQRT(SUMPRODUCT(E6:E20^2))} -> 3.0099017 | F21: {=SQRT(SUMPRODUCT(F6:F20^2))} -> 1.6959907 | G21: {=SQRT(SUMPRODUCT(G6:G20^2))} -> 2.712932 | H21: {=SQRT(SUMPRODUCT(H6:H20^2))} -> 1.0060627
B23: Alternativas | C23: Baron | D23: =D6/D$21 -> 0 | E23: =E6/E$21 -> 0.3258863 | F23: =F6/F$21 -> 0.21392513 | G23: =G6/G$21 -> 0.29488391 | H23: =H6/H$21 -> 0.0070809243
C24: Cordillera | D24: =D7/D$21 -> 0.33772019 | E24: =E7/E$21 -> 0.32616988 | F24: =F7/F$21 -> 0.084121793 | G24: =G7/G$21 -> 0.29488391 | H24: =H7/H$21 -> 0.00013663522
C25: Esperanza | D25: =D8/D$21 -> 0 | E25: =E8/E$21 -> 0.33223639 | F25: =F8/F$21 -> 0.067521505 | G25: =G8/G$21 -> 0.073720978 | H25: =H8/H$21 -> 0.00054580906
C26: Jean y Marie Thierry | D26: =D9/D$21 -> 0.33772019 | E26: =E9/E$21 -> 0.32612984 | F26: =F9/F$21 -> 0.17548137 | G26: =G9/G$21 -> 0.073720978 | H26: =H9/H$21 -> 0.086518973
C27: Laguna Verde | D27: =D10/D$21 -> 0.33772019 | E27: =E10/E$21 -> 0.33223677 | F27: =F10/F$21 -> 0.024723363 | G27: =G10/G$21 -> 0 | H27: =H10/H$21 -> 0.00015711149
C28: Las Cañas | D28: =D11/D$21 -> 0.33772019 | E28: =E11/E$21 -> 0.33223656 | F28: =F11/F$21 -> 0.026775665 | G28: =G11/G$21 -> 0.073720978 | H28: =H11/H$21 -> 3.0306649e-07
C29: Marcelo Mena | D29: =D12/D$21 -> 0.33772019 | E29: =E12/E$21 -> 0.08208658 | F29: =F12/F$21 -> 0.35781396 | G29: =G12/G$21 -> 0.36860489 | H29: =H12/H$21 -> 0.012313409
C30: Padre Demian Molokai | D30: =D13/D$21 -> 0 | E30: =E13/E$21 -> 0.081897559 | F30: =F13/F$21 -> 0.11879031 | G30: =G13/G$21 -> 0.073720978 | H30: =H13/H$21 -> 7.3986347e-05
C31: Placeres | D31: =D14/D$21 -> 0 | E31: =E14/E$21 -> 0.32595791 | F31: =F14/F$21 -> 0.26439124 | G31: =G14/G$21 -> 0.29488391 | H31: =H14/H$21 -> 0.0054273392
C32: Placilla | D32: =D15/D$21 -> 0.29590638 | E32: =E15/E$21 -> 0.32626434 | F32: =F15/F$21 -> 0.48995948 | G32: =G15/G$21 -> 0.36860489 | H32: =H15/H$21 -> 0.065388726
C33: Plaza Justicia | D33: =D16/D$21 -> 0.33772019 | E33: =E16/E$21 -> 0 | F33: =F16/F$21 -> 0.40605442 | G33: =G16/G$21 -> 0.36860489 | H33: =H16/H$21 -> 0.99397385
C34: Puertas Negras | D34: =D17/D$21 -> 0.33772019 | E34: =E17/E$21 -> 0.33223662 | F34: =F17/F$21 -> 0.047168403 | G34: =G17/G$21 -> 0 | H34: =H17/H$21 -> 0
C35: Quebrada Verde | D35: =D18/D$21 -> 0.33772019 | E35: =E18/E$21 -> 2.8438039e-05 | F35: =F18/F$21 -> 0.31868929 | G35: =G18/G$21 -> 0.29488391 | H35: =H18/H$21 -> 0.0030000762
... C37: Rodelillo | D37: =D20/D$21 -> 0 | E37: =E20/E$21 -> 0.082039304 | F37: =F20/F$21 -> 0.23918891 | G37: =G20/G$21 -> 0.29488391 | H37: =H20/H$21 -> 0.00067392981
B39: Alternativas | C39: Baron | D39: =D23*D$5 -> 0 | E39: =E23*E$5 -> 0.066480804 | F39: =F23*F$5 -> 0.061696006 | G39: =G23*G$5 -> 0.036860489 | H39: =H23*H$5 -> 0.00085749994
C40: Cordillera | D40: =D24*D$5 -> 0.08831383 | E40: =E24*E$5 -> 0.066538655 | F40: =F24*F$5 -> 0.024260725 | G40: =G24*G$5 -> 0.036860489 | H40: =H24*H$5 -> 1.6546526e-05
C41: Esperanza | D41: =D25*D$5 -> 0 | E41: =E25*E$5 -> 0.067776224 | F41: =F25*F$5 -> 0.019473202 | G41: =G25*G$5 -> 0.0092151223 | H41: =H25*H$5 -> 6.6097478e-05
C42: Jean y Marie Thierry | D42: =D26*D$5 -> 0.08831383 | E42: =E26*E$5 -> 0.066530486 | F42: =F26*F$5 -> 0.050608827 | G42: =G26*G$5 -> 0.0092151223 | H42: =H26*H$5 -> 0.010477448
C43: Laguna Verde | D43: =D27*D$5 -> 0.08831383 | E43: =E27*E$5 -> 0.067776301 | F43: =F27*F$5 -> 0.007130218 | G43: =G27*G$5 -> 0 | H43: =H27*H$5 -> 1.9026201e-05
C44: Las Cañas | D44: =D28*D$5 -> 0.08831383 | E44: =E28*E$5 -> 0.067776258 | F44: =F28*F$5 -> 0.0077221017 | G44: =G28*G$5 -> 0.0092151223 | H44: =H28*H$5 -> 3.6701352e-08
C45: Marcelo Mena | D45: =D29*D$5 -> 0.08831383 | E45: =E29*E$5 -> 0.016745662 | F45: =F29*F$5 -> 0.10319354 | G45: =G29*G$5 -> 0.046075611 | H45: =H29*H$5 -> 0.0014911538
...

Sheet C.Tec.
B2: Datos cuantificados de los criterios y alternativas | D2: Criterios
D3: Técnico
D4: Capacidad técnica de la red eléctrica
B5: Pesos: | D5: 1
B6: Alternativas | C6: Baron | D6: 23.508
C7: Cordillera | D7: 46.97
C8: Esperanza | D8: 23.508
C9: Jean y Marie Thierry | D9: 46.97
C10: Laguna Verde | D10: 46.97
C11: Las Cañas | D11: 46.97
C12: Marcelo Mena | D12: 46.97
C13: Padre Demian Molokai | D13: 23.508
C14: Placeres | D14: 23.508
C15: Placilla | D15: 40.56
C16: Plaza Justicia | D16: 46.97
C17: Puertas Negras | D17: 46.97
C18: Quebrada Verde | D18: 46.97
... C20: Rodelillo | D20: 23.508
C21: Total | D21: =SUM(D6:D20) -> 557.368
B23: Datos cuantificados de los criterios y alternativas | D23: Criterios
D24: Técnico
D25: Capacidad técnica de la red eléctrica
B26: Pesos: | D26: 1
B27: Alternativas | C27: Baron | D27: =D6/$D$21 -> 0.042176802
C28: Cordillera | D28: =D7/$D$21 -> 0.084271074
C29: Esperanza | D29: =D8/$D$21 -> 0.042176802
C30: Jean y Marie Thierry | D30: =D9/$D$21 -> 0.084271074
C31: Laguna Verde | D31: =D10/$D$21 -> 0.084271074
C32: Las Cañas | D32: =D11/$D$21 -> 0.084271074
C33: Marcelo Mena | D33: =D12/$D$21 -> 0.084271074
C34: Padre Demian Molokai | D34: =D13/$D$21 -> 0.042176802
C35: Placeres | D35: =D14/$D$21 -> 0.042176802
C36: Placilla | D36: =D15/$D$21 -> 0.072770593
C37: Plaza Justicia | D37: =D16/$D$21 -> 0.084271074
C38: Puertas Negras | D38: =D17/$D$21 -> 0.084271074
C39: Quebrada Verde | D39: =D18/$D$21 -> 0.084271074
... C41: Rodelillo | D41: =D20/$D$21 -> 0.042176802
D42: {=SQRT(SUMPRODUCT(D27:D41^2))} -> 0.26978096
B44: Alternativas | C44: Baron | D44: =D27/D$42 -> 0.15633721
C45: Cordillera | D45: =D28/D$42 -> 0.3123685
...

Sheet C.Eco.
B2: Datos cuantificados de los criterios y alternativas | D2: Criterios
D3: Económico
D4: Costos de instalación, operación y mantenimiento
B5: Pesos: | D5: 1
B6: Alternativas | C6: Baron | D6: 170166760
C7: Cordillera | D7: 168766760
C8: Esperanza | D8: 101617920
C9: Jean y Marie Thierry | D9: 168966760
C10: Laguna Verde | D10: 101017920
C11: Las Cañas | D11: 101467920
C12: Marcelo Mena | D12: 459923406
C13: Padre Demian Molokai | D13: 460123406
C14: Placeres | D14: 169816760
C15: Placilla | D15: 168291760
C16: Plaza Justicia | D16: 665519926
C17: Puertas Negras | D17: 101392920
C18: Quebrada Verde | D18: 660344926
... C20: Rodelillo | D20: 459973406
C21: Total | D21: =SUM(D6:D20) -> 4417863956
B23: Datos cuantificados de los criterios y alternativas | D23: Criterios
D24: Técnico
D25: Capacidad técnica de la red eléctrica
B26: Pesos: | D26: 1
B27: Alternativas | C27: Baron | D27: =D6/$D$21 -> 0.038517881
C28: Cordillera | D28: =D7/$D$21 -> 0.038200986
C29: Esperanza | D29: =D8/$D$21 -> 0.023001596
C30: Jean y Marie Thierry | D30: =D9/$D$21 -> 0.038246257
C31: Laguna Verde | D31: =D10/$D$21 -> 0.022865783
C32: Las Cañas | D32: =D11/$D$21 -> 0.022967643
C33: Marcelo Mena | D33: =D12/$D$21 -> 0.10410538
C34: Padre Demian Molokai | D34: =D13/$D$21 -> 0.10415065
C35: Placeres | D35: =D14/$D$21 -> 0.038438658
C36: Placilla | D36: =D15/$D$21 -> 0.038093468
C37: Plaza Justicia | D37: =D16/$D$21 -> 0.15064292
C38: Puertas Negras | D38: =D17/$D$21 -> 0.022950666
C39: Quebrada Verde | D39: =D18/$D$21 -> 0.14947154
... C41: Rodelillo | D41: =D20/$D$21 -> 0.1041167
D42: {=SQRT(SUMPRODUCT(D27:D41^2))} -> 0.31283382
B44: Alternativas | C44: Baron | D44: =D27/D$42 -> 0.1231257
C45: Cordillera | D45: =D28/D$42 -> 0.12211271
...

Sheet C.Soc.
B2: Datos cuantificados de los criterios y alternativas | D2: Criterios
D3: Social
D4: Cantidad de personas total | E4: Cantidad de personas por vulnerabilidd
E5: A | F5: B | G5: C | H5: D
B6: Pesos: | D6: 0.5 | E6: 0.2 | F6: =E6*0.75 -> 0.15 | G6: =E6*0.5 -> 0.1 | H6: =E6*0.25 -> 0.05 | I6: =SUM(D6:H6) -> 1
B7: Alternativas | C7: Baron | D7: 18776 | E7: 0 | F7: 11379 | G7: 6755 | H7: 642
C8: Cordillera | D8: 9919 | E8: 0 | F8: 2365 | G8: 6602 | H8: 952
C9: Esperanza | D9: 8014 | E9: 0 | F9: 3075 | G9: 4698 | H9: 241
C10: Jean y Marie Thierry | D10: 16950 | E10: 2531 | F10: 4168 | G10: 10251 | H10: 0
C11: Laguna Verde | D11: 4271 | E11: 0 | F11: 0 | G11: 1352 | H11: 2919
C12: Las Cañas | D12: 4788 | E12: 0 | F12: 0 | G12: 1836 | H12: 2952
C13: Marcelo Mena | D13: 33841 | E13: 5674 | F13: 9896 | G13: 17044 | H13: 1227
C14: Padre Demian Molokai | D14: 10687 | E14: 540 | F14: 6660 | G14: 1264 | H14: 2223
C15: Placeres | D15: 21459 | E15: 10219 | F15: 1767 | G15: 9133 | H15: 340
C16: Placilla | D16: 39496 | E16: 22476 | F16: 4888 | G16: 9418 | H16: 2714
C17: Plaza Justicia | D17: 33458 | E17: 11660 | F17: 9441 | G17: 12357 | H17: 0
C18: Puertas Negras | D18: 5813 | E18: 0 | F18: 384 | G18: 0 | H18: 5429
C19: Quebrada Verde | D19: 33319 | E19: 1536 | F19: 6341 | G19: 18382 | H19: 7060
... C21: Rodelillo | D21: 24054 | E21: 1327 | F21: 3283 | G21: 12122 | H21: 7322
D22: =SUM(D7:D21) -> 296675 | E22: =SUM(E7:E21) -> 64629 | F22: =SUM(F7:F21) -> 71000 | G22: =SUM(G7:G21) -> 123973 | H22: =SUM(H7:H21) -> 37073
B24: Alternativas | C24: Baron | D24: =D7/D$22 -> 0.06328811 | E24: =E7/E$22 -> 0 | F24: =F7/F$22 -> 0.16026761 | G24: =G7/G$22 -> 0.054487671 | H24: =H7/H$22 -> 0.017317185
C25: Cordillera | D25: =D8/D$22 -> 0.033433892 | E25: =E8/E$22 -> 0 | F25: =F8/F$22 -> 0.033309859 | G25: =G8/G$22 -> 0.053253531 | H25: =H8/H$22 -> 0.025679066
C26: Esperanza | D26: =D9/D$22 -> 0.027012724 | E26: =E9/E$22 -> 0 | F26: =F9/F$22 -> 0.043309859 | G26: =G9/G$22 -> 0.037895348 | H26: =H9/H$22 -> 0.0065006878
C27: Jean y Marie Thierry | D27: =D10/D$22 -> 0.057133227 | E27: =E10/E$22 -> 0.039161986 | F27: =F10/F$22 -> 0.058704225 | G27: =G10/G$22 -> 0.082687359 | H27: =H10/H$22 -> 0
C28: Laguna Verde | D28: =D11/D$22 -> 0.014396225 | E28: =E11/E$22 -> 0 | F28: =F11/F$22 -> 0 | G28: =G11/G$22 -> 0.0109056 | H28: =H11/H$22 -> 0.078736547
C29: Las Cañas | D29: =D12/D$22 -> 0.016138873 | E29: =E12/E$22 -> 0 | F29: =F12/F$22 -> 0 | G29: =G12/G$22 -> 0.014809676 | H29: =H12/H$22 -> 0.079626682
C30: Marcelo Mena | D30: =D13/D$22 -> 0.11406758 | E30: =E13/E$22 -> 0.087793405 | F30: =F13/F$22 -> 0.13938028 | G30: =G13/G$22 -> 0.13748155 | H30: =H13/H$22 -> 0.033096863
C31: Padre Demian Molokai | D31: =D14/D$22 -> 0.036022584 | E31: =E14/E$22 -> 0.0083553823 | F31: =F14/F$22 -> 0.093802817 | G31: =G14/G$22 -> 0.010195768 | H31: =H14/H$22 -> 0.059962776
C32: Placeres | D32: =D15/D$22 -> 0.072331676 | E32: =E15/E$22 -> 0.15811787 | F32: =F15/F$22 -> 0.024887324 | G32: =G15/G$22 -> 0.073669267 | H32: =H15/H$22 -> 0.0091710949
C33: Placilla | D33: =D16/D$22 -> 0.13312884 | E33: =E16/E$22 -> 0.34776958 | F33: =F16/F$22 -> 0.06884507 | G33: =G16/G$22 -> 0.075968154 | H33: =H16/H$22 -> 0.073206916
C34: Plaza Justicia | D34: =D17/D$22 -> 0.11277661 | E34: =E17/E$22 -> 0.18041437 | F34: =F17/F$22 -> 0.13297183 | G34: =G17/G$22 -> 0.099674929 | H34: =H17/H$22 -> 0
C35: Puertas Negras | D35: =D18/D$22 -> 0.019593832 | E35: =E18/E$22 -> 0 | F35: =F18/F$22 -> 0.0054084507 | G35: =G18/G$22 -> 0 | H35: =H18/H$22 -> 0.14644081
C36: Quebrada Verde | D36: =D19/D$22 -> 0.11230808 | E36: =E19/E$22 -> 0.023766421 | F36: =F19/F$22 -> 0.089309859 | G36: =G19/G$22 -> 0.14827422 | H36: =H19/H$22 -> 0.19043509
... C38: Rodelillo | D38: =D21/D$22 -> 0.081078621 | E38: =E21/E$22 -> 0.020532578 | F38: =F21/F$22 -> 0.046239437 | G38: =G21/G$22 -> 0.097779355 | H38: =H21/H$22 -> 0.19750223
D39: {=SQRT(SUMPRODUCT(D24:D38^2))} -> 0.30108023 | E39: {=SQRT(SUMPRODUCT(E24:E38^2))} -> 0.45472142 | F39: {=SQRT(SUMPRODUCT(F24:F38^2))} -> 0.32288157 | G39: {=SQRT(SUMPRODUCT(G24:G38^2))} -> 0.31095494 | H39: {=SQRT(SUMPRODUCT(H24:H38^2))} -> 0.35660976
B41: Alternativas | C41: Baron | D41: =D24/D$39 -> 0.21020348 | E41: =E24/E$39 -> 0 | F41: =F24/F$39 -> 0.49636654 | G41: =G24/G$39 -> 0.1752269 | H41: =H24/H$39 -> 0.048560603
C42: Cordillera | D42: =D25/D$39 -> 0.11104646 | E42: =E25/E$39 -> 0 | F42: =F25/F$39 -> 0.10316433 | G42: =G25/G$39 -> 0.17125803 | H42: =H25/H$39 -> 0.072008869
C43: Esperanza | D43: =D26/D$39 -> 0.089719357 | E43: =E26/E$39 -> 0 | F43: =F26/F$39 -> 0.13413543 | G43: =G26/G$39 -> 0.12186765 | H43: =H26/H$39 -> 0.018229136
C44: Jean y Marie Thierry | D44: =D27/D$39 -> 0.18976081 | E44: =E27/E$39 -> 0.086123029 | F44: =F27/F$39 -> 0.18181349 | G44: =G27/G$39 -> 0.26591428 | H44: =H27/H$39 -> 0
C45: Laguna Verde | D45: =D28/D$39 -> 0.047815245 | E45: =E28/E$39 -> 0 | F45: =F28/F$39 -> 0 | G45: =G28/G$39 -> 0.03507132 | H45: =H28/H$39 -> 0.2207919
...

Sheet C.Amb.
B2: Datos cuantificados de los criterios y alternativas | D2: Criterios
D3: Ambiental
D4: Calles con ato flujo y emisiones de CO2
B5: Pesos: | D5: 1
B6: Alternativas | C6: Baron | D6: 3
C7: Cordillera | D7: 3
C8: Esperanza | D8: 2
C9: Jean y Marie Thierry | D9: 2
C10: Laguna Verde | D10: 1
C11: Las Cañas | D11: 2
C12: Marcelo Mena | D12: 4
C13: Padre Demian Molokai | D13: 2
C14: Placeres | D14: 3
C15: Placilla | D15: 4
C16: Plaza Justicia | D16: 4
C17: Puertas Negras | D17: 1
C18: Quebrada Verde | D18: 3
... C20: Rodelillo | D20: 3
C21: Total | D21: =SUM(D6:D20) -> 41
B23: Datos cuantificados de los criterios y alternativas | D23: Criterios
D24: Técnico
D25: Capacidad técnica de la red eléctrica
B26: Pesos: | D26: 1
B27: Alternativas | C27: Baron | D27: =D6/$D$21 -> 0.073170732
C28: Cordillera | D28: =D7/$D$21 -> 0.073170732
C29: Esperanza | D29: =D8/$D$21 -> 0.048780488
C30: Jean y Marie Thierry | D30: =D9/$D$21 -> 0.048780488
C31: Laguna Verde | D31: =D10/$D$21 -> 0.024390244
C32: Las Cañas | D32: =D11/$D$21 -> 0.048780488
C33: Marcelo Mena | D33: =D12/$D$21 -> 0.097560976
C34: Padre Demian Molokai | D34: =D13/$D$21 -> 0.048780488
C35: Placeres | D35: =D14/$D$21 -> 0.073170732
C36: Placilla | D36: =D15/$D$21 -> 0.097560976
C37: Plaza Justicia | D37: =D16/$D$21 -> 0.097560976
C38: Puertas Negras | D38: =D17/$D$21 -> 0.024390244
C39: Quebrada Verde | D39: =D18/$D$21 -> 0.073170732
... C41: Rodelillo | D41: =D20/$D$21 -> 0.073170732
D42: {=SQRT(SUMPRODUCT(D27:D41^2))} -> 0.27486409
B44: Alternativas | C44: Baron | D44: =D27/D$42 -> 0.26620695
C45: Cordillera | D45: =D28/D$42 -> 0.26620695
...

Sheet C.Com.
B2: Datos cuantificados de los criterios y alternativas | D2: Criterios
D3: Comercial
D4: Cercanica y fomento al turismo y comercio
B5: Pesos: | D5: 1
B6: Alternativas | C6: Baron | D6: 322
C7: Cordillera | D7: 81
C8: Esperanza | D8: 122
C9: Jean y Marie Thierry | D9: 894
C10: Laguna Verde | D10: 84
C11: Las Cañas | D11: 41
C12: Marcelo Mena | D12: 404
C13: Padre Demian Molokai | D13: 70
C14: Placeres | D14: 289
C15: Placilla | D15: 799
C16: Plaza Justicia | D16: 3663
C17: Puertas Negras | D17: 39
C18: Quebrada Verde | D18: 228
... C20: Rodelillo | D20: 131
C21: Total | D21: =SUM(D6:D20) -> 7415
B23: Datos cuantificados de los criterios y alternativas | D23: Criterios
D24: Técnico
D25: Capacidad técnica de la red eléctrica
B26: Pesos: | D26: 1
B27: Alternativas | C27: Baron | D27: =D6/$D$21 -> 0.043425489
C28: Cordillera | D28: =D7/$D$21 -> 0.010923803
C29: Esperanza | D29: =D8/$D$21 -> 0.016453136
C30: Jean y Marie Thierry | D30: =D9/$D$21 -> 0.12056642
C31: Laguna Verde | D31: =D10/$D$21 -> 0.011328388
C32: Las Cañas | D32: =D11/$D$21 -> 0.0055293324
C33: Marcelo Mena | D33: =D12/$D$21 -> 0.054484154
C34: Padre Demian Molokai | D34: =D13/$D$21 -> 0.0094403237
C35: Placeres | D35: =D14/$D$21 -> 0.038975051
C36: Placilla | D36: =D15/$D$21 -> 0.10775455
C37: Plaza Justicia | D37: =D16/$D$21 -> 0.49399865
C38: Puertas Negras | D38: =D17/$D$21 -> 0.0052596089
C39: Quebrada Verde | D39: =D18/$D$21 -> 0.030748483
... C41: Rodelillo | D41: =D20/$D$21 -> 0.017666891
D42: {=SQRT(SUMPRODUCT(D27:D41^2))} -> 0.52876956
B44: Alternativas | C44: Baron | D44: =D27/D$42 -> 0.082125545
C45: Cordillera | D45: =D28/D$42 -> 0.020658911
...

Sheet Inicio AHP
B2: Datos cuantificados de los criterios y alternativas | D2: Criterios
D3: Técnico | E3: Económico | F3: Social | G3: Ambiental | H3: Comercial
D4: Capacidad técnica de la red eléctrica | E4: Costos de instalación, operación y mantenimiento | F4: Cantidad de Personas beneficiadas | G4: Calles con ato flujo y emisiones de CO2 | H4: Cercanica y fomento al turismo y comercio
B5: Alternativas | C5: Baron
C6: Cordillera
C7: Esperanza
C8: Jean y Marie Thierry
C9: Laguna Verde
C10: Las Cañas
C11: Marcelo Mena
C12: Padre Demian Molokai
C13: Placeres | J13: Axw | K13: cocientes | L13: λmax | M13: n | N13: RI | P13: CI=(λmax-n)/(n-1) | Q13: =(L14-M14)/(M14-1) -> 0
C14: Placilla | J14: =SUMPRODUCT(D24:H24,$D$49:$H$49) -> 1 | K14: =J14/N24 -> 5 | L14: =AVERAGE(K14:K18) -> 5 | M14: 5 | N14: 1.12 | P14: CR=CI/RI | Q14: =Q13/N14 -> 0
C15: Plaza Justicia | J15: =SUMPRODUCT(D25:H25,$D$49:$H$49) -> 1 | K15: =J15/N25 -> 5
C16: Puertas Negras | J16: =SUMPRODUCT(D26:H26,$D$49:$H$49) -> 1 | K16: =J16/N26 -> 5
C17: Quebrada Verde | J17: =SUMPRODUCT(D27:H27,$D$49:$H$49) -> 1 | K17: =J17/N27 -> 5
C18: Reina Isabel 2 | J18: =SUMPRODUCT(D28:H28,$D$49:$H$49) -> 1 | K18: =J18/N28 -> 5
C19: Rodelillo
C22: Importancia o Jerarquia de Criterios
C23: Criterios | D23: Técnico | E23: Económico | F23: Social | G23: Ambiental | H23: Comercial | I23: Matriz normalizada | N23: Ponderación
C24: Técnico | D24: 1 | E24: 1 | F24: 1 | G24: 1 | H24: 1 | I24: =D24/D$29 -> 0.2 | J24: =E24/E$29 -> 0.2 | K24: =F24/F$29 -> 0.2 | L24: =G24/G$29 -> 0.2 | M24: =H24/H$29 -> 0.2 | N24: =AVERAGE(I24:M24) -> 0.2
C25: Económico | D25: =1/E24 -> 1 | E25: 1 | F25: 1 | G25: 1 | H25: 1 | I25: =D25/D$29 -> 0.2 | J25: =E25/E$29 -> 0.2 | K25: =F25/F$29 -> 0.2 | L25: =G25/G$29 -> 0.2 | M25: =H25/H$29 -> 0.2 | N25: =AVERAGE(I25:M25) -> 0.2
C26: Social | D26: =1/F24 -> 1 | E26: =1/F25 -> 1 | F26: 1 | G26: 1 | H26: 1 | I26: =D26/D$29 -> 0.2 | J26: =E26/E$29 -> 0.2 | K26: =F26/F$29 -> 0.2 | L26: =G26/G$29 -> 0.2 | M26: =H26/H$29 -> 0.2 | N26: =AVERAGE(I26:M26) -> 0.2
C27: Ambiental | D27: =1/G24 -> 1 | E27: =1/G25 -> 1 | F27: =1/G26 -> 1 | G27: 1 | H27: 1 | I27: =D27/D$29 -> 0.2 | J27: =E27/E$29 -> 0.2 | K27: =F27/F$29 -> 0.2 | L27: =G27/G$29 -> 0.2 | M27: =H27/H$29 -> 0.2 | N27: =AVERAGE(I27:M27) -> 0.2
C28: Comercial | D28: =1/H24 -> 1 | E28: =1/H25 -> 1 | F28: =1/H26 -> 1 | G28: =1/H27 -> 1 | H28: 1 | I28: =D28/D$29 -> 0.2 | J28: =E28/E$29 -> 0.2 | K28: =F28/F$29 -> 0.2 | L28: =G28/G$29 -> 0.2 | M28: =H28/H$29 -> 0.2 | N28: =AVERAGE(I28:M28) -> 0.2
C29: Total | D29: =SUM(D24:D28) -> 5 | E29: =SUM(E24:E28) -> 5 | F29: =SUM(F24:F28) -> 5 | G29: =SUM(G24:G28) -> 5 | H29: =SUM(H24:H28) -> 5
B32: Resultado AHP | D32: Criterios | I32: Priorización
D33: Técnico | E33: Económico | F33: Social | G33: Ambiental | H33: Comercial
B34: Alternativas | C34: Baron | D34: ='C. Téc.'!AG4 -> 0.014769211 | E34: ='C. Eco.'!AG4 -> 0.061340895 | F34: ='C. So.'!AG4 -> 0.087405749 | G34: ='C. Am.'!AG4 -> 0.061075983 | H34: ='C. Com.'!AG4 -> 0.051497491 | I34: =SUMPRODUCT(D34:H34,$D$49:$H$49) -> 0.055217866
C35: Cordillera | D35: ='C. Téc.'!AG5 -> 0.10745572 | E35: ='C. Eco.'!AG5 -> 0.061340895 | F35: ='C. So.'!AG5 -> 0.04457811 | G35: ='C. Am.'!AG5 -> 0.061075983 | H35: ='C. Com.'!AG5 -> 0.020438782 | I35: =SUMPRODUCT(D35:H35,$D$49:$H$49) -> 0.058977898
C36: Esperanza | D36: ='C. Téc.'!AG6 -> 0.014769211 | E36: ='C. Eco.'!AG6 -> 0.15433205 | F36: ='C. So.'!AG6 -> 0.049731154 | G36: ='C. Am.'!AG6 -> 0.026522482 | H36: ='C. Com.'!AG6 -> 0.051497491 | I36: =SUMPRODUCT(D36:H36,$D$49:$H$49) -> 0.059370478
C37: Jean y Marie Thierry | D37: ='C. Téc.'!AG7 -> 0.10745572 | E37: ='C. Eco.'!AG7 -> 0.061340895 | F37: ='C. So.'!AG7 -> 0.049731154 | G37: ='C. Am.'!AG7 -> 0.026522482 | H37: ='C. Com.'!AG7 -> 0.12032109 | I37: =SUMPRODUCT(D37:H37,$D$49:$H$49) -> 0.073074269
C38: Laguna Verde | D38: ='C. Téc.'!AG8 -> 0.10745572 | E38: ='C. Eco.'!AG8 -> 0.15433205 | F38: ='C. So.'!AG8 -> 0.034951488 | G38: ='C. Am.'!AG8 -> 0.013431408 | H38: ='C. Com.'!AG8 -> 0.020438782 | I38: =SUMPRODUCT(D38:H38,$D$49:$H$49) -> 0.06612189
C39: Las Cañas | D39: ='C. Téc.'!AG9 -> 0.10745572 | E39: ='C. Eco.'!AG9 -> 0.15433205 | F39: ='C. So.'!AG9 -> 0.034951488 | G39: ='C. Am.'!AG9 -> 0.026522482 | H39: ='C. Com.'!AG9 -> 0.020438782 | I39: =SUMPRODUCT(D39:H39,$D$49:$H$49) -> 0.068740105
C40: Marcelo Mena | D40: ='C. Téc.'!AG10 -> 0.10745572 | E40: ='C. Eco.'!AG10 -> 0.014197254 | F40: ='C. So.'!AG10 -> 0.12617952 | G40: ='C. Am.'!AG10 -> 0.14041683 | H40: ='C. Com.'!AG10 -> 0.12032109 | I40: =SUMPRODUCT(D40:H40,$D$49:$H$49) -> 0.10171408
C41: Padre Demian Molokai | D41: ='C. Téc.'!AG11 -> 0.014769211 | E41: ='C. Eco.'!AG11 -> 0.014197254 | F41: ='C. So.'!AG11 -> 0.034951488 | G41: ='C. Am.'!AG11 -> 0.026522482 | H41: ='C. Com.'!AG11 -> 0.020438782 | I41: =SUMPRODUCT(D41:H41,$D$49:$H$49) -> 0.022175843
C42: Placeres | D42: ='C. Téc.'!AG12 -> 0.014769211 | E42: ='C. Eco.'!AG12 -> 0.061340895 | F42: ='C. So.'!AG12 -> 0.067387305 | G42: ='C. Am.'!AG12 -> 0.061075983 | H42: ='C. Com.'!AG12 -> 0.051497491 | I42: =SUMPRODUCT(D42:H42,$D$49:$H$49) -> 0.051214177
C43: Placilla | D43: ='C. Téc.'!AG13 -> 0.051738972 | E43: ='C. Eco.'!AG13 -> 0.061340895 | F43: ='C. So.'!AG13 -> 0.14815007 | G43: ='C. Am.'!AG13 -> 0.14041683 | H43: ='C. Com.'!AG13 -> 0.12032109 | I43: =SUMPRODUCT(D43:H43,$D$49:$H$49) -> 0.10439357
C44: Plaza Justicia | D44: ='C. Téc.'!AG14 -> 0.10745572 | E44: ='C. Eco.'!AG14 -> 0.0091778788 | F44: ='C. So.'!AG14 -> 0.14264043 | G44: ='C. Am.'!AG14 -> 0.14041683 | H44: ='C. Com.'!AG14 -> 0.22785787 | I44: =SUMPRODUCT(D44:H44,$D$49:$H$49) -> 0.12550975
C45: Puertas Negras | D45: ='C. Téc.'!AG15 -> 0.10745572 | E45: ='C. Eco.'!AG15 -> 0.15433205 | F45: ='C. So.'!AG15 -> 0.012492427 | G45: ='C. Am.'!AG15 -> 0.013431408 | H45: ='C. Com.'!AG15 -> 0.020438782 | I45: =SUMPRODUCT(D45:H45,$D$49:$H$49) -> 0.061630078
...

Sheet C. Téc.
B2: Criterio Técnico
B3: Alternativas | C3: Baron | D3: Cordillera | E3: Esperanza | F3: Jean y Marie Thierry | G3: Laguna Verde | H3: Las Cañas | I3: Marcelo Mena | J3: Padre Demian Molokai | K3: Placeres | L3: Placilla | M3: Plaza Justicia | N3: Puertas Negras | O3: Quebrada Verde | P3: Reina Isabel 2 | Q3: Rodelillo | R3: Matriz normalizada | AG3: Vector Promedio | AI3: Axw | AJ3: cocientes | AK3: λmax | AL3: n | AM3: RI | AO3: CI=(λmax-n)/(n-1) | AP3: =(AK4-AL4)/(AL4-1) -> 0.009205889
B4: Baron | C4: 1 | D4: 0.14285714 | E4: 1 | F4: 0.14285714 | G4: 0.14285714 | H4: 0.14285714 | I4: 0.14285714 | J4: 1 | K4: 1 | L4: 0.2 | M4: 0.14285714 | N4: 0.14285714 | O4: 0.14285714 | P4: 1 | Q4: 1 | R4: =C4/C$19 -> 0.014925373 | S4: =D4/D$19 -> 0.015544041 | T4: =E4/E$19 -> 0.014925373 | U4: =F4/F$19 -> 0.015544041 | V4: =G4/G$19 -> 0.015544041 | W4: =H4/H$19 -> 0.015544041 | X4: =I4/I$19 -> 0.015544041 | Y4: =J4/J$19 -> 0.014925373 | ... AF4: =Q4/Q$19 -> 0.014925373 | AG4: =AVERAGE(R4:AF4) -> 0.014769211 | AI4: =SUMPRODUCT(C4:Q4,$C$20:$Q$20) -> 0.2217696 | AJ4: =AI4/AG4 -> 15.01567 | AK4: =AVERAGE(AJ4:AJ18) -> 15.128882 | AL4: 15 | AM4: =(1.86668*(15-2))/15 -> 1.6177893 | AO4: CR=CI/RI | AP4: =AP3/AM4 -> 0.0056904127
B5: Cordillera | C5: =1/D4 -> 7 | D5: 1 | E5: 7 | F5: 1 | G5: 1 | H5: 1 | I5: 1 | J5: 7 | K5: 7 | L5: 3 | M5: 1 | N5: 1 | O5: 1 | P5: 7 | Q5: 7 | R5: =C5/C$19 -> 0.10447761 | S5: =D5/D$19 -> 0.10880829 | T5: =E5/E$19 -> 0.10447761 | U5: =F5/F$19 -> 0.10880829 | V5: =G5/G$19 -> 0.10880829 | W5: =H5/H$19 -> 0.10880829 | X5: =I5/I$19 -> 0.10880829 | Y5: =J5/J$19 -> 0.10447761 | ... AF5: =Q5/Q$19 -> 0.10447761 | AG5: =AVERAGE(R5:AF5) -> 0.10745572 | AI5: =SUMPRODUCT(C5:Q5,$C$20:$Q$20) -> 1.6351695 | AJ5: =AI5/AG5 -> 15.217147
B6: Esperanza | C6: =1/E4 -> 1 | D6: =1/E5 -> 0.14285714 | E6: 1 | F6: 0.14285714 | G6: 0.14285714 | H6: 0.14285714 | I6: 0.14285714 | J6: 1 | K6: 1 | L6: 0.2 | M6: 0.14285714 | N6: 0.14285714 | O6: 0.14285714 | P6: 1 | Q6: 1 | R6: =C6/C$19 -> 0.014925373 | S6: =D6/D$19 -> 0.015544041 | T6: =E6/E$19 -> 0.014925373 | U6: =F6/F$19 -> 0.015544041 | V6: =G6/G$19 -> 0.015544041 | W6: =H6/H$19 -> 0.015544041 | X6: =I6/I$19 -> 0.015544041 | Y6: =J6/J$19 -> 0.014925373 | ... AF6: =Q6/Q$19 -> 0.014925373 | AG6: =AVERAGE(R6:AF6) -> 0.014769211 | AI6: =SUMPRODUCT(C6:Q6,$C$20:$Q$20) -> 0.2217696 | AJ6: =AI6/AG6 -> 15.01567
B7: Jean y Marie Thierry | C7: =1/F4 -> 7 | D7: =1/F5 -> 1 | E7: =1/F6 -> 7 | F7: 1 | G7: 1 | H7: 1 | I7: 1 | J7: 7 | K7: 7 | L7: 3 | M7: 1 | N7: 1 | O7: 1 | P7: 7 | Q7: 7 | R7: =C7/C$19 -> 0.10447761 | S7: =D7/D$19 -> 0.10880829 | T7: =E7/E$19 -> 0.10447761 | U7: =F7/F$19 -> 0.10880829 | V7: =G7/G$19 -> 0.10880829 | W7: =H7/H$19 -> 0.10880829 | X7: =I7/I$19 -> 0.10880829 | Y7: =J7/J$19 -> 0.10447761 | ... AF7: =Q7/Q$19 -> 0.10447761 | AG7: =AVERAGE(R7:AF7) -> 0.10745572 | AI7: =SUMPRODUCT(C7:Q7,$C$20:$Q$20) -> 1.6351695 | AJ7: =AI7/AG7 -> 15.217147
B8: Laguna Verde | C8: =1/G4 -> 7 | D8: =1/G5 -> 1 | E8: =1/G6 -> 7 | F8: =1/G7 -> 1 | G8: 1 | H8: 1 | I8: 1 | J8: 7 | K8: 7 | L8: 3 | M8: 1 | N8: 1 | O8: 1 | P8: 7 | Q8: 7 | R8: =C8/C$19 -> 0.10447761 | S8: =D8/D$19 -> 0.10880829 | T8: =E8/E$19 -> 0.10447761 | U8: =F8/F$19 -> 0.10880829 | V8: =G8/G$19 -> 0.10880829 | W8: =H8/H$19 -> 0.10880829 | X8: =I8/I$19 -> 0.10880829 | Y8: =J8/J$19 -> 0.10447761 | ... AF8: =Q8/Q$19 -> 0.10447761 | AG8: =AVERAGE(R8:AF8) -> 0.10745572 | AI8: =SUMPRODUCT(C8:Q8,$C$20:$Q$20) -> 1.6351695 | AJ8: =AI8/AG8 -> 15.217147
B9: Las Cañas | C9: =1/H4 -> 7 | D9: =1/H5 -> 1 | E9: =1/H6 -> 7 | F9: =1/H7 -> 1 | G9: =1/H8 -> 1 | H9: 1 | I9: 1 | J9: 7 | K9: 7 | L9: 3 | M9: 1 | N9: 1 | O9: 1 | P9: 7 | Q9: 7 | R9: =C9/C$19 -> 0.10447761 | S9: =D9/D$19 -> 0.10880829 | T9: =E9/E$19 -> 0.10447761 | U9: =F9/F$19 -> 0.10880829 | V9: =G9/G$19 -> 0.10880829 | W9: =H9/H$19 -> 0.10880829 | X9: =I9/I$19 -> 0.10880829 | Y9: =J9/J$19 -> 0.10447761 | ... AF9: =Q9/Q$19 -> 0.10447761 | AG9: =AVERAGE(R9:AF9) -> 0.10745572 | AI9: =SUMPRODUCT(C9:Q9,$C$20:$Q$20) -> 1.6351695 | AJ9: =AI9/AG9 -> 15.217147
B10: Marcelo Mena | C10: =1/I4 -> 7 | D10: =1/I5 -> 1 | E10: =1/I6 -> 7 | F10: =1/I7 -> 1 | G10: =1/I8 -> 1 | H10: =1/I9 -> 1 | I10: 1 | J10: 7 | K10: 7 | L10: 3 | M10: 1 | N10: 1 | O10: 1 | P10: 7 | Q10: 7 | R10: =C10/C$19 -> 0.10447761 | S10: =D10/D$19 -> 0.10880829 | T10: =E10/E$19 -> 0.10447761 | U10: =F10/F$19 -> 0.10880829 | V10: =G10/G$19 -> 0.10880829 | W10: =H10/H$19 -> 0.10880829 | X10: =I10/I$19 -> 0.10880829 | Y10: =J10/J$19 -> 0.10447761 | ... AF10: =Q10/Q$19 -> 0.10447761 | AG10: =AVERAGE(R10:AF10) -> 0.10745572 | AI10: =SUMPRODUCT(C10:Q10,$C$20:$Q$20) -> 1.6351695 | AJ10: =AI10/AG10 -> 15.217147
B11: Padre Demian Molokai | C11: =1/J4 -> 1 | D11: =1/J5 -> 0.14285714 | E11: =1/J6 -> 1 | F11: =1/J7 -> 0.14285714 | G11: =1/J8 -> 0.14285714 | H11: =1/J9 -> 0.14285714 | I11: =1/J10 -> 0.14285714 | J11: 1 | K11: 1 | L11: 0.2 | M11: 0.14285714 | N11: 0.14285714 | O11: 0.14285714 | P11: 1 | Q11: 1 | R11: =C11/C$19 -> 0.014925373 | S11: =D11/D$19 -> 0.015544041 | T11: =E11/E$19 -> 0.014925373 | U11: =F11/F$19 -> 0.015544041 | V11: =G11/G$19 -> 0.015544041 | W11: =H11/H$19 -> 0.015544041 | X11: =I11/I$19 -> 0.015544041 | Y11: =J11/J$19 -> 0.014925373 | ... AF11: =Q11/Q$19 -> 0.014925373 | AG11: =AVERAGE(R11:AF11) -> 0.014769211 | AI11: =SUMPRODUCT(C11:Q11,$C$20:$Q$20) -> 0.2217696 | AJ11: =AI11/AG11 -> 15.01567
B12: Placeres | C12: =1/K4 -> 1 | D12: =1/K5 -> 0.14285714 | E12: =1/K6 -> 1 | F12: =1/K7 -> 0.14285714 | G12: =1/K8 -> 0.14285714 | H12: =1/K9 -> 0.14285714 | I12: =1/K10 -> 0.14285714 | J12: =1/K11 -> 1 | K12: 1 | L12: 0.2 | M12: 0.14285714 | N12: 0.14285714 | O12: 0.14285714 | P12: 1 | Q12: 1 | R12: =C12/C$19 -> 0.014925373 | S12: =D12/D$19 -> 0.015544041 | T12: =E12/E$19 -> 0.014925373 | U12: =F12/F$19 -> 0.015544041 | V12: =G12/G$19 -> 0.015544041 | W12: =H12/H$19 -> 0.015544041 | X12: =I12/I$19 -> 0.015544041 | Y12: =J12/J$19 -> 0.014925373 | ... AF12: =Q12/Q$19 -> 0.014925373 | AG12: =AVERAGE(R12:AF12) -> 0.014769211 | AI12: =SUMPRODUCT(C12:Q12,$C$20:$Q$20) -> 0.2217696 | AJ12: =AI12/AG12 -> 15.01567
B13: Placilla | C13: =1/L4 -> 5 | D13: =1/L5 -> 0.33333333 | E13: =1/L6 -> 5 | F13: =1/L7 -> 0.33333333 | G13: =1/L8 -> 0.33333333 | H13: =1/L9 -> 0.33333333 | I13: =1/L10 -> 0.33333333 | J13: =1/L11 -> 5 | K13: =1/L12 -> 5 | L13: 1 | M13: 0.33333333 | N13: 0.33333333 | O13: 0.33333333 | P13: 5 | Q13: 5 | R13: =C13/C$19 -> 0.074626866 | S13: =D13/D$19 -> 0.03626943 | T13: =E13/E$19 -> 0.074626866 | U13: =F13/F$19 -> 0.03626943 | V13: =G13/G$19 -> 0.03626943 | W13: =H13/H$19 -> 0.03626943 | X13: =I13/I$19 -> 0.03626943 | Y13: =J13/J$19 -> 0.074626866 | ... AF13: =Q13/Q$19 -> 0.074626866 | AG13: =AVERAGE(R13:AF13) -> 0.051738972 | AI13: =SUMPRODUCT(C13:Q13,$C$20:$Q$20) -> 0.78136388 | AJ13: =AI13/AG13 -> 15.102037
B14: Plaza Justicia | C14: =1/M4 -> 7 | D14: =1/M5 -> 1 | E14: =1/M6 -> 7 | F14: =1/M7 -> 1 | G14: =1/M8 -> 1 | H14: =1/M9 -> 1 | I14: =1/M10 -> 1 | J14: =1/M11 -> 7 | K14: =1/M12 -> 7 | L14: =1/M13 -> 3 | M14: 1 | N14: 1 | O14: 1 | P14: 7 | Q14: 7 | R14: =C14/C$19 -> 0.10447761 | S14: =D14/D$19 -> 0.10880829 | T14: =E14/E$19 -> 0.10447761 | U14: =F14/F$19 -> 0.10880829 | V14: =G14/G$19 -> 0.10880829 | W14: =H14/H$19 -> 0.10880829 | X14: =I14/I$19 -> 0.10880829 | Y14: =J14/J$19 -> 0.10447761 | ... AF14: =Q14/Q$19 -> 0.10447761 | AG14: =AVERAGE(R14:AF14) -> 0.10745572 | AI14: =SUMPRODUCT(C14:Q14,$C$20:$Q$20) -> 1.6351695 | AJ14: =AI14/AG14 -> 15.217147
B15: Puertas Negras | C15: =1/N4 -> 7 | D15: =1/N5 -> 1 | E15: =1/N6 -> 7 | F15: =1/N7 -> 1 | G15: =1/N8 -> 1 | H15: =1/N9 -> 1 | I15: =1/N10 -> 1 | J15: =1/N11 -> 7 | K15: =1/N12 -> 7 | L15: =1/N13 -> 3 | M15: =1/N14 -> 1 | N15: 1 | O15: 1 | P15: 7 | Q15: 7 | R15: =C15/C$19 -> 0.10447761 | S15: =D15/D$19 -> 0.10880829 | T15: =E15/E$19 -> 0.10447761 | U15: =F15/F$19 -> 0.10880829 | V15: =G15/G$19 -> 0.10880829 | W15: =H15/H$19 -> 0.10880829 | X15: =I15/I$19 -> 0.10880829 | Y15: =J15/J$19 -> 0.10447761 | ... AF15: =Q15/Q$19 -> 0.10447761 | AG15: =AVERAGE(R15:AF15) -> 0.10745572 | AI15: =SUMPRODUCT(C15:Q15,$C$20:$Q$20) -> 1.6351695 | AJ15: =AI15/AG15 -> 15.217147
B16: Quebrada Verde | C16: =1/O4 -> 7 | D16: =1/O5 -> 1 | E16: =1/O6 -> 7 | F16: =1/O7 -> 1 | G16: =1/O8 -> 1 | H16: =1/O9 -> 1 | I16: =1/O10 -> 1 | J16: =1/O11 -> 7 | K16: =1/O12 -> 7 | L16: =1/O13 -> 3 | M16: =1/O14 -> 1 | N16: =1/O15 -> 1 | O16: 1 | P16: 7 | Q16: 7 | R16: =C16/C$19 -> 0.10447761 | S16: =D16/D$19 -> 0.10880829 | T16: =E16/E$19 -> 0.10447761 | U16: =F16/F$19 -> 0.10880829 | V16: =G16/G$19 -> 0.10880829 | W16: =H16/H$19 -> 0.10880829 | X16: =I16/I$19 -> 0.10880829 | Y16: =J16/J$19 -> 0.10447761 | ... AF16: =Q16/Q$19 -> 0.10447761 | AG16: =AVERAGE(R16:AF16) -> 0.10745572 | AI16: =SUMPRODUCT(C16:Q16,$C$20:$Q$20) -> 1.6351695 | AJ16: =AI16/AG16 -> 15.217147
B17: Reina Isabel 2 | C17: =1/P4 -> 1 | D17: =1/P5 -> 0.14285714 | E17: =1/P6 -> 1 | F17: =1/P7 -> 0.14285714 | G17: =1/P8 -> 0.14285714 | H17: =1/P9 -> 0.14285714 | I17: =1/P10 -> 0.14285714 | J17: =1/P11 -> 1 | K17: =1/P12 -> 1 | L17: =1/P13 -> 0.2 | M17: =1/P14 -> 0.14285714 | N17: =1/P15 -> 0.14285714 | O17: =1/P16 -> 0.14285714 | P17: 1 | Q17: 1 | R17: =C17/C$19 -> 0.014925373 | S17: =D17/D$19 -> 0.015544041 | T17: =E17/E$19 -> 0.014925373 | U17: =F17/F$19 -> 0.015544041 | V17: =G17/G$19 -> 0.015544041 | W17: =H17/H$19 -> 0.015544041 | X17: =I17/I$19 -> 0.015544041 | Y17: =J17/J$19 -> 0.014925373 | ... AF17: =Q17/Q$19 -> 0.014925373 | AG17: =AVERAGE(R17:AF17) -> 0.014769211 | AI17: =SUMPRODUCT(C17:Q17,$C$20:$Q$20) -> 0.2217696 | AJ17: =AI17/AG17 -> 15.01567
B18: Rodelillo | C18: =1/Q4 -> 1 | D18: =1/Q5 -> 0.14285714 | E18: =1/Q6 -> 1 | F18: =1/Q7 -> 0.14285714 | G18: =1/Q8 -> 0.14285714 | H18: =1/Q9 -> 0.14285714 | I18: =1/Q10 -> 0.14285714 | J18: =1/Q11 -> 1 | K18: =1/Q12 -> 1 | L18: =1/Q13 -> 0.2 | M18: =1/Q14 -> 0.14285714 | N18: =1/Q15 -> 0.14285714 | O18: =1/Q16 -> 0.14285714 | P18: =1/Q17 -> 1 | Q18: 1 | R18: =C18/C$19 -> 0.014925373 | S18: =D18/D$19 -> 0.015544041 | T18: =E18/E$19 -> 0.014925373 | U18: =F18/F$19 -> 0.015544041 | V18: =G18/G$19 -> 0.015544041 | W18: =H18/H$19 -> 0.015544041 | X18: =I18/I$19 -> 0.015544041 | Y18: =J18/J$19 -> 0.014925373 | ... AF18: =Q18/Q$19 -> 0.014925373 | AG18: =AVERAGE(R18:AF18) -> 0.014769211 | AI18: =SUMPRODUCT(C18:Q18,$C$20:$Q$20) -> 0.2217696 | AJ18: =AI18/AG18 -> 15.01567
B19: Total | C19: =SUM(C4:C18) -> 67 | D19: =SUM(D4:D18) -> 9.1904762 | E19: =SUM(E4:E18) -> 67 | F19: =SUM(F4:F18) -> 9.1904762 | G19: =SUM(G4:G18) -> 9.1904762 | H19: =SUM(H4:H18) -> 9.1904762 | I19: =SUM(I4:I18) -> 9.1904762 | J19: =SUM(J4:J18) -> 67 | ... Q19: =SUM(Q4:Q18) -> 67
B20: Ponderación | C20: =AG4 -> 0.014769211 | D20: =AG5 -> 0.10745572 | E20: =AG6 -> 0.014769211 | F20: =AG7 -> 0.10745572 | G20: =AG8 -> 0.10745572 | H20: =AG9 -> 0.10745572 | I20: =AG10 -> 0.10745572 | J20: =AG11 -> 0.014769211 | K20: =AG12 -> 0.014769211 | L20: =AG13 -> 0.051738972 | M20: =AG14 -> 0.10745572 | N20: =AG15 -> 0.10745572 | O20: =AG16 -> 0.10745572 | P20: =AG17 -> 0.014769211 | Q20: =AG18 -> 0.014769211
C24: MVA dispo | E24: estand | G24: comp | H24: ressult | I24: saaty
B25: 1 | C25: =(30*(1-0.5249)+25*(1-0.6298)) -> 23.508 | E25: =C25/$C$28 -> 0.21171131 | G25: 1.2 | H25: =E25/E26 -> 0.5795858 | I25: 5
B26: 2 | C26: =(30*(1-0.324)+30*(1-0.324)) -> 40.56 | E26: =C26/$C$28 -> 0.36528035 | G26: 1.3 | H26: =E25/E27 -> 0.50048967 | I26: 7
B27: 3 | C27: =(30*(1-0.4364)+25*(1-0.4622)+30*(1-0.4461)) -> 46.97 | E27: =C27/$C$28 -> 0.42300834 | G27: 2.3 | H27: =E26/E27 -> 0.86352991 | I27: 3
C28: =SUM(C25:C27) -> 111.038

Sheet C. Eco.
B2: Criterio Económico
B3: Alternativas | C3: Baron | D3: Cordillera | E3: Esperanza | F3: Jean y Marie Thierry | G3: Laguna Verde | H3: Las Cañas | I3: Marcelo Mena | J3: Padre Demian Molokai | K3: Placeres | L3: Placilla | M3: Plaza Justicia | N3: Puertas Negras | O3: Quebrada Verde | P3: Reina Isabel 2 | Q3: Rodelillo | R3: Matriz normalizada | AG3: Vector Promedio | AI3: Axw | AJ3: cocientes | AK3: λmax | AL3: n | AM3: RI | AO3: CI=(λmax-n)/(n-1) | AP3: =(AK4-AL4)/(AL4-1) -> 0.12479939
B4: Baron | C4: 1 | D4: 1 | E4: 0.2 | F4: 1 | G4: 0.2 | H4: 0.2 | I4: 9 | J4: 9 | K4: 1 | L4: 1 | M4: 9 | N4: 0.2 | O4: 9 | P4: 7 | Q4: 7 | R4: =C4/C$19 -> 0.038864899 | S4: =D4/D$19 -> 0.038864899 | T4: =E4/E$19 -> 0.035294122 | U4: =F4/F$19 -> 0.038864899 | V4: =G4/G$19 -> 0.035294122 | W4: =H4/H$19 -> 0.035294122 | X4: =I4/I$19 -> 0.10505837 | Y4: =J4/J$19 -> 0.10505837 | ... AF4: =Q4/Q$19 -> 0.092511014 | AG4: =AVERAGE(R4:AF4) -> 0.061340895 | AI4: =SUMPRODUCT(C4:Q4,$C$20:$Q$20) -> 1.0554418 | AJ4: =AI4/AG4 -> 17.206169 | AK4: =AVERAGE(AJ4:AJ18) -> 16.747191 | AL4: 15 | AM4: =(1.86668*(15-2))/15 -> 1.6177893 | AO4: CR=CI/RI | AP4: =AP3/AM4 -> 0.077141927
B5: Cordillera | C5: 1 | D5: 1 | E5: 0.2 | F5: 1 | G5: 0.2 | H5: 0.2 | I5: 9 | J5: 9 | K5: 1 | L5: 1 | M5: 9 | N5: 0.2 | O5: 9 | P5: 7 | Q5: 7 | R5: =C5/C$19 -> 0.038864899 | S5: =D5/D$19 -> 0.038864899 | T5: =E5/E$19 -> 0.035294122 | U5: =F5/F$19 -> 0.038864899 | V5: =G5/G$19 -> 0.035294122 | W5: =H5/H$19 -> 0.035294122 | X5: =I5/I$19 -> 0.10505837 | Y5: =J5/J$19 -> 0.10505837 | ... AF5: =Q5/Q$19 -> 0.092511014 | AG5: =AVERAGE(R5:AF5) -> 0.061340895 | AI5: =SUMPRODUCT(C5:Q5,$C$20:$Q$20) -> 1.0554418 | AJ5: =AI5/AG5 -> 17.206169
B6: Esperanza | C6: 5 | D6: 5 | E6: 1 | F6: 5 | G6: 1 | H6: 1 | I6: 9 | J6: 9 | K6: 5 | L6: 5 | M6: 9 | N6: 1 | O6: 9 | P6: 9 | Q6: 9 | R6: =C6/C$19 -> 0.1943245 | S6: =D6/D$19 -> 0.1943245 | T6: =E6/E$19 -> 0.17647061 | U6: =F6/F$19 -> 0.1943245 | V6: =G6/G$19 -> 0.17647061 | W6: =H6/H$19 -> 0.17647061 | X6: =I6/I$19 -> 0.10505837 | Y6: =J6/J$19 -> 0.10505837 | ... AF6: =Q6/Q$19 -> 0.11894273 | AG6: =AVERAGE(R6:AF6) -> 0.15433205 | AI6: =SUMPRODUCT(C6:Q6,$C$20:$Q$20) -> 2.8345564 | AJ6: =AI6/AG6 -> 18.366608
B7: Jean y Marie Thierry | C7: 1 | D7: 1 | E7: 0.2 | F7: 1 | G7: 0.2 | H7: 0.2 | I7: 9 | J7: 9 | K7: 1 | L7: 1 | M7: 9 | N7: 0.2 | O7: 9 | P7: 7 | Q7: 7 | R7: =C7/C$19 -> 0.038864899 | S7: =D7/D$19 -> 0.038864899 | T7: =E7/E$19 -> 0.035294122 | U7: =F7/F$19 -> 0.038864899 | V7: =G7/G$19 -> 0.035294122 | W7: =H7/H$19 -> 0.035294122 | X7: =I7/I$19 -> 0.10505837 | Y7: =J7/J$19 -> 0.10505837 | ... AF7: =Q7/Q$19 -> 0.092511014 | AG7: =AVERAGE(R7:AF7) -> 0.061340895 | AI7: =SUMPRODUCT(C7:Q7,$C$20:$Q$20) -> 1.0554418 | AJ7: =AI7/AG7 -> 17.206169
B8: Laguna Verde | C8: 5 | D8: 5 | E8: 1 | F8: 5 | G8: 1 | H8: 1 | I8: 9 | J8: 9 | K8: 5 | L8: 5 | M8: 9 | N8: 1 | O8: 9 | P8: 9 | Q8: 9 | R8: =C8/C$19 -> 0.1943245 | S8: =D8/D$19 -> 0.1943245 | T8: =E8/E$19 -> 0.17647061 | U8: =F8/F$19 -> 0.1943245 | V8: =G8/G$19 -> 0.17647061 | W8: =H8/H$19 -> 0.17647061 | X8: =I8/I$19 -> 0.10505837 | Y8: =J8/J$19 -> 0.10505837 | ... AF8: =Q8/Q$19 -> 0.11894273 | AG8: =AVERAGE(R8:AF8) -> 0.15433205 | AI8: =SUMPRODUCT(C8:Q8,$C$20:$Q$20) -> 2.8345564 | AJ8: =AI8/AG8 -> 18.366608
B9: Las Cañas | C9: 5 | D9: 5 | E9: 1 | F9: 5 | G9: 1 | H9: 1 | I9: 9 | J9: 9 | K9: 5 | L9: 5 | M9: 9 | N9: 1 | O9: 9 | P9: 9 | Q9: 9 | R9: =C9/C$19 -> 0.1943245 | S9: =D9/D$19 -> 0.1943245 | T9: =E9/E$19 -> 0.17647061 | U9: =F9/F$19 -> 0.1943245 | V9: =G9/G$19 -> 0.17647061 | W9: =H9/H$19 -> 0.17647061 | X9: =I9/I$19 -> 0.10505837 | Y9: =J9/J$19 -> 0.10505837 | ... AF9: =Q9/Q$19 -> 0.11894273 | AG9: =AVERAGE(R9:AF9) -> 0.15433205 | AI9: =SUMPRODUCT(C9:Q9,$C$20:$Q$20) -> 2.8345564 | AJ9: =AI9/AG9 -> 18.366608
B10: Marcelo Mena | C10: 0.111111 | D10: 0.111111 | E10: 0.111111 | F10: 0.111111 | G10: 0.111111 | H10: 0.111111 | I10: 1 | J10: 1 | K10: 0.111111 | L10: 0.111111 | M10: 3 | N10: 0.111111 | O10: 3 | P10: 1 | Q10: 1 | R10: =C10/C$19 -> 0.0043183178 | S10: =D10/D$19 -> 0.0043183178 | T10: =E10/E$19 -> 0.019607826 | U10: =F10/F$19 -> 0.0043183178 | V10: =G10/G$19 -> 0.019607826 | W10: =H10/H$19 -> 0.019607826 | X10: =I10/I$19 -> 0.011673152 | Y10: =J10/J$19 -> 0.011673152 | ... AF10: =Q10/Q$19 -> 0.013215859 | AG10: =AVERAGE(R10:AF10) -> 0.014197254 | AI10: =SUMPRODUCT(C10:Q10,$C$20:$Q$20) -> 0.21534902 | AJ10: =AI10/AG10 -> 15.168357
B11: Padre Demian Molokai | C11: 0.111111 | D11: 0.111111 | E11: 0.111111 | F11: 0.111111 | G11: 0.111111 | H11: 0.111111 | I11: 1 | J11: 1 | K11: 0.111111 | L11: 0.111111 | M11: 3 | N11: 0.111111 | O11: 3 | P11: 1 | Q11: 1 | R11: =C11/C$19 -> 0.0043183178 | S11: =D11/D$19 -> 0.0043183178 | T11: =E11/E$19 -> 0.019607826 | U11: =F11/F$19 -> 0.0043183178 | V11: =G11/G$19 -> 0.019607826 | W11: =H11/H$19 -> 0.019607826 | X11: =I11/I$19 -> 0.011673152 | Y11: =J11/J$19 -> 0.011673152 | ... AF11: =Q11/Q$19 -> 0.013215859 | AG11: =AVERAGE(R11:AF11) -> 0.014197254 | AI11: =SUMPRODUCT(C11:Q11,$C$20:$Q$20) -> 0.21534902 | AJ11: =AI11/AG11 -> 15.168357
B12: Placeres | C12: 1 | D12: 1 | E12: 0.2 | F12: 1 | G12: 0.2 | H12: 0.2 | I12: 9 | J12: 9 | K12: 1 | L12: 1 | M12: 9 | N12: 0.2 | O12: 9 | P12: 7 | Q12: 7 | R12: =C12/C$19 -> 0.038864899 | S12: =D12/D$19 -> 0.038864899 | T12: =E12/E$19 -> 0.035294122 | U12: =F12/F$19 -> 0.038864899 | V12: =G12/G$19 -> 0.035294122 | W12: =H12/H$19 -> 0.035294122 | X12: =I12/I$19 -> 0.10505837 | Y12: =J12/J$19 -> 0.10505837 | ... AF12: =Q12/Q$19 -> 0.092511014 | AG12: =AVERAGE(R12:AF12) -> 0.061340895 | AI12: =SUMPRODUCT(C12:Q12,$C$20:$Q$20) -> 1.0554418 | AJ12: =AI12/AG12 -> 17.206169
B13: Placilla | C13: 1 | D13: 1 | E13: 0.2 | F13: 1 | G13: 0.2 | H13: 0.2 | I13: 9 | J13: 9 | K13: 1 | L13: 1 | M13: 9 | N13: 0.2 | O13: 9 | P13: 7 | Q13: 7 | R13: =C13/C$19 -> 0.038864899 | S13: =D13/D$19 -> 0.038864899 | T13: =E13/E$19 -> 0.035294122 | U13: =F13/F$19 -> 0.038864899 | V13: =G13/G$19 -> 0.035294122 | W13: =H13/H$19 -> 0.035294122 | X13: =I13/I$19 -> 0.10505837 | Y13: =J13/J$19 -> 0.10505837 | ... AF13: =Q13/Q$19 -> 0.092511014 | AG13: =AVERAGE(R13:AF13) -> 0.061340895 | AI13: =SUMPRODUCT(C13:Q13,$C$20:$Q$20) -> 1.0554418 | AJ13: =AI13/AG13 -> 17.206169
B14: Plaza Justicia | C14: 0.111111 | D14: 0.111111 | E14: 0.111111 | F14: 0.111111 | G14: 0.111111 | H14: 0.111111 | I14: 0.333333 | J14: 0.333333 | K14: 0.111111 | L14: 0.111111 | M14: 1 | N14: 0.111111 | O14: 1 | P14: 0.333333 | Q14: 0.333333 | R14: =C14/C$19 -> 0.0043183178 | S14: =D14/D$19 -> 0.0043183178 | T14: =E14/E$19 -> 0.019607826 | U14: =F14/F$19 -> 0.0043183178 | V14: =G14/G$19 -> 0.019607826 | W14: =H14/H$19 -> 0.019607826 | X14: =I14/I$19 -> 0.0038910467 | Y14: =J14/J$19 -> 0.0038910467 | ... AF14: =Q14/Q$19 -> 0.004405282 | AG14: =AVERAGE(R14:AF14) -> 0.0091778788 | AI14: =SUMPRODUCT(C14:Q14,$C$20:$Q$20) -> 0.14022979 | AJ14: =AI14/AG14 -> 15.279106
B15: Puertas Negras | C15: 5 | D15: 5 | E15: 1 | F15: 5 | G15: 1 | H15: 1 | I15: 9 | J15: 9 | K15: 5 | L15: 5 | M15: 9 | N15: 1 | O15: 9 | P15: 9 | Q15: 9 | R15: =C15/C$19 -> 0.1943245 | S15: =D15/D$19 -> 0.1943245 | T15: =E15/E$19 -> 0.17647061 | U15: =F15/F$19 -> 0.1943245 | V15: =G15/G$19 -> 0.17647061 | W15: =H15/H$19 -> 0.17647061 | X15: =I15/I$19 -> 0.10505837 | Y15: =J15/J$19 -> 0.10505837 | ... AF15: =Q15/Q$19 -> 0.11894273 | AG15: =AVERAGE(R15:AF15) -> 0.15433205 | AI15: =SUMPRODUCT(C15:Q15,$C$20:$Q$20) -> 2.8345564 | AJ15: =AI15/AG15 -> 18.366608
B16: Quebrada Verde | C16: 0.111111 | D16: 0.111111 | E16: 0.111111 | F16: 0.111111 | G16: 0.111111 | H16: 0.111111 | I16: 0.333333 | J16: 0.333333 | K16: 0.111111 | L16: 0.111111 | M16: 1 | N16: 0.111111 | O16: 1 | P16: 0.333333 | Q16: 0.333333 | R16: =C16/C$19 -> 0.0043183178 | S16: =D16/D$19 -> 0.0043183178 | T16: =E16/E$19 -> 0.019607826 | U16: =F16/F$19 -> 0.0043183178 | V16: =G16/G$19 -> 0.019607826 | W16: =H16/H$19 -> 0.019607826 | X16: =I16/I$19 -> 0.0038910467 | Y16: =J16/J$19 -> 0.0038910467 | ... AF16: =Q16/Q$19 -> 0.004405282 | AG16: =AVERAGE(R16:AF16) -> 0.0091778788 | AI16: =SUMPRODUCT(C16:Q16,$C$20:$Q$20) -> 0.14022979 | AJ16: =AI16/AG16 -> 15.279106
... B18: Rodelillo | C18: 0.142857 | D18: 0.142857 | E18: 0.111111 | F18: 0.142857 | G18: 0.111111 | H18: 0.111111 | I18: 1 | J18: 1 | K18: 0.142857 | L18: 0.142857 | M18: 3 | N18: 0.111111 | O18: 3 | P18: 1 | Q18: 1 | R18: =C18/C$19 -> 0.0055521229 | S18: =D18/D$19 -> 0.0055521229 | T18: =E18/E$19 -> 0.019607826 | U18: =F18/F$19 -> 0.0055521229 | V18: =G18/G$19 -> 0.019607826 | W18: =H18/H$19 -> 0.019607826 | X18: =I18/I$19 -> 0.011673152 | Y18: =J18/J$19 -> 0.011673152 | ... AF18: =Q18/Q$19 -> 0.013215859 | AG18: =AVERAGE(R18:AF18) -> 0.014608522 | AI18: =SUMPRODUCT(C18:Q18,$C$20:$Q$20) -> 0.22508566 | AJ18: =AI18/AG18 -> 15.407832
B19: Total | C19: =SUM(C4:C18) -> 25.730158 | D19: =SUM(D4:D18) -> 25.730158 | E19: =SUM(E4:E18) -> 5.666666 | F19: =SUM(F4:F18) -> 25.730158 | G19: =SUM(G4:G18) -> 5.666666 | H19: =SUM(H4:H18) -> 5.666666 | I19: =SUM(I4:I18) -> 85.666666 | J19: =SUM(J4:J18) -> 85.666666 | ... Q19: =SUM(Q4:Q18) -> 75.666666
B20: Ponderación | C20: =AG4 -> 0.061340895 | D20: =AG5 -> 0.061340895 | E20: =AG6 -> 0.15433205 | F20: =AG7 -> 0.061340895 | G20: =AG8 -> 0.15433205 | H20: =AG9 -> 0.15433205 | I20: =AG10 -> 0.014197254 | J20: =AG11 -> 0.014197254 | K20: =AG12 -> 0.061340895 | L20: =AG13 -> 0.061340895 | M20: =AG14 -> 0.0091778788 | N20: =AG15 -> 0.15433205 | O20: =AG16 -> 0.0091778788 | P20: =AG17 -> 0.014608522 | Q20: =AG18 -> 0.014608522

Sheet C. So.
B2: Criterio Social
B3: Alternativas | C3: Baron | D3: Cordillera | E3: Esperanza | F3: Jean y Marie Thierry | G3: Laguna Verde | H3: Las Cañas | I3: Marcelo Mena | J3: Padre Demian Molokai | K3: Placeres | L3: Placilla | M3: Plaza Justicia | N3: Puertas Negras | O3: Quebrada Verde | P3: Reina Isabel 2 | Q3: Rodelillo | R3: Matriz normalizada | AG3: Vector Promedio | AI3: Axw | AJ3: cocientes | AK3: λmax | AL3: n | AM3: RI | AO3: CI=(λmax-n)/(n-1) | AP3: =(AK4-AL4)/(AL4-1) -> 0.045444472
B4: Baron | C4: 1 | D4: 3 | E4: 1 | F4: 1 | G4: 3 | H4: 3 | I4: 1 | J4: 3 | K4: 1 | L4: 1 | M4: 1 | N4: 7 | O4: 1 | P4: 1 | Q4: 1 | R4: =C4/C$19 -> 0.087136941 | S4: =D4/D$19 -> 0.12396694 | T4: =E4/E$19 -> 0.04950495 | U4: =F4/F$19 -> 0.04950495 | V4: =G4/G$19 -> 0.092783506 | W4: =H4/H$19 -> 0.092783506 | X4: =I4/I$19 -> 0.11891282 | Y4: =J4/J$19 -> 0.092783506 | ... AF4: =Q4/Q$19 -> 0.04950495 | AG4: =AVERAGE(R4:AF4) -> 0.087405749 | AI4: =SUMPRODUCT(C4:Q4,$C$20:$Q$20) -> 1.3738197 | AJ4: =AI4/AG4 -> 15.717727 | AK4: =AVERAGE(AJ4:AJ18) -> 15.636223 | AL4: 15 | AM4: =(1.86668*(15-2))/15 -> 1.6177893 | AO4: CR=CI/RI | AP4: =AP3/AM4 -> 0.028090476
B5: Cordillera | C5: 0.333333 | D5: 1 | E5: 1 | F5: 1 | G5: 1 | H5: 1 | I5: 0.333333 | J5: 1 | K5: 1 | L5: 0.2 | M5: 0.333333 | N5: 5 | O5: 1 | P5: 1 | Q5: 1 | R5: =C5/C$19 -> 0.029045618 | S5: =D5/D$19 -> 0.041322314 | T5: =E5/E$19 -> 0.04950495 | U5: =F5/F$19 -> 0.04950495 | V5: =G5/G$19 -> 0.030927835 | W5: =H5/H$19 -> 0.030927835 | X5: =I5/I$19 -> 0.039637568 | Y5: =J5/J$19 -> 0.030927835 | ... AF5: =Q5/Q$19 -> 0.04950495 | AG5: =AVERAGE(R5:AF5) -> 0.04457811 | AI5: =SUMPRODUCT(C5:Q5,$C$20:$Q$20) -> 0.69396573 | AJ5: =AI5/AG5 -> 15.56741
B6: Esperanza | C6: 1 | D6: 1 | E6: 1 | F6: 1 | G6: 1 | H6: 1 | I6: 0.333333 | J6: 1 | K6: 1 | L6: 0.333333 | M6: 0.333333 | N6: 5 | O6: 1 | P6: 1 | Q6: 1 | R6: =C6/C$19 -> 0.087136941 | S6: =D6/D$19 -> 0.041322314 | T6: =E6/E$19 -> 0.04950495 | U6: =F6/F$19 -> 0.04950495 | V6: =G6/G$19 -> 0.030927835 | W6: =H6/H$19 -> 0.030927835 | X6: =I6/I$19 -> 0.039637568 | Y6: =J6/J$19 -> 0.030927835 | ... AF6: =Q6/Q$19 -> 0.04950495 | AG6: =AVERAGE(R6:AF6) -> 0.049731154 | AI6: =SUMPRODUCT(C6:Q6,$C$20:$Q$20) -> 0.77198955 | AJ6: =AI6/AG6 -> 15.523258
B7: Jean y Marie Thierry | C7: 1 | D7: 1 | E7: 1 | F7: 1 | G7: 1 | H7: 1 | I7: 0.333333 | J7: 1 | K7: 1 | L7: 0.333333 | M7: 0.333333 | N7: 5 | O7: 1 | P7: 1 | Q7: 1 | R7: =C7/C$19 -> 0.087136941 | S7: =D7/D$19 -> 0.041322314 | T7: =E7/E$19 -> 0.04950495 | U7: =F7/F$19 -> 0.04950495 | V7: =G7/G$19 -> 0.030927835 | W7: =H7/H$19 -> 0.030927835 | X7: =I7/I$19 -> 0.039637568 | Y7: =J7/J$19 -> 0.030927835 | ... AF7: =Q7/Q$19 -> 0.04950495 | AG7: =AVERAGE(R7:AF7) -> 0.049731154 | AI7: =SUMPRODUCT(C7:Q7,$C$20:$Q$20) -> 0.77198955 | AJ7: =AI7/AG7 -> 15.523258
B8: Laguna Verde | C8: 0.333333 | D8: 1 | E8: 1 | F8: 1 | G8: 1 | H8: 1 | I8: 0.2 | J8: 1 | K8: 0.333333 | L8: 0.2 | M8: 0.2 | N8: 3 | O8: 1 | P8: 0.333333 | Q8: 1 | R8: =C8/C$19 -> 0.029045618 | S8: =D8/D$19 -> 0.041322314 | T8: =E8/E$19 -> 0.04950495 | U8: =F8/F$19 -> 0.04950495 | V8: =G8/G$19 -> 0.030927835 | W8: =H8/H$19 -> 0.030927835 | X8: =I8/I$19 -> 0.023782565 | Y8: =J8/J$19 -> 0.030927835 | ... AF8: =Q8/Q$19 -> 0.04950495 | AG8: =AVERAGE(R8:AF8) -> 0.034951488 | AI8: =SUMPRODUCT(C8:Q8,$C$20:$Q$20) -> 0.54328852 | AJ8: =AI8/AG8 -> 15.544074
B9: Las Cañas | C9: 0.333333 | D9: 1 | E9: 1 | F9: 1 | G9: 1 | H9: 1 | I9: 0.2 | J9: 1 | K9: 0.333333 | L9: 0.2 | M9: 0.2 | N9: 3 | O9: 1 | P9: 0.333333 | Q9: 1 | R9: =C9/C$19 -> 0.029045618 | S9: =D9/D$19 -> 0.041322314 | T9: =E9/E$19 -> 0.04950495 | U9: =F9/F$19 -> 0.04950495 | V9: =G9/G$19 -> 0.030927835 | W9: =H9/H$19 -> 0.030927835 | X9: =I9/I$19 -> 0.023782565 | Y9: =J9/J$19 -> 0.030927835 | ... AF9: =Q9/Q$19 -> 0.04950495 | AG9: =AVERAGE(R9:AF9) -> 0.034951488 | AI9: =SUMPRODUCT(C9:Q9,$C$20:$Q$20) -> 0.54328852 | AJ9: =AI9/AG9 -> 15.544074
B10: Marcelo Mena | C10: 1 | D10: 3 | E10: 3 | F10: 3 | G10: 5 | H10: 5 | I10: 1 | J10: 5 | K10: 1 | L10: 1 | M10: 1 | N10: 7 | O10: 3 | P10: 1 | Q10: 3 | R10: =C10/C$19 -> 0.087136941 | S10: =D10/D$19 -> 0.12396694 | T10: =E10/E$19 -> 0.14851485 | U10: =F10/F$19 -> 0.14851485 | V10: =G10/G$19 -> 0.15463918 | W10: =H10/H$19 -> 0.15463918 | X10: =I10/I$19 -> 0.11891282 | Y10: =J10/J$19 -> 0.15463918 | ... AF10: =Q10/Q$19 -> 0.14851485 | AG10: =AVERAGE(R10:AF10) -> 0.12617952 | AI10: =SUMPRODUCT(C10:Q10,$C$20:$Q$20) -> 1.9813779 | AJ10: =AI10/AG10 -> 15.702848
B11: Padre Demian Molokai | C11: 0.333333 | D11: 1 | E11: 1 | F11: 1 | G11: 1 | H11: 1 | I11: 0.2 | J11: 1 | K11: 0.333333 | L11: 0.2 | M11: 0.2 | N11: 3 | O11: 1 | P11: 0.333333 | Q11: 1 | R11: =C11/C$19 -> 0.029045618 | S11: =D11/D$19 -> 0.041322314 | T11: =E11/E$19 -> 0.04950495 | U11: =F11/F$19 -> 0.04950495 | V11: =G11/G$19 -> 0.030927835 | W11: =H11/H$19 -> 0.030927835 | X11: =I11/I$19 -> 0.023782565 | Y11: =J11/J$19 -> 0.030927835 | ... AF11: =Q11/Q$19 -> 0.04950495 | AG11: =AVERAGE(R11:AF11) -> 0.034951488 | AI11: =SUMPRODUCT(C11:Q11,$C$20:$Q$20) -> 0.54328852 | AJ11: =AI11/AG11 -> 15.544074
B12: Placeres | C12: 1 | D12: 1 | E12: 1 | F12: 1 | G12: 3 | H12: 3 | I12: 1 | J12: 3 | K12: 1 | L12: 0.333333 | M12: 0.333333 | N12: 5 | O12: 1 | P12: 1 | Q12: 1 | R12: =C12/C$19 -> 0.087136941 | S12: =D12/D$19 -> 0.041322314 | T12: =E12/E$19 -> 0.04950495 | U12: =F12/F$19 -> 0.04950495 | V12: =G12/G$19 -> 0.092783506 | W12: =H12/H$19 -> 0.092783506 | X12: =I12/I$19 -> 0.11891282 | Y12: =J12/J$19 -> 0.092783506 | ... AF12: =Q12/Q$19 -> 0.04950495 | AG12: =AVERAGE(R12:AF12) -> 0.067387305 | AI12: =SUMPRODUCT(C12:Q12,$C$20:$Q$20) -> 1.0658182 | AJ12: =AI12/AG12 -> 15.816305
B13: Placilla | C13: 1 | D13: 5 | E13: 3 | F13: 3 | G13: 5 | H13: 5 | I13: 1 | J13: 5 | K13: 3 | L13: 1 | M13: 1 | N13: 7 | O13: 3 | P13: 3 | Q13: 3 | R13: =C13/C$19 -> 0.087136941 | S13: =D13/D$19 -> 0.20661157 | T13: =E13/E$19 -> 0.14851485 | U13: =F13/F$19 -> 0.14851485 | V13: =G13/G$19 -> 0.15463918 | W13: =H13/H$19 -> 0.15463918 | X13: =I13/I$19 -> 0.11891282 | Y13: =J13/J$19 -> 0.15463918 | ... AF13: =Q13/Q$19 -> 0.14851485 | AG13: =AVERAGE(R13:AF13) -> 0.14815007 | AI13: =SUMPRODUCT(C13:Q13,$C$20:$Q$20) -> 2.3400833 | AJ13: =AI13/AG13 -> 15.795357
B14: Plaza Justicia | C14: 1 | D14: 3 | E14: 3 | F14: 3 | G14: 5 | H14: 5 | I14: 1 | J14: 5 | K14: 3 | L14: 1 | M14: 1 | N14: 7 | O14: 3 | P14: 3 | Q14: 3 | R14: =C14/C$19 -> 0.087136941 | S14: =D14/D$19 -> 0.12396694 | T14: =E14/E$19 -> 0.14851485 | U14: =F14/F$19 -> 0.14851485 | V14: =G14/G$19 -> 0.15463918 | W14: =H14/H$19 -> 0.15463918 | X14: =I14/I$19 -> 0.11891282 | Y14: =J14/J$19 -> 0.15463918 | ... AF14: =Q14/Q$19 -> 0.14851485 | AG14: =AVERAGE(R14:AF14) -> 0.14264043 | AI14: =SUMPRODUCT(C14:Q14,$C$20:$Q$20) -> 2.2509271 | AJ14: =AI14/AG14 -> 15.780428
B15: Puertas Negras | C15: 0.142857 | D15: 0.2 | E15: 0.2 | F15: 0.2 | G15: 0.333333 | H15: 0.333333 | I15: 0.142857 | J15: 0.333333 | K15: 0.2 | L15: 0.142857 | M15: 0.142857 | N15: 1 | O15: 0.2 | P15: 0.2 | Q15: 0.2 | R15: =C15/C$19 -> 0.012448122 | S15: =D15/D$19 -> 0.0082644628 | T15: =E15/E$19 -> 0.0099009901 | U15: =F15/F$19 -> 0.0099009901 | V15: =G15/G$19 -> 0.010309268 | W15: =H15/H$19 -> 0.010309268 | X15: =I15/I$19 -> 0.016987529 | Y15: =J15/J$19 -> 0.010309268 | ... AF15: =Q15/Q$19 -> 0.0099009901 | AG15: =AVERAGE(R15:AF15) -> 0.012492427 | AI15: =SUMPRODUCT(C15:Q15,$C$20:$Q$20) -> 0.19515296 | AJ15: =AI15/AG15 -> 15.621701
B16: Quebrada Verde | C16: 1 | D16: 1 | E16: 1 | F16: 1 | G16: 1 | H16: 1 | I16: 0.333333 | J16: 1 | K16: 1 | L16: 0.333333 | M16: 0.333333 | N16: 5 | O16: 1 | P16: 1 | Q16: 1 | R16: =C16/C$19 -> 0.087136941 | S16: =D16/D$19 -> 0.041322314 | T16: =E16/E$19 -> 0.04950495 | U16: =F16/F$19 -> 0.04950495 | V16: =G16/G$19 -> 0.030927835 | W16: =H16/H$19 -> 0.030927835 | X16: =I16/I$19 -> 0.039637568 | Y16: =J16/J$19 -> 0.030927835 | ... AF16: =Q16/Q$19 -> 0.04950495 | AG16: =AVERAGE(R16:AF16) -> 0.049731154 | AI16: =SUMPRODUCT(C16:Q16,$C$20:$Q$20) -> 0.77198955 | AJ16: =AI16/AG16 -> 15.523258
... B18: Rodelillo | C18: 1 | D18: 1 | E18: 1 | F18: 1 | G18: 1 | H18: 1 | I18: 0.333333 | J18: 1 | K18: 1 | L18: 0.333333 | M18: 0.333333 | N18: 5 | O18: 1 | P18: 1 | Q18: 1 | R18: =C18/C$19 -> 0.087136941 | S18: =D18/D$19 -> 0.041322314 | T18: =E18/E$19 -> 0.04950495 | U18: =F18/F$19 -> 0.04950495 | V18: =G18/G$19 -> 0.030927835 | W18: =H18/H$19 -> 0.030927835 | X18: =I18/I$19 -> 0.039637568 | Y18: =J18/J$19 -> 0.030927835 | ... AF18: =Q18/Q$19 -> 0.04950495 | AG18: =AVERAGE(R18:AF18) -> 0.049731154 | AI18: =SUMPRODUCT(C18:Q18,$C$20:$Q$20) -> 0.77198955 | AJ18: =AI18/AG18 -> 15.523258
B19: Total | C19: =SUM(C4:C18) -> 11.476189 | D19: =SUM(D4:D18) -> 24.2 | E19: =SUM(E4:E18) -> 20.2 | F19: =SUM(F4:F18) -> 20.2 | G19: =SUM(G4:G18) -> 32.333333 | H19: =SUM(H4:H18) -> 32.333333 | I19: =SUM(I4:I18) -> 8.409522 | J19: =SUM(J4:J18) -> 32.333333 | ... Q19: =SUM(Q4:Q18) -> 20.2
B20: Ponderación | C20: =AG4 -> 0.087405749 | D20: =AG5 -> 0.04457811 | E20: =AG6 -> 0.049731154 | F20: =AG7 -> 0.049731154 | G20: =AG8 -> 0.034951488 | H20: =AG9 -> 0.034951488 | I20: =AG10 -> 0.12617952 | J20: =AG11 -> 0.034951488 | K20: =AG12 -> 0.067387305 | L20: =AG13 -> 0.14815007 | M20: =AG14 -> 0.14264043 | N20: =AG15 -> 0.012492427 | O20: =AG16 -> 0.049731154 | P20: =AG17 -> 0.067387305 | Q20: =AG18 -> 0.049731154

Sheet C. Am.
B2: Criterio Ambiental
B3: Alternativas | C3: Baron | D3: Cordillera | E3: Esperanza | F3: Jean y Marie Thierry | G3: Laguna Verde | H3: Las Cañas | I3: Marcelo Mena | J3: Padre Demian Molokai | K3: Placeres | L3: Placilla | M3: Plaza Justicia | N3: Puertas Negras | O3: Quebrada Verde | P3: Reina Isabel 2 | Q3: Rodelillo | R3: Matriz normalizada | AG3: Vector Promedio | AI3: Axw | AJ3: cocientes | AK3: λmax | AL3: n | AM3: RI | AO3: CI=(λmax-n)/(n-1) | AP3: =(AK4-AL4)/(AL4-1) -> 0.027136257
B4: Baron | C4: 1 | D4: 1 | E4: 3 | F4: 3 | G4: 5 | H4: 3 | I4: 0.333333 | J4: 3 | K4: 1 | L4: 0.333333 | M4: 0.333333 | N4: 5 | O4: 1 | P4: 0.333333 | Q4: 1 | R4: =C4/C$19 -> 0.053380787 | S4: =D4/D$19 -> 0.053380787 | T4: =E4/E$19 -> 0.075630253 | U4: =F4/F$19 -> 0.075630253 | V4: =G4/G$19 -> 0.074626866 | W4: =H4/H$19 -> 0.075630253 | X4: =I4/I$19 -> 0.049365268 | Y4: =J4/J$19 -> 0.075630253 | ... AF4: =Q4/Q$19 -> 0.053380787 | AG4: =AVERAGE(R4:AF4) -> 0.061075983 | AI4: =SUMPRODUCT(C4:Q4,$C$20:$Q$20) -> 0.94518604 | AJ4: =AI4/AG4 -> 15.475576 | AK4: =AVERAGE(AJ4:AJ18) -> 15.379908 | AL4: 15 | AM4: =(1.86668*(15-2))/15 -> 1.6177893 | AO4: CR=CI/RI | AP4: =AP3/AM4 -> 0.016773665
B5: Cordillera | C5: 1 | D5: 1 | E5: 3 | F5: 3 | G5: 5 | H5: 3 | I5: 0.333333 | J5: 3 | K5: 1 | L5: 0.333333 | M5: 0.333333 | N5: 5 | O5: 1 | P5: 0.333333 | Q5: 1 | R5: =C5/C$19 -> 0.053380787 | S5: =D5/D$19 -> 0.053380787 | T5: =E5/E$19 -> 0.075630253 | U5: =F5/F$19 -> 0.075630253 | V5: =G5/G$19 -> 0.074626866 | W5: =H5/H$19 -> 0.075630253 | X5: =I5/I$19 -> 0.049365268 | Y5: =J5/J$19 -> 0.075630253 | ... AF5: =Q5/Q$19 -> 0.053380787 | AG5: =AVERAGE(R5:AF5) -> 0.061075983 | AI5: =SUMPRODUCT(C5:Q5,$C$20:$Q$20) -> 0.94518604 | AJ5: =AI5/AG5 -> 15.475576
B6: Esperanza | C6: 0.333333 | D6: 0.333333 | E6: 1 | F6: 1 | G6: 3 | H6: 1 | I6: 0.2 | J6: 1 | K6: 0.333333 | L6: 0.2 | M6: 0.2 | N6: 3 | O6: 0.333333 | P6: 0.2 | Q6: 0.333333 | R6: =C6/C$19 -> 0.017793578 | S6: =D6/D$19 -> 0.017793578 | T6: =E6/E$19 -> 0.025210084 | U6: =F6/F$19 -> 0.025210084 | V6: =G6/G$19 -> 0.044776119 | W6: =H6/H$19 -> 0.025210084 | X6: =I6/I$19 -> 0.029619191 | Y6: =J6/J$19 -> 0.025210084 | ... AF6: =Q6/Q$19 -> 0.017793578 | AG6: =AVERAGE(R6:AF6) -> 0.026522482 | AI6: =SUMPRODUCT(C6:Q6,$C$20:$Q$20) -> 0.40080505 | AJ6: =AI6/AG6 -> 15.111898
B7: Jean y Marie Thierry | C7: 0.333333 | D7: 0.333333 | E7: 1 | F7: 1 | G7: 3 | H7: 1 | I7: 0.2 | J7: 1 | K7: 0.333333 | L7: 0.2 | M7: 0.2 | N7: 3 | O7: 0.333333 | P7: 0.2 | Q7: 0.333333 | R7: =C7/C$19 -> 0.017793578 | S7: =D7/D$19 -> 0.017793578 | T7: =E7/E$19 -> 0.025210084 | U7: =F7/F$19 -> 0.025210084 | V7: =G7/G$19 -> 0.044776119 | W7: =H7/H$19 -> 0.025210084 | X7: =I7/I$19 -> 0.029619191 | Y7: =J7/J$19 -> 0.025210084 | ... AF7: =Q7/Q$19 -> 0.017793578 | AG7: =AVERAGE(R7:AF7) -> 0.026522482 | AI7: =SUMPRODUCT(C7:Q7,$C$20:$Q$20) -> 0.40080505 | AJ7: =AI7/AG7 -> 15.111898
B8: Laguna Verde | C8: 0.2 | D8: 0.2 | E8: 0.333333 | F8: 0.333333 | G8: 1 | H8: 0.333333 | I8: 0.142857 | J8: 0.333333 | K8: 0.2 | L8: 0.142857 | M8: 0.142857 | N8: 1 | O8: 0.2 | P8: 0.142857 | Q8: 0.2 | R8: =C8/C$19 -> 0.010676157 | S8: =D8/D$19 -> 0.010676157 | T8: =E8/E$19 -> 0.0084033531 | U8: =F8/F$19 -> 0.0084033531 | V8: =G8/G$19 -> 0.014925373 | W8: =H8/H$19 -> 0.0084033531 | X8: =I8/I$19 -> 0.021156543 | Y8: =J8/J$19 -> 0.0084033531 | ... AF8: =Q8/Q$19 -> 0.010676157 | AG8: =AVERAGE(R8:AF8) -> 0.013431408 | AI8: =SUMPRODUCT(C8:Q8,$C$20:$Q$20) -> 0.20354018 | AJ8: =AI8/AG8 -> 15.154047
B9: Las Cañas | C9: 0.333333 | D9: 0.333333 | E9: 1 | F9: 1 | G9: 3 | H9: 1 | I9: 0.2 | J9: 1 | K9: 0.333333 | L9: 0.2 | M9: 0.2 | N9: 3 | O9: 0.333333 | P9: 0.2 | Q9: 0.333333 | R9: =C9/C$19 -> 0.017793578 | S9: =D9/D$19 -> 0.017793578 | T9: =E9/E$19 -> 0.025210084 | U9: =F9/F$19 -> 0.025210084 | V9: =G9/G$19 -> 0.044776119 | W9: =H9/H$19 -> 0.025210084 | X9: =I9/I$19 -> 0.029619191 | Y9: =J9/J$19 -> 0.025210084 | ... AF9: =Q9/Q$19 -> 0.017793578 | AG9: =AVERAGE(R9:AF9) -> 0.026522482 | AI9: =SUMPRODUCT(C9:Q9,$C$20:$Q$20) -> 0.40080505 | AJ9: =AI9/AG9 -> 15.111898
B10: Marcelo Mena | C10: 3 | D10: 3 | E10: 5 | F10: 5 | G10: 7 | H10: 5 | I10: 1 | J10: 5 | K10: 3 | L10: 1 | M10: 1 | N10: 7 | O10: 3 | P10: 1 | Q10: 3 | R10: =C10/C$19 -> 0.16014236 | S10: =D10/D$19 -> 0.16014236 | T10: =E10/E$19 -> 0.12605042 | U10: =F10/F$19 -> 0.12605042 | V10: =G10/G$19 -> 0.10447761 | W10: =H10/H$19 -> 0.12605042 | X10: =I10/I$19 -> 0.14809595 | Y10: =J10/J$19 -> 0.12605042 | ... AF10: =Q10/Q$19 -> 0.16014236 | AG10: =AVERAGE(R10:AF10) -> 0.14041683 | AI10: =SUMPRODUCT(C10:Q10,$C$20:$Q$20) -> 2.1962964 | AJ10: =AI10/AG10 -> 15.641262
