Workbook

Sheet Inicio
B2: Datos cuantificados de los criterios y alternativas | D2: Criterios
D3: Técnico | E3: Económico | F3: Social | G3: Ambiental | H3: Comercial
D4: Capacidad técnica de la red eléctrica | E4: Costos de instalación, operación y mantenimiento | F4: Cantidad de Personas beneficiadas | G4: Calles con ato flujo y emisiones de CO2 | H4: Cercanica y fomento al turismo y comercio
B5: Alternativas | C5: Baron
C6: Cordillera
C7: Esperanza
C8: Jean y Marie Thierry
C9: Laguna Verde
C10: Las Cañas
C11: Marcelo Mena
C12: Padre Demian Molokai
C13: Placeres | J13: Axw | K13: cocientes | L13: λmax | M13: n | N13: RI | P13: CI=(λmax-n)/(n-1) | Q13: =(L14-M14)/(M14-1) -> 0
C14: Placilla | J14: =SUMPRODUCT(D24:H24,$D$49:$H$49) -> 1 | K14: =J14/N24 -> 5 | L14: =AVERAGE(K14:K18) -> 5 | M14: 5 | N14: 1.12 | P14: CR=CI/RI | Q14: =Q13/N14 -> 0
C15: Plaza Justicia | J15: =SUMPRODUCT(D25:H25,$D$49:$H$49) -> 1 | K15: =J15/N25 -> 5
C16: Puertas Negras | J16: =SUMPRODUCT(D26:H26,$D$49:$H$49) -> 1 | K16: =J16/N26 -> 5
C17: Quebrada Verde | J17: =SUMPRODUCT(D27:H27,$D$49:$H$49) -> 1 | K17: =J17/N27 -> 5
C18: Reina Isabel 2 | J18: =SUMPRODUCT(D28:H28,$D$49:$H$49) -> 1 | K18: =J18/N28 -> 5
C19: Rodelillo
C22: Importancia o Jerarquia de Criterios
C23: Criterios | D23: Técnico | E23: Económico | F23: Social | G23: Ambiental | H23: Comercial | I23: Matriz normalizada | N23: Ponderación
C24: Técnico | D24: 1 | E24: 1 | F24: 1 | G24: 1 | H24: 1 | I24: =D24/D$29 -> 0.2 | J24: =E24/E$29 -> 0.2 | K24: =F24/F$29 -> 0.2 | L24: =G24/G$29 -> 0.2 | M24: =H24/H$29 -> 0.2 | N24: =AVERAGE(I24:M24) -> 0.2
C25: Económico | D25: =1/E24 -> 1 | E25: 1 | F25: 1 | G25: 1 | H25: 1 | I25: =D25/D$29 -> 0.2 | J25: =E25/E$29 -> 0.2 | K25: =F25/F$29 -> 0.2 | L25: =G25/G$29 -> 0.2 | M25: =H25/H$29 -> 0.2 | N25: =AVERAGE(I25:M25) -> 0.2
C26: Social | D26: =1/F24 -> 1 | E26: =1/F25 -> 1 | F26: 1 | G26: 1 | H26: 1 | I26: =D26/D$29 -> 0.2 | J26: =E26/E$29 -> 0.2 | K26: =F26/F$29 -> 0.2 | L26: =G26/G$29 -> 0.2 | M26: =H26/H$29 -> 0.2 | N26: =AVERAGE(I26:M26) -> 0.2
C27: Ambiental | D27: =1/G24 -> 1 | E27: =1/G25 -> 1 | F27: =1/G26 -> 1 | G27: 1 | H27: 1 | I27: =D27/D$29 -> 0.2 | J27: =E27/E$29 -> 0.2 | K27: =F27/F$29 -> 0.2 | L27: =G27/G$29 -> 0.2 | M27: =H27/H$29 -> 0.2 | N27: =AVERAGE(I27:M27) -> 0.2
C28: Comercial | D28: =1/H24 -> 1 | E28: =1/H25 -> 1 | F28: =1/H26 -> 1 | G28: =1/H27 -> 1 | H28: 1 | I28: =D28/D$29 -> 0.2 | J28: =E28/E$29 -> 0.2 | K28: =F28/F$29 -> 0.2 | L28: =G28/G$29 -> 0.2 | M28: =H28/H$29 -> 0.2 | N28: =AVERAGE(I28:M28) -> 0.2
C29: Total | D29: =SUM(D24:D28) -> 5 | E29: =SUM(E24:E28) -> 5 | F29: =SUM(F24:F28) -> 5 | G29: =SUM(G24:G28) -> 5 | H29: =SUM(H24:H28) -> 5
B32: Resultado AHP | D32: Criterios | I32: Priorización
D33: Técnico | E33: Económico | F33: Social | G33: Ambiental | H33: Comercial
B34: Alternativas | C34: Baron | D34: ='C. Téc.'!AG4 -> 0.014769211 | E34: ='C. Eco.'!AG4 -> 0.069091049 | F34: ='C. So.'!AG4 -> 0.073225328 | G34: ='C. Am.'!AG4 -> 0.060069033 | H34: ='C. Com.'!AG4 -> 0.05140334 | I34: =SUMPRODUCT(D34:H34,$D$49:$H$49) -> 0.053711592
C35: Cordillera | D35: ='C. Téc.'!AG5 -> 0.10745572 | E35: ='C. Eco.'!AG5 -> 0.069091049 | F35: ='C. So.'!AG5 -> 0.029475881 | G35: ='C. Am.'!AG5 -> 0.060069033 | H35: ='C. Com.'!AG5 -> 0.014060846 | I35: =SUMPRODUCT(D35:H35,$D$49:$H$49) -> 0.056030506
C36: Esperanza | D36: ='C. Téc.'!AG6 -> 0.014769211 | E36: ='C. Eco.'!AG6 -> 0.14315542 | F36: ='C. So.'!AG6 -> 0.035035941 | G36: ='C. Am.'!AG6 -> 0.029453939 | H36: ='C. Com.'!AG6 -> 0.05140334 | I36: =SUMPRODUCT(D36:H36,$D$49:$H$49) -> 0.054763569
C37: Jean y Marie Thierry | D37: ='C. Téc.'!AG7 -> 0.10745572 | E37: ='C. Eco.'!AG7 -> 0.069091049 | F37: ='C. So.'!AG7 -> 0.073225328 | G37: ='C. Am.'!AG7 -> 0.029453939 | H37: ='C. Com.'!AG7 -> 0.15676939 | I37: =SUMPRODUCT(D37:H37,$D$49:$H$49) -> 0.087199085
C38: Laguna Verde | D38: ='C. Téc.'!AG8 -> 0.10745572 | E38: ='C. Eco.'!AG8 -> 0.14315542 | F38: ='C. So.'!AG8 -> 0.010979829 | G38: ='C. Am.'!AG8 -> 0.012237224 | H38: ='C. Com.'!AG8 -> 0.014060846 | I38: =SUMPRODUCT(D38:H38,$D$49:$H$49) -> 0.057577807
C39: Las Cañas | D39: ='C. Téc.'!AG9 -> 0.10745572 | E39: ='C. Eco.'!AG9 -> 0.14315542 | F39: ='C. So.'!AG9 -> 0.010979829 | G39: ='C. Am.'!AG9 -> 0.029453939 | H39: ='C. Com.'!AG9 -> 0.014060846 | I39: =SUMPRODUCT(D39:H39,$D$49:$H$49) -> 0.06102115
C40: Marcelo Mena | D40: ='C. Téc.'!AG10 -> 0.10745572 | E40: ='C. Eco.'!AG10 -> 0.015279074 | F40: ='C. So.'!AG10 -> 0.087413552 | G40: ='C. Am.'!AG10 -> 0.13930816 | H40: ='C. Com.'!AG10 -> 0.09155924 | I40: =SUMPRODUCT(D40:H40,$D$49:$H$49) -> 0.088203149
C41: Padre Demian Molokai | D41: ='C. Téc.'!AG11 -> 0.014769211 | E41: ='C. Eco.'!AG11 -> 0.015279074 | F41: ='C. So.'!AG11 -> 0.065189305 | G41: ='C. Am.'!AG11 -> 0.029453939 | H41: ='C. Com.'!AG11 -> 0.014060846 | I41: =SUMPRODUCT(D41:H41,$D$49:$H$49) -> 0.027750475
C42: Placeres | D42: ='C. Téc.'!AG12 -> 0.014769211 | E42: ='C. Eco.'!AG12 -> 0.069091049 | F42: ='C. So.'!AG12 -> 0.11766825 | G42: ='C. Am.'!AG12 -> 0.060069033 | H42: ='C. Com.'!AG12 -> 0.05140334 | I42: =SUMPRODUCT(D42:H42,$D$49:$H$49) -> 0.062600175
C43: Placilla | D43: ='C. Téc.'!AG13 -> 0.051738972 | E43: ='C. Eco.'!AG13 -> 0.070623616 | F43: ='C. So.'!AG13 -> 0.14116914 | G43: ='C. Am.'!AG13 -> 0.13930816 | H43: ='C. Com.'!AG13 -> 0.15676939 | I43: =SUMPRODUCT(D43:H43,$D$49:$H$49) -> 0.11192185
C44: Plaza Justicia | D44: ='C. Téc.'!AG14 -> 0.10745572 | E44: ='C. Eco.'!AG14 -> 0.0093996528 | F44: ='C. So.'!AG14 -> 0.10000263 | G44: ='C. Am.'!AG14 -> 0.13930816 | H44: ='C. Com.'!AG14 -> 0.21617771 | I44: =SUMPRODUCT(D44:H44,$D$49:$H$49) -> 0.11446878
C45: Puertas Negras | D45: ='C. Téc.'!AG15 -> 0.10745572 | E45: ='C. Eco.'!AG15 -> 0.14315542 | F45: ='C. So.'!AG15 -> 0.010232443 | G45: ='C. Am.'!AG15 -> 0.012237224 | H45: ='C. Com.'!AG15 -> 0.014060846 | I45: =SUMPRODUCT(D45:H45,$D$49:$H$49) -> 0.05742833
...

Sheet C. Téc.
B2: Criterio Técnico
B3: Alternativas | C3: Baron | D3: Cordillera | E3: Esperanza | F3: Jean y Marie Thierry | G3: Laguna Verde | H3: Las Cañas | I3: Marcelo Mena | J3: Padre Demian Molokai | K3: Placeres | L3: Placilla | M3: Plaza Justicia | N3: Puertas Negras | O3: Quebrada Verde | P3: Reina Isabel 2 | Q3: Rodelillo | R3: Matriz normalizada | AG3: Vector Promedio | AI3: Axw | AJ3: cocientes | AK3: λmax | AL3: n | AM3: RI | AO3: CI=(λmax-n)/(n-1) | AP3: =(AK4-AL4)/(AL4-1) -> 0.009205889
B4: Baron | C4: 1 | D4: 0.14285714 | E4: 1 | F4: 0.14285714 | G4: 0.14285714 | H4: 0.14285714 | I4: 0.14285714 | J4: 1 | K4: 1 | L4: 0.2 | M4: 0.14285714 | N4: 0.14285714 | O4: 0.14285714 | P4: 1 | Q4: 1 | R4: =C4/C$19 -> 0.014925373 | S4: =D4/D$19 -> 0.015544041 | T4: =E4/E$19 -> 0.014925373 | U4: =F4/F$19 -> 0.015544041 | V4: =G4/G$19 -> 0.015544041 | W4: =H4/H$19 -> 0.015544041 | X4: =I4/I$19 -> 0.015544041 | Y4: =J4/J$19 -> 0.014925373 | ... AF4: =Q4/Q$19 -> 0.014925373 | AG4: =AVERAGE(R4:AF4) -> 0.014769211 | AI4: =SUMPRODUCT(C4:Q4,$C$20:$Q$20) -> 0.2217696 | AJ4: =AI4/AG4 -> 15.01567 | AK4: =AVERAGE(AJ4:AJ18) -> 15.128882 | AL4: 15 | AM4: =(1.86668*(15-2))/15 -> 1.6177893 | AO4: CR=CI/RI | AP4: =AP3/AM4 -> 0.0056904127
B5: Cordillera | C5: =1/D4 -> 7 | D5: 1 | E5: 7 | F5: 1 | G5: 1 | H5: 1 | I5: 1 | J5: 7 | K5: 7 | L5: 3 | M5: 1 | N5: 1 | O5: 1 | P5: 7 | Q5: 7 | R5: =C5/C$19 -> 0.10447761 | S5: =D5/D$19 -> 0.10880829 | T5: =E5/E$19 -> 0.10447761 | U5: =F5/F$19 -> 0.10880829 | V5: =G5/G$19 -> 0.10880829 | W5: =H5/H$19 -> 0.10880829 | X5: =I5/I$19 -> 0.10880829 | Y5: =J5/J$19 -> 0.10447761 | ... AF5: =Q5/Q$19 -> 0.10447761 | AG5: =AVERAGE(R5:AF5) -> 0.10745572 | AI5: =SUMPRODUCT(C5:Q5,$C$20:$Q$20) -> 1.6351695 | AJ5: =AI5/AG5 -> 15.217147
B6: Esperanza | C6: =1/E4 -> 1 | D6: =1/E5 -> 0.14285714 | E6: 1 | F6: 0.14285714 | G6: 0.14285714 | H6: 0.14285714 | I6: 0.14285714 | J6: 1 | K6: 1 | L6: 0.2 | M6: 0.14285714 | N6: 0.14285714 | O6: 0.14285714 | P6: 1 | Q6: 1 | R6: =C6/C$19 -> 0.014925373 | S6: =D6/D$19 -> 0.015544041 | T6: =E6/E$19 -> 0.014925373 | U6: =F6/F$19 -> 0.015544041 | V6: =G6/G$19 -> 0.015544041 | W6: =H6/H$19 -> 0.015544041 | X6: =I6/I$19 -> 0.015544041 | Y6: =J6/J$19 -> 0.014925373 | ... AF6: =Q6/Q$19 -> 0.014925373 | AG6: =AVERAGE(R6:AF6) -> 0.014769211 | AI6: =SUMPRODUCT(C6:Q6,$C$20:$Q$20) -> 0.2217696 | AJ6: =AI6/AG6 -> 15.01567
B7: Jean y Marie Thierry | C7: =1/F4 -> 7 | D7: =1/F5 -> 1 | E7: =1/F6 -> 7 | F7: 1 | G7: 1 | H7: 1 | I7: 1 | J7: 7 | K7: 7 | L7: 3 | M7: 1 | N7: 1 | O7: 1 | P7: 7 | Q7: 7 | R7: =C7/C$19 -> 0.10447761 | S7: =D7/D$19 -> 0.10880829 | T7: =E7/E$19 -> 0.10447761 | U7: =F7/F$19 -> 0.10880829 | V7: =G7/G$19 -> 0.10880829 | W7: =H7/H$19 -> 0.10880829 | X7: =I7/I$19 -> 0.10880829 | Y7: =J7/J$19 -> 0.10447761 | ... AF7: =Q7/Q$19 -> 0.10447761 | AG7: =AVERAGE(R7:AF7) -> 0.10745572 | AI7: =SUMPRODUCT(C7:Q7,$C$20:$Q$20) -> 1.6351695 | AJ7: =AI7/AG7 -> 15.217147
B8: Laguna Verde | C8: =1/G4 -> 7 | D8: =1/G5 -> 1 | E8: =1/G6 -> 7 | F8: =1/G7 -> 1 | G8: 1 | H8: 1 | I8: 1 | J8: 7 | K8: 7 | L8: 3 | M8: 1 | N8: 1 | O8: 1 | P8: 7 | Q8: 7 | R8: =C8/C$19 -> 0.10447761 | S8: =D8/D$19 -> 0.10880829 | T8: =E8/E$19 -> 0.10447761 | U8: =F8/F$19 -> 0.10880829 | V8: =G8/G$19 -> 0.10880829 | W8: =H8/H$19 -> 0.10880829 | X8: =I8/I$19 -> 0.10880829 | Y8: =J8/J$19 -> 0.10447761 | ... AF8: =Q8/Q$19 -> 0.10447761 | AG8: =AVERAGE(R8:AF8) -> 0.10745572 | AI8: =SUMPRODUCT(C8:Q8,$C$20:$Q$20) -> 1.6351695 | AJ8: =AI8/AG8 -> 15.217147
B9: Las Cañas | C9: =1/H4 -> 7 | D9: =1/H5 -> 1 | E9: =1/H6 -> 7 | F9: =1/H7 -> 1 | G9: =1/H8 -> 1 | H9: 1 | I9: 1 | J9: 7 | K9: 7 | L9: 3 | M9: 1 | N9: 1 | O9: 1 | P9: 7 | Q9: 7 | R9: =C9/C$19 -> 0.10447761 | S9: =D9/D$19 -> 0.10880829 | T9: =E9/E$19 -> 0.10447761 | U9: =F9/F$19 -> 0.10880829 | V9: =G9/G$19 -> 0.10880829 | W9: =H9/H$19 -> 0.10880829 | X9: =I9/I$19 -> 0.10880829 | Y9: =J9/J$19 -> 0.10447761 | ... AF9: =Q9/Q$19 -> 0.10447761 | AG9: =AVERAGE(R9:AF9) -> 0.10745572 | AI9: =SUMPRODUCT(C9:Q9,$C$20:$Q$20) -> 1.6351695 | AJ9: =AI9/AG9 -> 15.217147
B10: Marcelo Mena | C10: =1/I4 -> 7 | D10: =1/I5 -> 1 | E10: =1/I6 -> 7 | F10: =1/I7 -> 1 | G10: =1/I8 -> 1 | H10: =1/I9 -> 1 | I10: 1 | J10: 7 | K10: 7 | L10: 3 | M10: 1 | N10: 1 | O10: 1 | P10: 7 | Q10: 7 | R10: =C10/C$19 -> 0.10447761 | S10: =D10/D$19 -> 0.10880829 | T10: =E10/E$19 -> 0.10447761 | U10: =F10/F$19 -> 0.10880829 | V10: =G10/G$19 -> 0.10880829 | W10: =H10/H$19 -> 0.10880829 | X10: =I10/I$19 -> 0.10880829 | Y10: =J10/J$19 -> 0.10447761 | ... AF10: =Q10/Q$19 -> 0.10447761 | AG10: =AVERAGE(R10:AF10) -> 0.10745572 | AI10: =SUMPRODUCT(C10:Q10,$C$20:$Q$20) -> 1.6351695 | AJ10: =AI10/AG10 -> 15.217147
B11: Padre Demian Molokai | C11: =1/J4 -> 1 | D11: =1/J5 -> 0.14285714 | E11: =1/J6 -> 1 | F11: =1/J7 -> 0.14285714 | G11: =1/J8 -> 0.14285714 | H11: =1/J9 -> 0.14285714 | I11: =1/J10 -> 0.14285714 | J11: 1 | K11: 1 | L11: 0.2 | M11: 0.14285714 | N11: 0.14285714 | O11: 0.14285714 | P11: 1 | Q11: 1 | R11: =C11/C$19 -> 0.014925373 | S11: =D11/D$19 -> 0.015544041 | T11: =E11/E$19 -> 0.014925373 | U11: =F11/F$19 -> 0.015544041 | V11: =G11/G$19 -> 0.015544041 | W11: =H11/H$19 -> 0.015544041 | X11: =I11/I$19 -> 0.015544041 | Y11: =J11/J$19 -> 0.014925373 | ... AF11: =Q11/Q$19 -> 0.014925373 | AG11: =AVERAGE(R11:AF11) -> 0.014769211 | AI11: =SUMPRODUCT(C11:Q11,$C$20:$Q$20) -> 0.2217696 | AJ11: =AI11/AG11 -> 15.01567
B12: Placeres | C12: =1/K4 -> 1 | D12: =1/K5 -> 0.14285714 | E12: =1/K6 -> 1 | F12: =1/K7 -> 0.14285714 | G12: =1/K8 -> 0.14285714 | H12: =1/K9 -> 0.14285714 | I12: =1/K10 -> 0.14285714 | J12: =1/K11 -> 1 | K12: 1 | L12: 0.2 | M12: 0.14285714 | N12: 0.14285714 | O12: 0.14285714 | P12: 1 | Q12: 1 | R12: =C12/C$19 -> 0.014925373 | S12: =D12/D$19 -> 0.015544041 | T12: =E12/E$19 -> 0.014925373 | U12: =F12/F$19 -> 0.015544041 | V12: =G12/G$19 -> 0.015544041 | W12: =H12/H$19 -> 0.015544041 | X12: =I12/I$19 -> 0.015544041 | Y12: =J12/J$19 -> 0.014925373 | ... AF12: =Q12/Q$19 -> 0.014925373 | AG12: =AVERAGE(R12:AF12) -> 0.014769211 | AI12: =SUMPRODUCT(C12:Q12,$C$20:$Q$20) -> 0.2217696 | AJ12: =AI12/AG12 -> 15.01567
B13: Placilla | C13: =1/L4 -> 5 | D13: =1/L5 -> 0.33333333 | E13: =1/L6 -> 5 | F13: =1/L7 -> 0.33333333 | G13: =1/L8 -> 0.33333333 | H13: =1/L9 -> 0.33333333 | I13: =1/L10 -> 0.33333333 | J13: =1/L11 -> 5 | K13: =1/L12 -> 5 | L13: 1 | M13: 0.33333333 | N13: 0.33333333 | O13: 0.33333333 | P13: 5 | Q13: 5 | R13: =C13/C$19 -> 0.074626866 | S13: =D13/D$19 -> 0.03626943 | T13: =E13/E$19 -> 0.074626866 | U13: =F13/F$19 -> 0.03626943 | V13: =G13/G$19 -> 0.03626943 | W13: =H13/H$19 -> 0.03626943 | X13: =I13/I$19 -> 0.03626943 | Y13: =J13/J$19 -> 0.074626866 | ... AF13: =Q13/Q$19 -> 0.074626866 | AG13: =AVERAGE(R13:AF13) -> 0.051738972 | AI13: =SUMPRODUCT(C13:Q13,$C$20:$Q$20) -> 0.78136388 | AJ13: =AI13/AG13 -> 15.102037
B14: Plaza Justicia | C14: =1/M4 -> 7 | D14: =1/M5 -> 1 | E14: =1/M6 -> 7 | F14: =1/M7 -> 1 | G14: =1/M8 -> 1 | H14: =1/M9 -> 1 | I14: =1/M10 -> 1 | J14: =1/M11 -> 7 | K14: =1/M12 -> 7 | L14: =1/M13 -> 3 | M14: 1 | N14: 1 | O14: 1 | P14: 7 | Q14: 7 | R14: =C14/C$19 -> 0.10447761 | S14: =D14/D$19 -> 0.10880829 | T14: =E14/E$19 -> 0.10447761 | U14: =F14/F$19 -> 0.10880829 | V14: =G14/G$19 -> 0.10880829 | W14: =H14/H$19 -> 0.10880829 | X14: =I14/I$19 -> 0.10880829 | Y14: =J14/J$19 -> 0.10447761 | ... AF14: =Q14/Q$19 -> 0.10447761 | AG14: =AVERAGE(R14:AF14) -> 0.10745572 | AI14: =SUMPRODUCT(C14:Q14,$C$20:$Q$20) -> 1.6351695 | AJ14: =AI14/AG14 -> 15.217147
B15: Puertas Negras | C15: =1/N4 -> 7 | D15: =1/N5 -> 1 | E15: =1/N6 -> 7 | F15: =1/N7 -> 1 | G15: =1/N8 -> 1 | H15: =1/N9 -> 1 | I15: =1/N10 -> 1 | J15: =1/N11 -> 7 | K15: =1/N12 -> 7 | L15: =1/N13 -> 3 | M15: =1/N14 -> 1 | N15: 1 | O15: 1 | P15: 7 | Q15: 7 | R15: =C15/C$19 -> 0.10447761 | S15: =D15/D$19 -> 0.10880829 | T15: =E15/E$19 -> 0.10447761 | U15: =F15/F$19 -> 0.10880829 | V15: =G15/G$19 -> 0.10880829 | W15: =H15/H$19 -> 0.10880829 | X15: =I15/I$19 -> 0.10880829 | Y15: =J15/J$19 -> 0.10447761 | ... AF15: =Q15/Q$19 -> 0.10447761 | AG15: =AVERAGE(R15:AF15) -> 0.10745572 | AI15: =SUMPRODUCT(C15:Q15,$C$20:$Q$20) -> 1.6351695 | AJ15: =AI15/AG15 -> 15.217147
B16: Quebrada Verde | C16: =1/O4 -> 7 | D16: =1/O5 -> 1 | E16: =1/O6 -> 7 | F16: =1/O7 -> 1 | G16: =1/O8 -> 1 | H16: =1/O9 -> 1 | I16: =1/O10 -> 1 | J16: =1/O11 -> 7 | K16: =1/O12 -> 7 | L16: =1/O13 -> 3 | M16: =1/O14 -> 1 | N16: =1/O15 -> 1 | O16: 1 | P16: 7 | Q16: 7 | R16: =C16/C$19 -> 0.10447761 | S16: =D16/D$19 -> 0.10880829 | T16: =E16/E$19 -> 0.10447761 | U16: =F16/F$19 -> 0.10880829 | V16: =G16/G$19 -> 0.10880829 | W16: =H16/H$19 -> 0.10880829 | X16: =I16/I$19 -> 0.10880829 | Y16: =J16/J$19 -> 0.10447761 | ... AF16: =Q16/Q$19 -> 0.10447761 | AG16: =AVERAGE(R16:AF16) -> 0.10745572 | AI16: =SUMPRODUCT(C16:Q16,$C$20:$Q$20) -> 1.6351695 | AJ16: =AI16/AG16 -> 15.217147
B17: Reina Isabel 2 | C17: =1/P4 -> 1 | D17: =1/P5 -> 0.14285714 | E17: =1/P6 -> 1 | F17: =1/P7 -> 0.14285714 | G17: =1/P8 -> 0.14285714 | H17: =1/P9 -> 0.14285714 | I17: =1/P10 -> 0.14285714 | J17: =1/P11 -> 1 | K17: =1/P12 -> 1 | L17: =1/P13 -> 0.2 | M17: =1/P14 -> 0.14285714 | N17: =1/P15 -> 0.14285714 | O17: =1/P16 -> 0.14285714 | P17: 1 | Q17: 1 | R17: =C17/C$19 -> 0.014925373 | S17: =D17/D$19 -> 0.015544041 | T17: =E17/E$19 -> 0.014925373 | U17: =F17/F$19 -> 0.015544041 | V17: =G17/G$19 -> 0.015544041 | W17: =H17/H$19 -> 0.015544041 | X17: =I17/I$19 -> 0.015544041 | Y17: =J17/J$19 -> 0.014925373 | ... AF17: =Q17/Q$19 -> 0.014925373 | AG17: =AVERAGE(R17:AF17) -> 0.014769211 | AI17: =SUMPRODUCT(C17:Q17,$C$20:$Q$20) -> 0.2217696 | AJ17: =AI17/AG17 -> 15.01567
B18: Rodelillo | C18: =1/Q4 -> 1 | D18: =1/Q5 -> 0.14285714 | E18: =1/Q6 -> 1 | F18: =1/Q7 -> 0.14285714 | G18: =1/Q8 -> 0.14285714 | H18: =1/Q9 -> 0.14285714 | I18: =1/Q10 -> 0.14285714 | J18: =1/Q11 -> 1 | K18: =1/Q12 -> 1 | L18: =1/Q13 -> 0.2 | M18: =1/Q14 -> 0.14285714 | N18: =1/Q15 -> 0.14285714 | O18: =1/Q16 -> 0.14285714 | P18: =1/Q17 -> 1 | Q18: 1 | R18: =C18/C$19 -> 0.014925373 | S18: =D18/D$19 -> 0.015544041 | T18: =E18/E$19 -> 0.014925373 | U18: =F18/F$19 -> 0.015544041 | V18: =G18/G$19 -> 0.015544041 | W18: =H18/H$19 -> 0.015544041 | X18: =I18/I$19 -> 0.015544041 | Y18: =J18/J$19 -> 0.014925373 | ... AF18: =Q18/Q$19 -> 0.014925373 | AG18: =AVERAGE(R18:AF18) -> 0.014769211 | AI18: =SUMPRODUCT(C18:Q18,$C$20:$Q$20) -> 0.2217696 | AJ18: =AI18/AG18 -> 15.01567
B19: Total | C19: =SUM(C4:C18) -> 67 | D19: =SUM(D4:D18) -> 9.1904762 | E19: =SUM(E4:E18) -> 67 | F19: =SUM(F4:F18) -> 9.1904762 | G19: =SUM(G4:G18) -> 9.1904762 | H19: =SUM(H4:H18) -> 9.1904762 | I19: =SUM(I4:I18) -> 9.1904762 | J19: =SUM(J4:J18) -> 67 | ... Q19: =SUM(Q4:Q18) -> 67
B20: Ponderación | C20: =AG4 -> 0.014769211 | D20: =AG5 -> 0.10745572 | E20: =AG6 -> 0.014769211 | F20: =AG7 -> 0.10745572 | G20: =AG8 -> 0.10745572 | H20: =AG9 -> 0.10745572 | I20: =AG10 -> 0.10745572 | J20: =AG11 -> 0.014769211 | K20: =AG12 -> 0.014769211 | L20: =AG13 -> 0.051738972 | M20: =AG14 -> 0.10745572 | N20: =AG15 -> 0.10745572 | O20: =AG16 -> 0.10745572 | P20: =AG17 -> 0.014769211 | Q20: =AG18 -> 0.014769211
B23: Cálculo y asignación de pesos
C24: MVA dispo | E24: estand | G24: comp | H24: ressult | I24: saaty
B25: 1 | C25: =(30*(1-0.5249)+25*(1-0.6298)) -> 23.508 | E25: =C25/$C$28 -> 0.21171131 | G25: 1.2 | H25: =E25/E26 -> 0.5795858 | I25: 5
B26: 2 | C26: =(30*(1-0.324)+30*(1-0.324)) -> 40.56 | E26: =C26/$C$28 -> 0.36528035 | G26: 1.3 | H26: =E25/E27 -> 0.50048967 | I26: 7
B27: 3 | C27: =(30*(1-0.4364)+25*(1-0.4622)+30*(1-0.4461)) -> 46.97 | E27: =C27/$C$28 -> 0.42300834 | G27: 2.3 | H27: =E26/E27 -> 0.86352991 | I27: 3
C28: =SUM(C25:C27) -> 111.038

Sheet C. Eco.
B2: Criterio Económico
B3: Alternativas | C3: Baron | D3: Cordillera | E3: Esperanza | F3: Jean y Marie Thierry | G3: Laguna Verde | H3: Las Cañas | I3: Marcelo Mena | J3: Padre Demian Molokai | K3: Placeres | L3: Placilla | M3: Plaza Justicia | N3: Puertas Negras | O3: Quebrada Verde | P3: Reina Isabel 2 | Q3: Rodelillo | R3: Matriz normalizada | AG3: Vector Promedio | AI3: Axw | AJ3: cocientes | AK3: λmax | AL3: n | AM3: RI | AO3: CI=(λmax-n)/(n-1) | AP3: =(AK4-AL4)/(AL4-1) -> 0.058810545
B4: Baron | C4: =IF(F24<0,"r", IF(F24=0,1, IF(AND(F24>=1,F24<=1.25),1, IF(AND(F24>1.25,F24<=1.5),3, IF(AND(F24>1.5,F24<=2),5, IF(AND(F24>2,F24<=3),7, IF(F24>3,9, ""))))))) -> 1 | D4: 1 | E4: 0.33333333 | F4: 1 | G4: 0.33333333 | H4: 0.33333333 | I4: =IF(L24<0,"r", IF(L24=0,1, IF(AND(L24>=1,L24<=1.25),1, IF(AND(L24>1.25,L24<=1.5),3, IF(AND(L24>1.5,L24<=2),5, IF(AND(L24>2,L24<=3),7, IF(L24>3,9, ""))))))) -> 7 | J4: =IF(M24<0,"r", IF(M24=0,1, IF(AND(M24>=1,M24<=1.25),1, IF(AND(M24>1.25,M24<=1.5),3, IF(AND(M24>1.5,M24<=2),5, IF(AND(M24>2,M24<=3),7, IF(M24>3,9, ""))))))) -> 7 | K4: 1 | L4: 1 | M4: =IF(P24<0,"r", IF(P24=0,1, IF(AND(P24>=1,P24<=1.25),1, IF(AND(P24>1.25,P24<=1.5),3, IF(AND(P24>1.5,P24<=2),5, IF(AND(P24>2,P24<=3),7, IF(P24>3,9, ""))))))) -> 9 | N4: 0.33333333 | O4: =IF(R24<0,"r", IF(R24=0,1, IF(AND(R24>=1,R24<=1.25),1, IF(AND(R24>1.25,R24<=1.5),3, IF(AND(R24>1.5,R24<=2),5, IF(AND(R24>2,R24<=3),7, IF(R24>3,9, ""))))))) -> 7 | P4: =IF(S24<0,"r", IF(S24=0,1, IF(AND(S24>=1,S24<=1.25),1, IF(AND(S24>1.25,S24<=1.5),3, IF(AND(S24>1.5,S24<=2),5, IF(AND(S24>2,S24<=3),7, IF(S24>3,9, ""))))))) -> 7 | Q4: =IF(T24<0,"r", IF(T24=0,1, IF(AND(T24>=1,T24<=1.25),1, IF(AND(T24>1.25,T24<=1.5),3, IF(AND(T24>1.5,T24<=2),5, IF(AND(T24>2,T24<=3),7, IF(T24>3,9, ""))))))) -> 7 | R4: =C4/C$19 -> 0.056099733 | S4: =D4/D$19 -> 0.056099733 | T4: =E4/E$19 -> 0.052631579 | U4: =F4/F$19 -> 0.056099733 | V4: =G4/G$19 -> 0.052631579 | W4: =H4/H$19 -> 0.052631579 | X4: =I4/I$19 -> 0.092511013 | Y4: =J4/J$19 -> 0.092511013 | ... AF4: =Q4/Q$19 -> 0.092511013 | AG4: =AVERAGE(R4:AF4) -> 0.069091049 | AI4: =SUMPRODUCT(C4:Q4,$C$20:$Q$20) -> 1.1193947 | AJ4: =AI4/AG4 -> 16.201732 | AK4: =AVERAGE(AJ4:AJ18) -> 15.823348 | AL4: 15 | AM4: =(1.86668*(15-2))/15 -> 1.6177893 | AO4: CR=CI/RI | AP4: =AP3/AM4 -> 0.036352413
B5: Cordillera | C5: =IF(F25<0,"r", IF(F25=0,1, IF(AND(F25>=1,F25<=1.25),1, IF(AND(F25>1.25,F25<=1.5),3, IF(AND(F25>1.5,F25<=2),5, IF(AND(F25>2,F25<=3),7, IF(F25>3,9, ""))))))) -> 1 | D5: =IF(G25<0,"r", IF(G25=0,1, IF(AND(G25>=1,G25<=1.25),1, IF(AND(G25>1.25,G25<=1.5),3, IF(AND(G25>1.5,G25<=2),5, IF(AND(G25>2,G25<=3),7, IF(G25>3,9, ""))))))) -> 1 | E5: 0.33333333 | F5: =IF(I25<0,"r", IF(I25=0,1, IF(AND(I25>=1,I25<=1.25),1, IF(AND(I25>1.25,I25<=1.5),3, IF(AND(I25>1.5,I25<=2),5, IF(AND(I25>2,I25<=3),7, IF(I25>3,9, ""))))))) -> 1 | G5: 0.33333333 | H5: 0.33333333 | I5: =IF(L25<0,"r", IF(L25=0,1, IF(AND(L25>=1,L25<=1.25),1, IF(AND(L25>1.25,L25<=1.5),3, IF(AND(L25>1.5,L25<=2),5, IF(AND(L25>2,L25<=3),7, IF(L25>3,9, ""))))))) -> 7 | J5: =IF(M25<0,"r", IF(M25=0,1, IF(AND(M25>=1,M25<=1.25),1, IF(AND(M25>1.25,M25<=1.5),3, IF(AND(M25>1.5,M25<=2),5, IF(AND(M25>2,M25<=3),7, IF(M25>3,9, ""))))))) -> 7 | K5: =IF(N25<0,"r", IF(N25=0,1, IF(AND(N25>=1,N25<=1.25),1, IF(AND(N25>1.25,N25<=1.5),3, IF(AND(N25>1.5,N25<=2),5, IF(AND(N25>2,N25<=3),7, IF(N25>3,9, ""))))))) -> 1 | L5: 1 | M5: =IF(P25<0,"r", IF(P25=0,1, IF(AND(P25>=1,P25<=1.25),1, IF(AND(P25>1.25,P25<=1.5),3, IF(AND(P25>1.5,P25<=2),5, IF(AND(P25>2,P25<=3),7, IF(P25>3,9, ""))))))) -> 9 | N5: 0.33333333 | O5: =IF(R25<0,"r", IF(R25=0,1, IF(AND(R25>=1,R25<=1.25),1, IF(AND(R25>1.25,R25<=1.5),3, IF(AND(R25>1.5,R25<=2),5, IF(AND(R25>2,R25<=3),7, IF(R25>3,9, ""))))))) -> 7 | P5: =IF(S25<0,"r", IF(S25=0,1, IF(AND(S25>=1,S25<=1.25),1, IF(AND(S25>1.25,S25<=1.5),3, IF(AND(S25>1.5,S25<=2),5, IF(AND(S25>2,S25<=3),7, IF(S25>3,9, ""))))))) -> 7 | Q5: =IF(T25<0,"r", IF(T25=0,1, IF(AND(T25>=1,T25<=1.25),1, IF(AND(T25>1.25,T25<=1.5),3, IF(AND(T25>1.5,T25<=2),5, IF(AND(T25>2,T25<=3),7, IF(T25>3,9, ""))))))) -> 7 | R5: =C5/C$19 -> 0.056099733 | S5: =D5/D$19 -> 0.056099733 | T5: =E5/E$19 -> 0.052631579 | U5: =F5/F$19 -> 0.056099733 | V5: =G5/G$19 -> 0.052631579 | W5: =H5/H$19 -> 0.052631579 | X5: =I5/I$19 -> 0.092511013 | Y5: =J5/J$19 -> 0.092511013 | ... AF5: =Q5/Q$19 -> 0.092511013 | AG5: =AVERAGE(R5:AF5) -> 0.069091049 | AI5: =SUMPRODUCT(C5:Q5,$C$20:$Q$20) -> 1.1193947 | AJ5: =AI5/AG5 -> 16.201732
B6: Esperanza | C6: =IF(F26<0,"r", IF(F26=0,1, IF(AND(F26>=1,F26<=1.25),1, IF(AND(F26>1.25,F26<=1.5),3, IF(AND(F26>1.5,F26<=2),5, IF(AND(F26>2,F26<=3),7, IF(F26>3,9, ""))))))) -> 3 | D6: =IF(G26<0,"r", IF(G26=0,1, IF(AND(G26>=1,G26<=1.25),1, IF(AND(G26>1.25,G26<=1.5),3, IF(AND(G26>1.5,G26<=2),5, IF(AND(G26>2,G26<=3),7, IF(G26>3,9, ""))))))) -> 3 | E6: =IF(H26<0,"r", IF(H26=0,1, IF(AND(H26>=1,H26<=1.25),1, IF(AND(H26>1.25,H26<=1.5),3, IF(AND(H26>1.5,H26<=2),5, IF(AND(H26>2,H26<=3),7, IF(H26>3,9, ""))))))) -> 1 | F6: =IF(I26<0,"r", IF(I26=0,1, IF(AND(I26>=1,I26<=1.25),1, IF(AND(I26>1.25,I26<=1.5),3, IF(AND(I26>1.5,I26<=2),5, IF(AND(I26>2,I26<=3),7, IF(I26>3,9, ""))))))) -> 3 | G6: 1 | H6: 1 | I6: =IF(L26<0,"r", IF(L26=0,1, IF(AND(L26>=1,L26<=1.25),1, IF(AND(L26>1.25,L26<=1.5),3, IF(AND(L26>1.5,L26<=2),5, IF(AND(L26>2,L26<=3),7, IF(L26>3,9, ""))))))) -> 9 | J6: =IF(M26<0,"r", IF(M26=0,1, IF(AND(M26>=1,M26<=1.25),1, IF(AND(M26>1.25,M26<=1.5),3, IF(AND(M26>1.5,M26<=2),5, IF(AND(M26>2,M26<=3),7, IF(M26>3,9, ""))))))) -> 9 | K6: =IF(N26<0,"r", IF(N26=0,1, IF(AND(N26>=1,N26<=1.25),1, IF(AND(N26>1.25,N26<=1.5),3, IF(AND(N26>1.5,N26<=2),5, IF(AND(N26>2,N26<=3),7, IF(N26>3,9, ""))))))) -> 3 | L6: =IF(O26<0,"r", IF(O26=0,1, IF(AND(O26>=1,O26<=1.25),1, IF(AND(O26>1.25,O26<=1.5),3, IF(AND(O26>1.5,O26<=2),5, IF(AND(O26>2,O26<=3),7, IF(O26>3,9, ""))))))) -> 3 | M6: =IF(P26<0,"r", IF(P26=0,1, IF(AND(P26>=1,P26<=1.25),1, IF(AND(P26>1.25,P26<=1.5),3, IF(AND(P26>1.5,P26<=2),5, IF(AND(P26>2,P26<=3),7, IF(P26>3,9, ""))))))) -> 9 | N6: 1 | O6: =IF(R26<0,"r", IF(R26=0,1, IF(AND(R26>=1,R26<=1.25),1, IF(AND(R26>1.25,R26<=1.5),3, IF(AND(R26>1.5,R26<=2),5, IF(AND(R26>2,R26<=3),7, IF(R26>3,9, ""))))))) -> 9 | P6: =IF(S26<0,"r", IF(S26=0,1, IF(AND(S26>=1,S26<=1.25),1, IF(AND(S26>1.25,S26<=1.5),3, IF(AND(S26>1.5,S26<=2),5, IF(AND(S26>2,S26<=3),7, IF(S26>3,9, ""))))))) -> 9 | Q6: =IF(T26<0,"r", IF(T26=0,1, IF(AND(T26>=1,T26<=1.25),1, IF(AND(T26>1.25,T26<=1.5),3, IF(AND(T26>1.5,T26<=2),5, IF(AND(T26>2,T26<=3),7, IF(T26>3,9, ""))))))) -> 9 | R6: =C6/C$19 -> 0.1682992 | S6: =D6/D$19 -> 0.1682992 | T6: =E6/E$19 -> 0.15789474 | U6: =F6/F$19 -> 0.1682992 | V6: =G6/G$19 -> 0.15789474 | W6: =H6/H$19 -> 0.15789474 | X6: =I6/I$19 -> 0.11894273 | Y6: =J6/J$19 -> 0.11894273 | ... AF6: =Q6/Q$19 -> 0.11894273 | AG6: =AVERAGE(R6:AF6) -> 0.14315542 | AI6: =SUMPRODUCT(C6:Q6,$C$20:$Q$20) -> 2.3370998 | AJ6: =AI6/AG6 -> 16.325612
B7: Jean y Marie Thierry | C7: =IF(F27<0,"r", IF(F27=0,1, IF(AND(F27>=1,F27<=1.25),1, IF(AND(F27>1.25,F27<=1.5),3, IF(AND(F27>1.5,F27<=2),5, IF(AND(F27>2,F27<=3),7, IF(F27>3,9, ""))))))) -> 1 | D7: 1 | E7: 0.33333333 | F7: =IF(I27<0,"r", IF(I27=0,1, IF(AND(I27>=1,I27<=1.25),1, IF(AND(I27>1.25,I27<=1.5),3, IF(AND(I27>1.5,I27<=2),5, IF(AND(I27>2,I27<=3),7, IF(I27>3,9, ""))))))) -> 1 | G7: 0.33333333 | H7: 0.33333333 | I7: =IF(L27<0,"r", IF(L27=0,1, IF(AND(L27>=1,L27<=1.25),1, IF(AND(L27>1.25,L27<=1.5),3, IF(AND(L27>1.5,L27<=2),5, IF(AND(L27>2,L27<=3),7, IF(L27>3,9, ""))))))) -> 7 | J7: =IF(M27<0,"r", IF(M27=0,1, IF(AND(M27>=1,M27<=1.25),1, IF(AND(M27>1.25,M27<=1.5),3, IF(AND(M27>1.5,M27<=2),5, IF(AND(M27>2,M27<=3),7, IF(M27>3,9, ""))))))) -> 7 | K7: =IF(N27<0,"r", IF(N27=0,1, IF(AND(N27>=1,N27<=1.25),1, IF(AND(N27>1.25,N27<=1.5),3, IF(AND(N27>1.5,N27<=2),5, IF(AND(N27>2,N27<=3),7, IF(N27>3,9, ""))))))) -> 1 | L7: 1 | M7: =IF(P27<0,"r", IF(P27=0,1, IF(AND(P27>=1,P27<=1.25),1, IF(AND(P27>1.25,P27<=1.5),3, IF(AND(P27>1.5,P27<=2),5, IF(AND(P27>2,P27<=3),7, IF(P27>3,9, ""))))))) -> 9 | N7: 0.33333333 | O7: =IF(R27<0,"r", IF(R27=0,1, IF(AND(R27>=1,R27<=1.25),1, IF(AND(R27>1.25,R27<=1.5),3, IF(AND(R27>1.5,R27<=2),5, IF(AND(R27>2,R27<=3),7, IF(R27>3,9, ""))))))) -> 7 | P7: =IF(S27<0,"r", IF(S27=0,1, IF(AND(S27>=1,S27<=1.25),1, IF(AND(S27>1.25,S27<=1.5),3, IF(AND(S27>1.5,S27<=2),5, IF(AND(S27>2,S27<=3),7, IF(S27>3,9, ""))))))) -> 7 | Q7: =IF(T27<0,"r", IF(T27=0,1, IF(AND(T27>=1,T27<=1.25),1, IF(AND(T27>1.25,T27<=1.5),3, IF(AND(T27>1.5,T27<=2),5, IF(AND(T27>2,T27<=3),7, IF(T27>3,9, ""))))))) -> 7 | R7: =C7/C$19 -> 0.056099733 | S7: =D7/D$19 -> 0.056099733 | T7: =E7/E$19 -> 0.052631579 | U7: =F7/F$19 -> 0.056099733 | V7: =G7/G$19 -> 0.052631579 | W7: =H7/H$19 -> 0.052631579 | X7: =I7/I$19 -> 0.092511013 | Y7: =J7/J$19 -> 0.092511013 | ... AF7: =Q7/Q$19 -> 0.092511013 | AG7: =AVERAGE(R7:AF7) -> 0.069091049 | AI7: =SUMPRODUCT(C7:Q7,$C$20:$Q$20) -> 1.1193947 | AJ7: =AI7/AG7 -> 16.201732
B8: Laguna Verde | C8: =IF(F28<0,"r", IF(F28=0,1, IF(AND(F28>=1,F28<=1.25),1, IF(AND(F28>1.25,F28<=1.5),3, IF(AND(F28>1.5,F28<=2),5, IF(AND(F28>2,F28<=3),7, IF(F28>3,9, ""))))))) -> 3 | D8: =IF(G28<0,"r", IF(G28=0,1, IF(AND(G28>=1,G28<=1.25),1, IF(AND(G28>1.25,G28<=1.5),3, IF(AND(G28>1.5,G28<=2),5, IF(AND(G28>2,G28<=3),7, IF(G28>3,9, ""))))))) -> 3 | E8: =IF(H28<0,"r", IF(H28=0,1, IF(AND(H28>=1,H28<=1.25),1, IF(AND(H28>1.25,H28<=1.5),3, IF(AND(H28>1.5,H28<=2),5, IF(AND(H28>2,H28<=3),7, IF(H28>3,9, ""))))))) -> 1 | F8: =IF(I28<0,"r", IF(I28=0,1, IF(AND(I28>=1,I28<=1.25),1, IF(AND(I28>1.25,I28<=1.5),3, IF(AND(I28>1.5,I28<=2),5, IF(AND(I28>2,I28<=3),7, IF(I28>3,9, ""))))))) -> 3 | G8: =IF(J28<0,"r", IF(J28=0,1, IF(AND(J28>=1,J28<=1.25),1, IF(AND(J28>1.25,J28<=1.5),3, IF(AND(J28>1.5,J28<=2),5, IF(AND(J28>2,J28<=3),7, IF(J28>3,9, ""))))))) -> 1 | H8: =IF(K28<0,"r", IF(K28=0,1, IF(AND(K28>=1,K28<=1.25),1, IF(AND(K28>1.25,K28<=1.5),3, IF(AND(K28>1.5,K28<=2),5, IF(AND(K28>2,K28<=3),7, IF(K28>3,9, ""))))))) -> 1 | I8: =IF(L28<0,"r", IF(L28=0,1, IF(AND(L28>=1,L28<=1.25),1, IF(AND(L28>1.25,L28<=1.5),3, IF(AND(L28>1.5,L28<=2),5, IF(AND(L28>2,L28<=3),7, IF(L28>3,9, ""))))))) -> 9 | J8: =IF(M28<0,"r", IF(M28=0,1, IF(AND(M28>=1,M28<=1.25),1, IF(AND(M28>1.25,M28<=1.5),3, IF(AND(M28>1.5,M28<=2),5, IF(AND(M28>2,M28<=3),7, IF(M28>3,9, ""))))))) -> 9 | ... Q8: =IF(T28<0,"r", IF(T28=0,1, IF(AND(T28>=1,T28<=1.25),1, IF(AND(T28>1.25,T28<=1.5),3, IF(AND(T28>1.5,T28<=2),5, IF(AND(T28>2,T28<=3),7, IF(T28>3,9, ""))))))) -> 9 | R8: =C8/C$19 -> 0.1682992 | S8: =D8/D$19 -> 0.1682992 | T8: =E8/E$19 -> 0.15789474 | U8: =F8/F$19 -> 0.1682992 | V8: =G8/G$19 -> 0.15789474 | W8: =H8/H$19 -> 0.15789474 | X8: =I8/I$19 -> 0.11894273 | Y8: =J8/J$19 -> 0.11894273 | ... AF8: =Q8/Q$19 -> 0.11894273 | AG8: =AVERAGE(R8:AF8) -> 0.14315542 | AI8: =SUMPRODUCT(C8:Q8,$C$20:$Q$20) -> 2.3370998 | AJ8: =AI8/AG8 -> 16.325612
B9: Las Cañas | C9: =IF(F29<0,"r", IF(F29=0,1, IF(AND(F29>=1,F29<=1.25),1, IF(AND(F29>1.25,F29<=1.5),3, IF(AND(F29>1.5,F29<=2),5, IF(AND(F29>2,F29<=3),7, IF(F29>3,9, ""))))))) -> 3 | D9: =IF(G29<0,"r", IF(G29=0,1, IF(AND(G29>=1,G29<=1.25),1, IF(AND(G29>1.25,G29<=1.5),3, IF(AND(G29>1.5,G29<=2),5, IF(AND(G29>2,G29<=3),7, IF(G29>3,9, ""))))))) -> 3 | E9: =IF(H29<0,"r", IF(H29=0,1, IF(AND(H29>=1,H29<=1.25),1, IF(AND(H29>1.25,H29<=1.5),3, IF(AND(H29>1.5,H29<=2),5, IF(AND(H29>2,H29<=3),7, IF(H29>3,9, ""))))))) -> 1 | F9: =IF(I29<0,"r", IF(I29=0,1, IF(AND(I29>=1,I29<=1.25),1, IF(AND(I29>1.25,I29<=1.5),3, IF(AND(I29>1.5,I29<=2),5, IF(AND(I29>2,I29<=3),7, IF(I29>3,9, ""))))))) -> 3 | G9: 1 | H9: =IF(K29<0,"r", IF(K29=0,1, IF(AND(K29>=1,K29<=1.25),1, IF(AND(K29>1.25,K29<=1.5),3, IF(AND(K29>1.5,K29<=2),5, IF(AND(K29>2,K29<=3),7, IF(K29>3,9, ""))))))) -> 1 | I9: =IF(L29<0,"r", IF(L29=0,1, IF(AND(L29>=1,L29<=1.25),1, IF(AND(L29>1.25,L29<=1.5),3, IF(AND(L29>1.5,L29<=2),5, IF(AND(L29>2,L29<=3),7, IF(L29>3,9, ""))))))) -> 9 | J9: =IF(M29<0,"r", IF(M29=0,1, IF(AND(M29>=1,M29<=1.25),1, IF(AND(M29>1.25,M29<=1.5),3, IF(AND(M29>1.5,M29<=2),5, IF(AND(M29>2,M29<=3),7, IF(M29>3,9, ""))))))) -> 9 | K9: =IF(N29<0,"r", IF(N29=0,1, IF(AND(N29>=1,N29<=1.25),1, IF(AND(N29>1.25,N29<=1.5),3, IF(AND(N29>1.5,N29<=2),5, IF(AND(N29>2,N29<=3),7, IF(N29>3,9, ""))))))) -> 3 | L9: =IF(O29<0,"r", IF(O29=0,1, IF(AND(O29>=1,O29<=1.25),1, IF(AND(O29>1.25,O29<=1.5),3, IF(AND(O29>1.5,O29<=2),5, IF(AND(O29>2,O29<=3),7, IF(O29>3,9, ""))))))) -> 3 | M9: =IF(P29<0,"r", IF(P29=0,1, IF(AND(P29>=1,P29<=1.25),1, IF(AND(P29>1.25,P29<=1.5),3, IF(AND(P29>1.5,P29<=2),5, IF(AND(P29>2,P29<=3),7, IF(P29>3,9, ""))))))) -> 9 | N9: 1 | O9: =IF(R29<0,"r", IF(R29=0,1, IF(AND(R29>=1,R29<=1.25),1, IF(AND(R29>1.25,R29<=1.5),3, IF(AND(R29>1.5,R29<=2),5, IF(AND(R29>2,R29<=3),7, IF(R29>3,9, ""))))))) -> 9 | P9: =IF(S29<0,"r", IF(S29=0,1, IF(AND(S29>=1,S29<=1.25),1, IF(AND(S29>1.25,S29<=1.5),3, IF(AND(S29>1.5,S29<=2),5, IF(AND(S29>2,S29<=3),7, IF(S29>3,9, ""))))))) -> 9 | Q9: =IF(T29<0,"r", IF(T29=0,1, IF(AND(T29>=1,T29<=1.25),1, IF(AND(T29>1.25,T29<=1.5),3, IF(AND(T29>1.5,T29<=2),5, IF(AND(T29>2,T29<=3),7, IF(T29>3,9, ""))))))) -> 9 | R9: =C9/C$19 -> 0.1682992 | S9: =D9/D$19 -> 0.1682992 | T9: =E9/E$19 -> 0.15789474 | U9: =F9/F$19 -> 0.1682992 | V9: =G9/G$19 -> 0.15789474 | W9: =H9/H$19 -> 0.15789474 | X9: =I9/I$19 -> 0.11894273 | Y9: =J9/J$19 -> 0.11894273 | ... AF9: =Q9/Q$19 -> 0.11894273 | AG9: =AVERAGE(R9:AF9) -> 0.14315542 | AI9: =SUMPRODUCT(C9:Q9,$C$20:$Q$20) -> 2.3370998 | AJ9: =AI9/AG9 -> 16.325612
B10: Marcelo Mena | C10: 0.14285714 | D10: 0.14285714 | E10: 0.11111111 | F10: 0.14285714 | G10: 0.11111111 | H10: 0.11111111 | I10: =IF(L30<0,"r", IF(L30=0,1, IF(AND(L30>=1,L30<=1.25),1, IF(AND(L30>1.25,L30<=1.5),3, IF(AND(L30>1.5,L30<=2),5, IF(AND(L30>2,L30<=3),7, IF(L30>3,9, ""))))))) -> 1 | J10: =IF(M30<0,"r", IF(M30=0,1, IF(AND(M30>=1,M30<=1.25),1, IF(AND(M30>1.25,M30<=1.5),3, IF(AND(M30>1.5,M30<=2),5, IF(AND(M30>2,M30<=3),7, IF(M30>3,9, ""))))))) -> 1 | K10: 0.14285714 | L10: 0.14285714 | M10: =IF(P30<0,"r", IF(P30=0,1, IF(AND(P30>=1,P30<=1.25),1, IF(AND(P30>1.25,P30<=1.5),3, IF(AND(P30>1.5,P30<=2),5, IF(AND(P30>2,P30<=3),7, IF(P30>3,9, ""))))))) -> 3 | N10: 0.11111111 | O10: =IF(R30<0,"r", IF(R30=0,1, IF(AND(R30>=1,R30<=1.25),1, IF(AND(R30>1.25,R30<=1.5),3, IF(AND(R30>1.5,R30<=2),5, IF(AND(R30>2,R30<=3),7, IF(R30>3,9, ""))))))) -> 3 | P10: =IF(S30<0,"r", IF(S30=0,1, IF(AND(S30>=1,S30<=1.25),1, IF(AND(S30>1.25,S30<=1.5),3, IF(AND(S30>1.5,S30<=2),5, IF(AND(S30>2,S30<=3),7, IF(S30>3,9, ""))))))) -> 1 | Q10: =IF(T30<0,"r", IF(T30=0,1, IF(AND(T30>=1,T30<=1.25),1, IF(AND(T30>1.25,T30<=1.5),3, IF(AND(T30>1.5,T30<=2),5, IF(AND(T30>2,T30<=3),7, IF(T30>3,9, ""))))))) -> 1 | R10: =C10/C$19 -> 0.0080142476 | S10: =D10/D$19 -> 0.0080142476 | T10: =E10/E$19 -> 0.01754386 | U10: =F10/F$19 -> 0.0080142476 | V10: =G10/G$19 -> 0.01754386 | W10: =H10/H$19 -> 0.01754386 | X10: =I10/I$19 -> 0.013215859 | Y10: =J10/J$19 -> 0.013215859 | ... AF10: =Q10/Q$19 -> 0.013215859 | AG10: =AVERAGE(R10:AF10) -> 0.015279074 | AI10: =SUMPRODUCT(C10:Q10,$C$20:$Q$20) -> 0.23213329 | AJ10: =AI10/AG10 -> 15.192889
B11: Padre Demian Molokai | C11: 0.14285714 | D11: 0.14285714 | E11: 0.11111111 | F11: 0.14285714 | G11: 0.11111111 | H11: 0.11111111 | I11: 1 | J11: =IF(M31<0,"r", IF(M31=0,1, IF(AND(M31>=1,M31<=1.25),1, IF(AND(M31>1.25,M31<=1.5),3, IF(AND(M31>1.5,M31<=2),5, IF(AND(M31>2,M31<=3),7, IF(M31>3,9, ""))))))) -> 1 | K11: 0.14285714 | L11: 0.14285714 | M11: =IF(P31<0,"r", IF(P31=0,1, IF(AND(P31>=1,P31<=1.25),1, IF(AND(P31>1.25,P31<=1.5),3, IF(AND(P31>1.5,P31<=2),5, IF(AND(P31>2,P31<=3),7, IF(P31>3,9, ""))))))) -> 3 | N11: 0.11111111 | O11: =IF(R31<0,"r", IF(R31=0,1, IF(AND(R31>=1,R31<=1.25),1, IF(AND(R31>1.25,R31<=1.5),3, IF(AND(R31>1.5,R31<=2),5, IF(AND(R31>2,R31<=3),7, IF(R31>3,9, ""))))))) -> 3 | P11: =IF(S31<0,"r", IF(S31=0,1, IF(AND(S31>=1,S31<=1.25),1, IF(AND(S31>1.25,S31<=1.5),3, IF(AND(S31>1.5,S31<=2),5, IF(AND(S31>2,S31<=3),7, IF(S31>3,9, ""))))))) -> 1 | Q11: 1 | R11: =C11/C$19 -> 0.0080142476 | S11: =D11/D$19 -> 0.0080142476 | T11: =E11/E$19 -> 0.01754386 | U11: =F11/F$19 -> 0.0080142476 | V11: =G11/G$19 -> 0.01754386 | W11: =H11/H$19 -> 0.01754386 | X11: =I11/I$19 -> 0.013215859 | Y11: =J11/J$19 -> 0.013215859 | ... AF11: =Q11/Q$19 -> 0.013215859 | AG11: =AVERAGE(R11:AF11) -> 0.015279074 | AI11: =SUMPRODUCT(C11:Q11,$C$20:$Q$20) -> 0.23213329 | AJ11: =AI11/AG11 -> 15.192889
B12: Placeres | C12: =IF(F32<0,"r", IF(F32=0,1, IF(AND(F32>=1,F32<=1.25),1, IF(AND(F32>1.25,F32<=1.5),3, IF(AND(F32>1.5,F32<=2),5, IF(AND(F32>2,F32<=3),7, IF(F32>3,9, ""))))))) -> 1 | D12: 1 | E12: 0.33333333 | F12: 1 | G12: 0.33333333 | H12: 0.33333333 | I12: =IF(L32<0,"r", IF(L32=0,1, IF(AND(L32>=1,L32<=1.25),1, IF(AND(L32>1.25,L32<=1.5),3, IF(AND(L32>1.5,L32<=2),5, IF(AND(L32>2,L32<=3),7, IF(L32>3,9, ""))))))) -> 7 | J12: =IF(M32<0,"r", IF(M32=0,1, IF(AND(M32>=1,M32<=1.25),1, IF(AND(M32>1.25,M32<=1.5),3, IF(AND(M32>1.5,M32<=2),5, IF(AND(M32>2,M32<=3),7, IF(M32>3,9, ""))))))) -> 7 | K12: =IF(N32<0,"r", IF(N32=0,1, IF(AND(N32>=1,N32<=1.25),1, IF(AND(N32>1.25,N32<=1.5),3, IF(AND(N32>1.5,N32<=2),5, IF(AND(N32>2,N32<=3),7, IF(N32>3,9, ""))))))) -> 1 | L12: 1 | M12: =IF(P32<0,"r", IF(P32=0,1, IF(AND(P32>=1,P32<=1.25),1, IF(AND(P32>1.25,P32<=1.5),3, IF(AND(P32>1.5,P32<=2),5, IF(AND(P32>2,P32<=3),7, IF(P32>3,9, ""))))))) -> 9 | N12: 0.33333333 | O12: =IF(R32<0,"r", IF(R32=0,1, IF(AND(R32>=1,R32<=1.25),1, IF(AND(R32>1.25,R32<=1.5),3, IF(AND(R32>1.5,R32<=2),5, IF(AND(R32>2,R32<=3),7, IF(R32>3,9, ""))))))) -> 7 | P12: =IF(S32<0,"r", IF(S32=0,1, IF(AND(S32>=1,S32<=1.25),1, IF(AND(S32>1.25,S32<=1.5),3, IF(AND(S32>1.5,S32<=2),5, IF(AND(S32>2,S32<=3),7, IF(S32>3,9, ""))))))) -> 7 | Q12: =IF(T32<0,"r", IF(T32=0,1, IF(AND(T32>=1,T32<=1.25),1, IF(AND(T32>1.25,T32<=1.5),3, IF(AND(T32>1.5,T32<=2),5, IF(AND(T32>2,T32<=3),7, IF(T32>3,9, ""))))))) -> 7 | R12: =C12/C$19 -> 0.056099733 | S12: =D12/D$19 -> 0.056099733 | T12: =E12/E$19 -> 0.052631579 | U12: =F12/F$19 -> 0.056099733 | V12: =G12/G$19 -> 0.052631579 | W12: =H12/H$19 -> 0.052631579 | X12: =I12/I$19 -> 0.092511013 | Y12: =J12/J$19 -> 0.092511013 | ... AF12: =Q12/Q$19 -> 0.092511013 | AG12: =AVERAGE(R12:AF12) -> 0.069091049 | AI12: =SUMPRODUCT(C12:Q12,$C$20:$Q$20) -> 1.1193947 | AJ12: =AI12/AG12 -> 16.201732
B13: Placilla | C13: =IF(F33<0,"r", IF(F33=0,1, IF(AND(F33>=1,F33<=1.25),1, IF(AND(F33>1.25,F33<=1.5),3, IF(AND(F33>1.5,F33<=2),5, IF(AND(F33>2,F33<=3),7, IF(F33>3,9, ""))))))) -> 1 | D13: =IF(G33<0,"r", IF(G33=0,1, IF(AND(G33>=1,G33<=1.25),1, IF(AND(G33>1.25,G33<=1.5),3, IF(AND(G33>1.5,G33<=2),5, IF(AND(G33>2,G33<=3),7, IF(G33>3,9, ""))))))) -> 1 | E13: 0.33333333 | F13: =IF(I33<0,"r", IF(I33=0,1, IF(AND(I33>=1,I33<=1.25),1, IF(AND(I33>1.25,I33<=1.5),3, IF(AND(I33>1.5,I33<=2),5, IF(AND(I33>2,I33<=3),7, IF(I33>3,9, ""))))))) -> 1 | G13: 0.33333333 | H13: 0.33333333 | I13: =IF(L33<0,"r", IF(L33=0,1, IF(AND(L33>=1,L33<=1.25),1, IF(AND(L33>1.25,L33<=1.5),3, IF(AND(L33>1.5,L33<=2),5, IF(AND(L33>2,L33<=3),7, IF(L33>3,9, ""))))))) -> 7 | J13: =IF(M33<0,"r", IF(M33=0,1, IF(AND(M33>=1,M33<=1.25),1, IF(AND(M33>1.25,M33<=1.5),3, IF(AND(M33>1.5,M33<=2),5, IF(AND(M33>2,M33<=3),7, IF(M33>3,9, ""))))))) -> 7 | K13: =IF(N33<0,"r", IF(N33=0,1, IF(AND(N33>=1,N33<=1.25),1, IF(AND(N33>1.25,N33<=1.5),3, IF(AND(N33>1.5,N33<=2),5, IF(AND(N33>2,N33<=3),7, IF(N33>3,9, ""))))))) -> 1 | L13: =IF(O33<0,"r", IF(O33=0,1, IF(AND(O33>=1,O33<=1.25),1, IF(AND(O33>1.25,O33<=1.5),3, IF(AND(O33>1.5,O33<=2),5, IF(AND(O33>2,O33<=3),7, IF(O33>3,9, ""))))))) -> 1 | M13: =IF(P33<0,"r", IF(P33=0,1, IF(AND(P33>=1,P33<=1.25),1, IF(AND(P33>1.25,P33<=1.5),3, IF(AND(P33>1.5,P33<=2),5, IF(AND(P33>2,P33<=3),7, IF(P33>3,9, ""))))))) -> 9 | N13: 0.33333333 | O13: =IF(R33<0,"r", IF(R33=0,1, IF(AND(R33>=1,R33<=1.25),1, IF(AND(R33>1.25,R33<=1.5),3, IF(AND(R33>1.5,R33<=2),5, IF(AND(R33>2,R33<=3),7, IF(R33>3,9, ""))))))) -> 9 | P13: =IF(S33<0,"r", IF(S33=0,1, IF(AND(S33>=1,S33<=1.25),1, IF(AND(S33>1.25,S33<=1.5),3, IF(AND(S33>1.5,S33<=2),5, IF(AND(S33>2,S33<=3),7, IF(S33>3,9, ""))))))) -> 7 | Q13: =IF(T33<0,"r", IF(T33=0,1, IF(AND(T33>=1,T33<=1.25),1, IF(AND(T33>1.25,T33<=1.5),3, IF(AND(T33>1.5,T33<=2),5, IF(AND(T33>2,T33<=3),7, IF(T33>3,9, ""))))))) -> 7 | R13: =C13/C$19 -> 0.056099733 | S13: =D13/D$19 -> 0.056099733 | T13: =E13/E$19 -> 0.052631579 | U13: =F13/F$19 -> 0.056099733 | V13: =G13/G$19 -> 0.052631579 | W13: =H13/H$19 -> 0.052631579 | X13: =I13/I$19 -> 0.092511013 | Y13: =J13/J$19 -> 0.092511013 | ... AF13: =Q13/Q$19 -> 0.092511013 | AG13: =AVERAGE(R13:AF13) -> 0.070623616 | AI13: =SUMPRODUCT(C13:Q13,$C$20:$Q$20) -> 1.1391438 | AJ13: =AI13/AG13 -> 16.129786
B14: Plaza Justicia | C14: 0.11111111 | D14: 0.11111111 | E14: 0.11111111 | F14: 0.11111111 | G14: 0.11111111 | H14: 0.11111111 | I14: 0.33333333 | J14: 0.33333333 | K14: 0.11111111 | L14: 0.11111111 | M14: =IF(P34<0,"r", IF(P34=0,1, IF(AND(P34>=1,P34<=1.25),1, IF(AND(P34>1.25,P34<=1.5),3, IF(AND(P34>1.5,P34<=2),5, IF(AND(P34>2,P34<=3),7, IF(P34>3,9, ""))))))) -> 1 | N14: 0.11111111 | O14: 1 | P14: 0.33333333 | Q14: 0.33333333 | R14: =C14/C$19 -> 0.0062333037 | S14: =D14/D$19 -> 0.0062333037 | T14: =E14/E$19 -> 0.01754386 | U14: =F14/F$19 -> 0.0062333037 | V14: =G14/G$19 -> 0.01754386 | W14: =H14/H$19 -> 0.01754386 | X14: =I14/I$19 -> 0.0044052863 | Y14: =J14/J$19 -> 0.0044052863 | ... AF14: =Q14/Q$19 -> 0.0044052863 | AG14: =AVERAGE(R14:AF14) -> 0.0093996528 | AI14: =SUMPRODUCT(C14:Q14,$C$20:$Q$20) -> 0.14182515 | AJ14: =AI14/AG14 -> 15.08834
B15: Puertas Negras | C15: =IF(F35<0,"r", IF(F35=0,1, IF(AND(F35>=1,F35<=1.25),1, IF(AND(F35>1.25,F35<=1.5),3, IF(AND(F35>1.5,F35<=2),5, IF(AND(F35>2,F35<=3),7, IF(F35>3,9, ""))))))) -> 3 | D15: =IF(G35<0,"r", IF(G35=0,1, IF(AND(G35>=1,G35<=1.25),1, IF(AND(G35>1.25,G35<=1.5),3, IF(AND(G35>1.5,G35<=2),5, IF(AND(G35>2,G35<=3),7, IF(G35>3,9, ""))))))) -> 3 | E15: =IF(H35<0,"r", IF(H35=0,1, IF(AND(H35>=1,H35<=1.25),1, IF(AND(H35>1.25,H35<=1.5),3, IF(AND(H35>1.5,H35<=2),5, IF(AND(H35>2,H35<=3),7, IF(H35>3,9, ""))))))) -> 1 | F15: =IF(I35<0,"r", IF(I35=0,1, IF(AND(I35>=1,I35<=1.25),1, IF(AND(I35>1.25,I35<=1.5),3, IF(AND(I35>1.5,I35<=2),5, IF(AND(I35>2,I35<=3),7, IF(I35>3,9, ""))))))) -> 3 | G15: 1 | H15: =IF(K35<0,"r", IF(K35=0,1, IF(AND(K35>=1,K35<=1.25),1, IF(AND(K35>1.25,K35<=1.5),3, IF(AND(K35>1.5,K35<=2),5, IF(AND(K35>2,K35<=3),7, IF(K35>3,9, ""))))))) -> 1 | I15: =IF(L35<0,"r", IF(L35=0,1, IF(AND(L35>=1,L35<=1.25),1, IF(AND(L35>1.25,L35<=1.5),3, IF(AND(L35>1.5,L35<=2),5, IF(AND(L35>2,L35<=3),7, IF(L35>3,9, ""))))))) -> 9 | J15: =IF(M35<0,"r", IF(M35=0,1, IF(AND(M35>=1,M35<=1.25),1, IF(AND(M35>1.25,M35<=1.5),3, IF(AND(M35>1.5,M35<=2),5, IF(AND(M35>2,M35<=3),7, IF(M35>3,9, ""))))))) -> 9 | K15: =IF(N35<0,"r", IF(N35=0,1, IF(AND(N35>=1,N35<=1.25),1, IF(AND(N35>1.25,N35<=1.5),3, IF(AND(N35>1.5,N35<=2),5, IF(AND(N35>2,N35<=3),7, IF(N35>3,9, ""))))))) -> 3 | L15: =IF(O35<0,"r", IF(O35=0,1, IF(AND(O35>=1,O35<=1.25),1, IF(AND(O35>1.25,O35<=1.5),3, IF(AND(O35>1.5,O35<=2),5, IF(AND(O35>2,O35<=3),7, IF(O35>3,9, ""))))))) -> 3 | M15: =IF(P35<0,"r", IF(P35=0,1, IF(AND(P35>=1,P35<=1.25),1, IF(AND(P35>1.25,P35<=1.5),3, IF(AND(P35>1.5,P35<=2),5, IF(AND(P35>2,P35<=3),7, IF(P35>3,9, ""))))))) -> 9 | N15: =IF(Q35<0,"r", IF(Q35=0,1, IF(AND(Q35>=1,Q35<=1.25),1, IF(AND(Q35>1.25,Q35<=1.5),3, IF(AND(Q35>1.5,Q35<=2),5, IF(AND(Q35>2,Q35<=3),7, IF(Q35>3,9, ""))))))) -> 1 | O15: =IF(R35<0,"r", IF(R35=0,1, IF(AND(R35>=1,R35<=1.25),1, IF(AND(R35>1.25,R35<=1.5),3, IF(AND(R35>1.5,R35<=2),5, IF(AND(R35>2,R35<=3),7, IF(R35>3,9, ""))))))) -> 9 | ... Q15: =IF(T35<0,"r", IF(T35=0,1, IF(AND(T35>=1,T35<=1.25),1, IF(AND(T35>1.25,T35<=1.5),3, IF(AND(T35>1.5,T35<=2),5, IF(AND(T35>2,T35<=3),7, IF(T35>3,9, ""))))))) -> 9 | R15: =C15/C$19 -> 0.1682992 | S15: =D15/D$19 -> 0.1682992 | T15: =E15/E$19 -> 0.15789474 | U15: =F15/F$19 -> 0.1682992 | V15: =G15/G$19 -> 0.15789474 | W15: =H15/H$19 -> 0.15789474 | X15: =I15/I$19 -> 0.11894273 | Y15: =J15/J$19 -> 0.11894273 | ... AF15: =Q15/Q$19 -> 0.11894273 | AG15: =AVERAGE(R15:AF15) -> 0.14315542 | AI15: =SUMPRODUCT(C15:Q15,$C$20:$Q$20) -> 2.3370998 | AJ15: =AI15/AG15 -> 16.325612
B16: Quebrada Verde | C16: 0.14285714 | D16: 0.14285714 | E16: 0.11111111 | F16: 0.14285714 | G16: 0.11111111 | H16: 0.11111111 | I16: 0.33333333 | J16: 0.33333333 | K16: 0.14285714 | L16: 0.11111111 | M16: =IF(P36<0,"r", IF(P36=0,1, IF(AND(P36>=1,P36<=1.25),1, IF(AND(P36>1.25,P36<=1.5),3, IF(AND(P36>1.5,P36<=2),5, IF(AND(P36>2,P36<=3),7, IF(P36>3,9, ""))))))) -> 1 | N16: 0.11111111 | O16: =IF(R36<0,"r", IF(R36=0,1, IF(AND(R36>=1,R36<=1.25),1, IF(AND(R36>1.25,R36<=1.5),3, IF(AND(R36>1.5,R36<=2),5, IF(AND(R36>2,R36<=3),7, IF(R36>3,9, ""))))))) -> 1 | P16: 0.33333333 | Q16: 0.33333333 | R16: =C16/C$19 -> 0.0080142476 | S16: =D16/D$19 -> 0.0080142476 | T16: =E16/E$19 -> 0.01754386 | U16: =F16/F$19 -> 0.0080142476 | V16: =G16/G$19 -> 0.01754386 | W16: =H16/H$19 -> 0.01754386 | X16: =I16/I$19 -> 0.0044052863 | Y16: =J16/J$19 -> 0.0044052863 | ... AF16: =Q16/Q$19 -> 0.0044052863 | AG16: =AVERAGE(R16:AF16) -> 0.0098745712 | AI16: =SUMPRODUCT(C16:Q16,$C$20:$Q$20) -> 0.15059862 | AJ16: =AI16/AG16 -> 15.251156
B17: Reina Isabel 2 | C17: 0.14285714 | D17: 0.14285714 | E17: 0.11111111 | F17: 0.14285714 | G17: 0.11111111 | H17: 0.11111111 | I17: 1 | J17: 1 | K17: 0.14285714 | L17: 0.14285714 | M17: =IF(P37<0,"r", IF(P37=0,1, IF(AND(P37>=1,P37<=1.25),1, IF(AND(P37>1.25,P37<=1.5),3, IF(AND(P37>1.5,P37<=2),5, IF(AND(P37>2,P37<=3),7, IF(P37>3,9, ""))))))) -> 3 | N17: 0.11111111 | O17: =IF(R37<0,"r", IF(R37=0,1, IF(AND(R37>=1,R37<=1.25),1, IF(AND(R37>1.25,R37<=1.5),3, IF(AND(R37>1.5,R37<=2),5, IF(AND(R37>2,R37<=3),7, IF(R37>3,9, ""))))))) -> 3 | P17: =IF(S37<0,"r", IF(S37=0,1, IF(AND(S37>=1,S37<=1.25),1, IF(AND(S37>1.25,S37<=1.5),3, IF(AND(S37>1.5,S37<=2),5, IF(AND(S37>2,S37<=3),7, IF(S37>3,9, ""))))))) -> 1 | Q17: 1 | R17: =C17/C$19 -> 0.0080142476 | S17: =D17/D$19 -> 0.0080142476 | T17: =E17/E$19 -> 0.01754386 | U17: =F17/F$19 -> 0.0080142476 | V17: =G17/G$19 -> 0.01754386 | W17: =H17/H$19 -> 0.01754386 | X17: =I17/I$19 -> 0.013215859 | Y17: =J17/J$19 -> 0.013215859 | ... AF17: =Q17/Q$19 -> 0.013215859 | AG17: =AVERAGE(R17:AF17) -> 0.015279074 | AI17: =SUMPRODUCT(C17:Q17,$C$20:$Q$20) -> 0.23213329 | AJ17: =AI17/AG17 -> 15.192889
B18: Rodelillo | C18: 0.14285714 | D18: 0.14285714 | E18: 0.11111111 | F18: 0.14285714 | G18: 0.11111111 | H18: 0.11111111 | I18: 1 | J18: =IF(M38<0,"r", IF(M38=0,1, IF(AND(M38>=1,M38<=1.25),1, IF(AND(M38>1.25,M38<=1.5),3, IF(AND(M38>1.5,M38<=2),5, IF(AND(M38>2,M38<=3),7, IF(M38>3,9, ""))))))) -> 1 | K18: 0.14285714 | L18: 0.14285714 | M18: =IF(P38<0,"r", IF(P38=0,1, IF(AND(P38>=1,P38<=1.25),1, IF(AND(P38>1.25,P38<=1.5),3, IF(AND(P38>1.5,P38<=2),5, IF(AND(P38>2,P38<=3),7, IF(P38>3,9, ""))))))) -> 3 | N18: 0.11111111 | O18: =IF(R38<0,"r", IF(R38=0,1, IF(AND(R38>=1,R38<=1.25),1, IF(AND(R38>1.25,R38<=1.5),3, IF(AND(R38>1.5,R38<=2),5, IF(AND(R38>2,R38<=3),7, IF(R38>3,9, ""))))))) -> 3 | P18: =IF(S38<0,"r", IF(S38=0,1, IF(AND(S38>=1,S38<=1.25),1, IF(AND(S38>1.25,S38<=1.5),3, IF(AND(S38>1.5,S38<=2),5, IF(AND(S38>2,S38<=3),7, IF(S38>3,9, ""))))))) -> 1 | Q18: =IF(T38<0,"r", IF(T38=0,1, IF(AND(T38>=1,T38<=1.25),1, IF(AND(T38>1.25,T38<=1.5),3, IF(AND(T38>1.5,T38<=2),5, IF(AND(T38>2,T38<=3),7, IF(T38>3,9, ""))))))) -> 1 | R18: =C18/C$19 -> 0.0080142476 | S18: =D18/D$19 -> 0.0080142476 | T18: =E18/E$19 -> 0.01754386 | U18: =F18/F$19 -> 0.0080142476 | V18: =G18/G$19 -> 0.01754386 | W18: =H18/H$19 -> 0.01754386 | X18: =I18/I$19 -> 0.013215859 | Y18: =J18/J$19 -> 0.013215859 | ... AF18: =Q18/Q$19 -> 0.013215859 | AG18: =AVERAGE(R18:AF18) -> 0.015279074 | AI18: =SUMPRODUCT(C18:Q18,$C$20:$Q$20) -> 0.23213329 | AJ18: =AI18/AG18 -> 15.192889
B19: Total | C19: =SUM(C4:C18) -> 17.825397 | D19: =SUM(D4:D18) -> 17.825397 | E19: =SUM(E4:E18) -> 6.3333333 | F19: =SUM(F4:F18) -> 17.825397 | G19: =SUM(G4:G18) -> 6.3333333 | H19: =SUM(H4:H18) -> 6.3333333 | I19: =SUM(I4:I18) -> 75.666667 | J19: =SUM(J4:J18) -> 75.666667 | ... Q19: =SUM(Q4:Q18) -> 75.666667
B20: Ponderación | C20: =AG4 -> 0.069091049 | D20: =AG5 -> 0.069091049 | E20: =AG6 -> 0.14315542 | F20: =AG7 -> 0.069091049 | G20: =AG8 -> 0.14315542 | H20: =AG9 -> 0.14315542 | I20: =AG10 -> 0.015279074 | J20: =AG11 -> 0.015279074 | K20: =AG12 -> 0.069091049 | L20: =AG13 -> 0.070623616 | M20: =AG14 -> 0.0093996528 | N20: =AG15 -> 0.14315542 | O20: =AG16 -> 0.0098745712 | P20: =AG17 -> 0.015279074 | Q20: =AG18 -> 0.015279074
B23: Unidad Vecinal | D23: Precio | E23: Score | F23: Baron | G23: Cordillera | H23: Esperanza | I23: Jean y Marie Thierry | J23: Laguna Verde | K23: Las Cañas | L23: Marcelo Mena | M23: Padre Demian Molokai | N23: Placeres | O23: Placilla | P23: Plaza Justicia | Q23: Puertas Negras | R23: Quebrada Verde | S23: Reina Isabel 2 | T23: Rodelillo
B24: Baron | D24: 3.1621784e+08 | E24: =1/(D24/$D$39) -> 21.726817 | F24: 0 | G24: =$F$39/G39 -> 0.95572672 | H24: =$F$39/H39 -> 0.68759098 | I24: =$F$39/I39 -> 0.96205148 | J24: =$F$39/J39 -> 0.66861672 | K24: =$F$39/K39 -> 0.68284741 | L24: =$F$39/L39 -> 2.0711556 | M24: =$F$39/M39 -> 2.0774804 | N24: =$F$39/N39 -> 0.98893168 | ... T24: =$F$39/T39 -> 2.0727368 | X24: SI(F24<0;"r"; SI(F24=0;1; SI(Y(F24>=1;F24<=1,25);1; SI(Y(F24>1,25;F24<=1,5);3; SI(Y(F24>1,5;F24<=2);5; SI(Y(F24>2;F24<=3);7; SI(F24>3;9; "")))))))
B25: Cordillera | D25: 3.0221784e+08 | E25: =1/(D25/$D$39) -> 22.733295 | F25: =E25/$E$24 -> 1.0463242 | G25: 0 | H25: =$G$39/H39 -> 0.71944308 | I25: =$G$39/I39 -> 1.0066177 | J25: =$G$39/J39 -> 0.69958985 | K25: =$G$39/K39 -> 0.71447977 | L25: =$G$39/L39 -> 2.1671002 | M25: =$G$39/M39 -> 2.173718 | N25: =$G$39/N39 -> 1.0347432 | O25: =$G$39/O39 -> 0.98428286 | ... T25: =$G$39/T39 -> 2.1687547
B26: Esperanza | D26: 2.1742853e+08 | E26: =1/(D26/$D$39) -> 31.598462 | F26: =E26/$E$24 -> 1.454353 | G26: =E26/$E$25 -> 1.389964 | H26: 0 | I26: =$H$39/I39 -> 1.3991624 | J26: =$H$39/J39 -> 0.97240473 | K26: =$H$39/K39 -> 0.99310118 | L26: =$H$39/L39 -> 3.0121914 | M26: =$H$39/M39 -> 3.0213898 | N26: =$H$39/N39 -> 1.4382558 | O26: =$H$39/O39 -> 1.3681178 | P26: =$H$39/P39 -> 4.3729507 | ... T26: =$H$39/T39 -> 3.014491
B27: Jean y Marie Thierry | D27: 3.0421784e+08 | E27: =1/(D27/$D$39) -> 22.583841 | F27: =E27/$E$24 -> 1.0394454 | G27: =E27/$E$25 -> 0.99342576 | H27: =E27/$E$26 -> 0.71471329 | I27: 0 | J27: =$I$39/J39 -> 0.69499058 | K27: =$I$39/K39 -> 0.70978261 | L27: =$I$39/L39 -> 2.1528532 | M27: =$I$39/M39 -> 2.1594274 | N27: =$I$39/N39 -> 1.0279405 | O27: =$I$39/O39 -> 0.97781195 | P27: =$I$39/P39 -> 3.125406 | Q27: =$I$39/Q39 -> 0.70731728 | ... T27: =$I$39/T39 -> 2.1544968
B28: Laguna Verde | D28: 2.1142853e+08 | E28: =1/(D28/$D$39) -> 32.495175 | F28: =E28/$E$24 -> 1.4956252 | G28: =E28/$E$25 -> 1.429409 | H28: =E28/$E$26 -> 1.0283784 | I28: =E28/$E$27 -> 1.4388684 | J28: 0 | K28: =$J$39/K39 -> 1.0212838 | L28: =$J$39/L39 -> 3.0976725 | M28: =$J$39/M39 -> 3.1071319 | N28: =$J$39/N39 -> 1.4790711 | O28: =$J$39/O39 -> 1.4069427 | P28: =$J$39/P39 -> 4.497048 | Q28: =$J$39/Q39 -> 1.0177365 | R28: =$J$39/R39 -> 4.2522845 | ... T28: =$J$39/T39 -> 3.1000373
B29: Las Cañas | D29: 2.1592853e+08 | E29: =1/(D29/$D$39) -> 31.817968 | F29: =E29/$E$24 -> 1.464456 | G29: =E29/$E$25 -> 1.3996197 | H29: =E29/$E$26 -> 1.0069467 | I29: =E29/$E$27 -> 1.4088821 | J29: =E29/$E$28 -> 0.97915977 | K29: 0 | L29: =$K$39/L39 -> 3.0331163 | M29: =$K$39/M39 -> 3.0423786 | N29: =$K$39/N39 -> 1.4482469 | O29: =$K$39/O39 -> 1.3776217 | P29: =$K$39/P39 -> 4.4033285 | Q29: =$K$39/Q39 -> 0.99652663 | R29: =$K$39/R39 -> 4.1636659 | S29: =$K$39/S39 -> 3.0585877 | T29: =$K$39/T39 -> 3.0354319
B30: Marcelo Mena | D30: 6.5493634e+08 | E30: =1/(D30/$D$39) -> 10.490191 | F30: =E30/$E$24 -> 0.48282225 | G30: =E30/$E$25 -> 0.46144612 | H30: =E30/$E$26 -> 0.33198422 | I30: =E30/$E$27 -> 0.46449986 | J30: =E30/$E$28 -> 0.32282302 | K30: =E30/$E$29 -> 0.32969392 | L30: 0 | M30: =$L$39/M39 -> 1.0030537 | N30: =$L$39/N39 -> 0.47747822 | O30: =$L$39/O39 -> 0.45419351 | P30: =$L$39/P39 -> 1.4517506 | Q30: =$L$39/Q39 -> 0.32854877 | R30: =$L$39/R39 -> 1.3727353 | S30: =$L$39/S39 -> 1.0083978 | T30: =$L$39/T39 -> 1.0007634
B31: Padre Demian Molokai | D31: 6.5693634e+08 | E31: =1/(D31/$D$39) -> 10.458254 | F31: =E31/$E$24 -> 0.48135233 | G31: =E31/$E$25 -> 0.46004128 | H31: =E31/$E$26 -> 0.33097352 | I31: =E31/$E$27 -> 0.46308572 | J31: =E31/$E$28 -> 0.32184021 | K31: =E31/$E$29 -> 0.32869019 | L31: =E31/$E$30 -> 0.99695556 | M31: 0 | N31: =$M$39/N39 -> 0.47602456 | O31: =$M$39/O39 -> 0.45281075 | P31: =$M$39/P39 -> 1.4473309 | Q31: =$M$39/Q39 -> 0.32754853 | R31: =$M$39/R39 -> 1.3685561 | S31: =$M$39/S39 -> 1.0053278 | T31: =$M$39/T39 -> 0.99771667
B32: Placeres | D32: 3.1271784e+08 | E32: =1/(D32/$D$39) -> 21.969988 | F32: =E32/$E$24 -> 1.0111922 | G32: =E32/$E$25 -> 0.96642341 | H32: =E32/$E$26 -> 0.69528663 | I32: =E32/$E$27 -> 0.97281895 | J32: =E32/$E$28 -> 0.67610001 | K32: =E32/$E$29 -> 0.69048998 | L32: =E32/$E$30 -> 2.0943364 | M32: =E32/$E$31 -> 2.1007319 | N32: 0 | O32: =$N$39/O39 -> 0.95123399 | P32: =$N$39/P39 -> 3.0404542 | Q32: =$N$39/Q39 -> 0.68809165 | R32: =$N$39/R39 -> 2.8749696 | S32: =$N$39/S39 -> 2.1119241 | T32: =$N$39/T39 -> 2.0959353
B33: Placilla | D33: 2.9746784e+08 | E33: =1/(D33/$D$39) -> 23.096303 | F33: =E33/$E$24 -> 1.063032 | G33: =E33/$E$25 -> 1.0159681 | H33: =E33/$E$26 -> 0.73093123 | I33: =E33/$E$27 -> 1.0226915 | J33: =E33/$E$28 -> 0.71076098 | K33: =E33/$E$29 -> 0.72588867 | L33: =E33/$E$30 -> 2.2017047 | M33: =E33/$E$31 -> 2.2084281 | N33: =E33/$E$32 -> 1.051266 | O33: 0 | P33: =$O$39/P39 -> 3.1963263 | Q33: =$O$39/Q39 -> 0.72336739 | R33: =$O$39/R39 -> 3.0223579 | S33: =$O$39/S39 -> 2.2201941 | T33: =$O$39/T39 -> 2.2033856
B34: Plaza Justicia | D34: 9.5080426e+08 | E34: =1/(D34/$D$39) -> 7.2258902 | F34: =E34/$E$24 -> 0.33257932 | G34: =E34/$E$25 -> 0.31785495 | H34: =E34/$E$26 -> 0.22867854 | I34: =E34/$E$27 -> 0.31995843 | J34: =E34/$E$28 -> 0.22236809 | K34: =E34/$E$29 -> 0.22710093 | L34: =E34/$E$30 -> 0.68882353 | M34: =E34/$E$31 -> 0.69092701 | N34: =E34/$E$32 -> 0.32889823 | O34: =E34/$E$33 -> 0.31285918 | P34: 0 | Q34: =$P$39/Q39 -> 0.22631212 | R34: =$P$39/R39 -> 0.94557239 | S34: =$P$39/S39 -> 0.6946081 | T34: =$P$39/T39 -> 0.6893494
B35: Puertas Negras | D35: 2.1517853e+08 | E35: =1/(D35/$D$39) -> 31.928869 | F35: =E35/$E$24 -> 1.4695603 | G35: =E35/$E$25 -> 1.4044981 | H35: =E35/$E$26 -> 1.0104564 | I35: =E35/$E$27 -> 1.4137927 | J35: =E35/$E$28 -> 0.98257261 | K35: =E35/$E$29 -> 1.0034855 | L35: =E35/$E$30 -> 3.0436881 | M35: =E35/$E$31 -> 3.0529827 | N35: =E35/$E$32 -> 1.4532948 | O35: =E35/$E$33 -> 1.3824234 | P35: =E35/$E$34 -> 4.4186762 | Q35: 0 | R35: =$Q$39/R39 -> 4.1781782 | S35: =$Q$39/S39 -> 3.0692483 | T35: =$Q$39/T39 -> 3.0460118
B36: Quebrada Verde | D36: 8.9905426e+08 | E36: =1/(D36/$D$39) -> 7.641816 | F36: =E36/$E$24 -> 0.35172275 | G36: =E36/$E$25 -> 0.33615083 | H36: =E36/$E$26 -> 0.24184139 | I36: =E36/$E$27 -> 0.33837539 | J36: =E36/$E$28 -> 0.23516771 | K36: =E36/$E$29 -> 0.24017297 | L36: =E36/$E$30 -> 0.72847254 | M36: =E36/$E$31 -> 0.7306971 | N36: =E36/$E$32 -> 0.34782977 | O36: =E36/$E$33 -> 0.3308675 | P36: =E36/$E$34 -> 1.0575605 | Q36: =E36/$E$35 -> 0.23933876 | R36: 0 | S36: =$R$39/S39 -> 0.73459008 | T36: =$R$39/T39 -> 0.72902868
B37: Reina Isabel 2 | D37: 6.6043634e+08 | E37: =1/(D37/$D$39) -> 10.40283 | F37: =E37/$E$24 -> 0.47880139 | G37: =E37/$E$25 -> 0.45760328 | H37: =E37/$E$26 -> 0.32921951 | I37: =E37/$E$27 -> 0.46063158 | J37: =E37/$E$28 -> 0.32013461 | K37: =E37/$E$29 -> 0.32694829 | L37: =E37/$E$30 -> 0.99167217 | M37: =E37/$E$31 -> 0.99470047 | N37: =E37/$E$32 -> 0.47350186 | O37: =E37/$E$33 -> 0.45041106 | P37: =E37/$E$34 -> 1.4396607 | Q37: =E37/$E$35 -> 0.32581267 | R37: =E37/$E$36 -> 1.3613034 | S37: 0 | T37: =$S$39/T39 -> 0.99242925
B38: Rodelillo | D38: 6.5543634e+08 | E38: =1/(D38/$D$39) -> 10.482188 | F38: =E38/$E$24 -> 0.48245393 | G38: =E38/$E$25 -> 0.46109411 | H38: =E38/$E$26 -> 0.33173097 | I38: =E38/$E$27 -> 0.46414551 | J38: =E38/$E$28 -> 0.32257676 | K38: =E38/$E$29 -> 0.32944241 | L38: =E38/$E$30 -> 0.99923715 | M38: =E38/$E$31 -> 1.0022886 | N38: =E38/$E$32 -> 0.47711397 | O38: =E38/$E$33 -> 0.45384703 | P38: =E38/$E$34 -> 1.4506432 | Q38: =E38/$E$35 -> 0.32829814 | R38: =E38/$E$36 -> 1.3716881 | S38: =E38/$E$37 -> 1.0076285 | T38: 0
B39: Total | D39: =SUM(D24:D38) -> 6.8704072e+09 | F39: =E24 -> 21.726817 | G39: =E25 -> 22.733295 | H39: =E26 -> 31.598462 | I39: =E27 -> 22.583841 | J39: =E28 -> 32.495175 | K39: =E29 -> 31.817968 | L39: =E30 -> 10.490191 | M39: =E31 -> 10.458254 | N39: =E32 -> 21.969988 | O39: =E33 -> 23.096303 | P39: =E34 -> 7.2258902 | Q39: =E35 -> 31.928869 | R39: =E36 -> 7.641816 | S39: =E37 -> 10.40283 | T39: =E38 -> 10.482188

Sheet C. So.
B2: Criterio Social
B3: Alternativas | C3: Baron | D3: Cordillera | E3: Esperanza | F3: Jean y Marie Thierry | G3: Laguna Verde | H3: Las Cañas | I3: Marcelo Mena | J3: Padre Demian Molokai | K3: Placeres | L3: Placilla | M3: Plaza Justicia | N3: Puertas Negras | O3: Quebrada Verde | P3: Reina Isabel 2 | Q3: Rodelillo | R3: Matriz normalizada | AG3: Vector Promedio | AI3: Axw | AJ3: cocientes | AK3: λmax | AL3: n | AM3: RI | AO3: CI=(λmax-n)/(n-1) | AP3: =(AK4-AL4)/(AL4-1) -> 0.048736525
B4: Baron | C4: =IF(I24=0,1, IF(I24<1,"", IF(AND(I24>=1,I24<1.25),1, IF(AND(I24>=1.25,I24<1.5),3, IF(AND(I24>=1.5,I24<2),5, IF(AND(I24>=2,I24<3),7, IF(I24>=3,9, ""))))))) -> 1 | D4: =IF(J24=0,1, IF(J24<1,"", IF(AND(J24>=1,J24<1.25),1, IF(AND(J24>=1.25,J24<1.5),3, IF(AND(J24>=1.5,J24<2),5, IF(AND(J24>=2,J24<3),7, IF(J24>=3,9, ""))))))) -> 3 | E4: =IF(K24=0,1, IF(K24<1,"", IF(AND(K24>=1,K24<1.25),1, IF(AND(K24>=1.25,K24<1.5),3, IF(AND(K24>=1.5,K24<2),5, IF(AND(K24>=2,K24<3),7, IF(K24>=3,9, ""))))))) -> 3 | F4: =IF(L24=0,1, IF(L24<1,"", IF(AND(L24>=1,L24<1.25),1, IF(AND(L24>=1.25,L24<1.5),3, IF(AND(L24>=1.5,L24<2),5, IF(AND(L24>=2,L24<3),7, IF(L24>=3,9, ""))))))) -> 1 | G4: =IF(M24=0,1, IF(M24<1,"", IF(AND(M24>=1,M24<1.25),1, IF(AND(M24>=1.25,M24<1.5),3, IF(AND(M24>=1.5,M24<2),5, IF(AND(M24>=2,M24<3),7, IF(M24>=3,9, ""))))))) -> 7 | H4: =IF(N24=0,1, IF(N24<1,"", IF(AND(N24>=1,N24<1.25),1, IF(AND(N24>=1.25,N24<1.5),3, IF(AND(N24>=1.5,N24<2),5, IF(AND(N24>=2,N24<3),7, IF(N24>=3,9, ""))))))) -> 7 | I4: 1 | J4: =IF(P24=0,1, IF(P24<1,"", IF(AND(P24>=1,P24<1.25),1, IF(AND(P24>=1.25,P24<1.5),3, IF(AND(P24>=1.5,P24<2),5, IF(AND(P24>=2,P24<3),7, IF(P24>=3,9, ""))))))) -> 1 | K4: 0.33333333 | L4: 0.33333333 | M4: 1 | N4: =IF(T24=0,1, IF(T24<1,"", IF(AND(T24>=1,T24<1.25),1, IF(AND(T24>=1.25,T24<1.5),3, IF(AND(T24>=1.5,T24<2),5, IF(AND(T24>=2,T24<3),7, IF(T24>=3,9, ""))))))) -> 7 | O4: 1 | P4: 1 | Q4: 1 | R4: =C4/C$19 -> 0.066246057 | S4: =D4/D$19 -> 0.070422535 | T4: =E4/E$19 -> 0.082095387 | U4: =F4/F$19 -> 0.066246057 | V4: =G4/G$19 -> 0.082352941 | W4: =H4/H$19 -> 0.082352941 | X4: =I4/I$19 -> 0.091225022 | Y4: =J4/J$19 -> 0.056300268 | ... AF4: =Q4/Q$19 -> 0.076363636 | AG4: =AVERAGE(R4:AF4) -> 0.073225328 | AI4: =SUMPRODUCT(C4:Q4,$C$20:$Q$20) -> 1.149618 | AJ4: =AI4/AG4 -> 15.699732 | AK4: =AVERAGE(AJ4:AJ18) -> 15.682311 | AL4: 15 | AM4: =(1.86668*(15-2))/15 -> 1.6177893 | AO4: CR=CI/RI | AP4: =AP3/AM4 -> 0.030125384
B5: Cordillera | C5: 0.33333333 | D5: =IF(J25=0,1, IF(J25<1,"", IF(AND(J25>=1,J25<1.25),1, IF(AND(J25>=1.25,J25<1.5),3, IF(AND(J25>=1.5,J25<2),5, IF(AND(J25>=2,J25<3),7, IF(J25>=3,9, ""))))))) -> 1 | E5: 1 | F5: 0.33333333 | G5: =IF(M25=0,1, IF(M25<1,"", IF(AND(M25>=1,M25<1.25),1, IF(AND(M25>=1.25,M25<1.5),3, IF(AND(M25>=1.5,M25<2),5, IF(AND(M25>=2,M25<3),7, IF(M25>=3,9, ""))))))) -> 5 | H5: =IF(N25=0,1, IF(N25<1,"", IF(AND(N25>=1,N25<1.25),1, IF(AND(N25>=1.25,N25<1.5),3, IF(AND(N25>=1.5,N25<2),5, IF(AND(N25>=2,N25<3),7, IF(N25>=3,9, ""))))))) -> 5 | I5: 0.2 | J5: 0.33333333 | K5: 0.2 | L5: 0.2 | M5: 0.2 | N5: =IF(T25=0,1, IF(T25<1,"", IF(AND(T25>=1,T25<1.25),1, IF(AND(T25>=1.25,T25<1.5),3, IF(AND(T25>=1.5,T25<2),5, IF(AND(T25>=2,T25<3),7, IF(T25>=3,9, ""))))))) -> 5 | O5: 0.33333333 | P5: 0.2 | Q5: 0.33333333 | R5: =C5/C$19 -> 0.022082019 | S5: =D5/D$19 -> 0.023474178 | T5: =E5/E$19 -> 0.027365129 | U5: =F5/F$19 -> 0.022082019 | V5: =G5/G$19 -> 0.058823529 | W5: =H5/H$19 -> 0.058823529 | X5: =I5/I$19 -> 0.018245004 | Y5: =J5/J$19 -> 0.018766756 | ... AF5: =Q5/Q$19 -> 0.025454545 | AG5: =AVERAGE(R5:AF5) -> 0.029475881 | AI5: =SUMPRODUCT(C5:Q5,$C$20:$Q$20) -> 0.45522424 | AJ5: =AI5/AG5 -> 15.443957
B6: Esperanza | C6: 0.33333333 | D6: =IF(J26=0,1, IF(J26<1,"", IF(AND(J26>=1,J26<1.25),1, IF(AND(J26>=1.25,J26<1.5),3, IF(AND(J26>=1.5,J26<2),5, IF(AND(J26>=2,J26<3),7, IF(J26>=3,9, ""))))))) -> 1 | E6: =IF(K26=0,1, IF(K26<1,"", IF(AND(K26>=1,K26<1.25),1, IF(AND(K26>=1.25,K26<1.5),3, IF(AND(K26>=1.5,K26<2),5, IF(AND(K26>=2,K26<3),7, IF(K26>=3,9, ""))))))) -> 1 | F6: 0.33333333 | G6: =IF(M26=0,1, IF(M26<1,"", IF(AND(M26>=1,M26<1.25),1, IF(AND(M26>=1.25,M26<1.5),3, IF(AND(M26>=1.5,M26<2),5, IF(AND(M26>=2,M26<3),7, IF(M26>=3,9, ""))))))) -> 5 | H6: =IF(N26=0,1, IF(N26<1,"", IF(AND(N26>=1,N26<1.25),1, IF(AND(N26>=1.25,N26<1.5),3, IF(AND(N26>=1.5,N26<2),5, IF(AND(N26>=2,N26<3),7, IF(N26>=3,9, ""))))))) -> 5 | I6: 0.33333333 | J6: 1 | K6: 0.2 | L6: 0.2 | M6: 0.2 | N6: =IF(T26=0,1, IF(T26<1,"", IF(AND(T26>=1,T26<1.25),1, IF(AND(T26>=1.25,T26<1.5),3, IF(AND(T26>=1.5,T26<2),5, IF(AND(T26>=2,T26<3),7, IF(T26>=3,9, ""))))))) -> 7 | O6: 0.33333333 | P6: 0.33333333 | Q6: 0.33333333 | R6: =C6/C$19 -> 0.022082019 | S6: =D6/D$19 -> 0.023474178 | T6: =E6/E$19 -> 0.027365129 | U6: =F6/F$19 -> 0.022082019 | V6: =G6/G$19 -> 0.058823529 | W6: =H6/H$19 -> 0.058823529 | X6: =I6/I$19 -> 0.030408341 | Y6: =J6/J$19 -> 0.056300268 | ... AF6: =Q6/Q$19 -> 0.025454545 | AG6: =AVERAGE(R6:AF6) -> 0.035035941 | AI6: =SUMPRODUCT(C6:Q6,$C$20:$Q$20) -> 0.5426501 | AJ6: =AI6/AG6 -> 15.488384
